Workbook
Name Company_Name: Model!$G$7
Name Cost_of_Debt: WACC!$F$8
Name Cost_of_Preferred: WACC!$F$9
Name Diluted: Model!$G$10
Name Discount_Rate: DCF!$G$13
Name Equity_Risk_Premium: WACC!$F$7
Name Forward_Year_1: Model!$N$14
Name Forward_Year_2: Model!$N$15
Name Forward_Year_3: Model!$N$16
Name Hist_Year: Model!$N$7
Name LTM: Model!$N$13
Name Premium_Case: DCF!$G$6
Name Premium_Uplift: DCF!#REF!
Name Pub_Comps_Params: PubComps_Data!$C$3:$C$102
Name Pub_Comps_Range: PubComps_Data!$C$3:$AL$102
Name Pub_Comps_Tickers: PubComps_Data!$C$3:$AL$3
Name Risk_Free_Rate: WACC!$F$6
Name Scenario: DCF!$G$5
Name Share_Price: Model!$G$9
Name Tax_Rate: Model!$G$12
Name Terminal_Growth_Rate: DCF!$Q$10
Name Ticker: Model!$G$8
Name Units: Model!$G$15
Name Valuation_Date: Model!$N$10

Sheet Cover
B2: =Company_Name&" - Operating Model and Valuation - Cover Page and Navigation" -> Butterfly Network, inc. - Operating Model and Valuation - Cover Page and Navigation
C12: Company Name: | D12: =Company_Name -> Butterfly Network, inc.
C13: Model Name: | D13: Operating Model and Valuation (5-Year Forecast)
C14: Author: | D14: Glenn Rentrop
C16: File Name: | D16: =MID(CELL("filename"),SEARCH("[",CELL("filename"))+1, SEARCH("]",CELL("filename"))-SEARCH("[",CELL("filename"))-1) -> BFLYMODEL.xlsx
C17: Analysis Date: | D17: =Valuation_Date -> 45966
C19: Navigation, Summary, or Graph Worksheet:
C20: Financial Model Worksheet:
C21: Data and Back-End Calculation Worksheet:
B23: # | C23: Sheet Name | D23: Link to Sheet
B24: =_xlfn.SHEET(INDIRECT(D24&"!A1")) -> 2 | C24: Model and Valuation Summary | D24: Summary
B25: =_xlfn.SHEET(INDIRECT(D25&"!A1")) -> 3 | C25: Graphs and Dashboard | D25: Graphs
B26: =_xlfn.SHEET(INDIRECT(D26&"!A1")) -> 5 | C26: Operating Scenarios and 3-Statement Model | D26: Model
B27: =_xlfn.SHEET(INDIRECT(D27&"!A1")) -> 6 | C27: Revenue Drivers, Scenario Analysis, Capex, D&A | D27: Drivers
B28: =_xlfn.SHEET(INDIRECT(D28&"!A1")) -> 4 | C28: Stub Period Results from Q1 | D28: Q3
B29: =_xlfn.SHEET(INDIRECT(D29&"!A1")) -> 7 | C29: Discounted Cash Flow Analysis and Sensitivities | D29: DCF
B30: =_xlfn.SHEET(INDIRECT(D30&"!A1")) -> 8 | C30: Weighted Average Cost of Capital (WACC) Calculations | D30: WACC
B31: =_xlfn.SHEET(INDIRECT(D31&"!A1")) -> 9 | C31: Valuation Summary - Back-End Calculations | D31: ValSum
B32: =_xlfn.SHEET(INDIRECT(D32&"!A1")) -> 10 | C32: Valuation "Football Field" Chart | D32: ValGraph
B33: =_xlfn.SHEET(INDIRECT(D33&"!A1")) -> 11 | C33: Comparable Public Companies - Output | D33: PubComps
B34: =_xlfn.SHEET(INDIRECT(D34&"!A1")) -> 12 | C34: Comparable Public Companies - Data and Calculations | D34: PubComps_Data
B35: =_xlfn.SHEET(INDIRECT(D35&"!A1")) -> 13 | C35: Precedent Transactions | D35: MAComps

Sheet Summary
C3: =Company_Name&" - Summary of Operating Model and Valuation - "&Scenario&" Case" -> Butterfly Network, inc. - Summary of Operating Model and Valuation - Downside Case
C4: ($ in Thousands Except Per Share and Per Unit Data)
G6: Historical | H6: Projected: | P6: Projected
C7: Summary of Operational Performance: | E7: Units: | G7: 44592 | H7: 44957 | I7: 45322 | J7: 45688 | K7: 46053 | L7: 46418 | M7: 46783 | N7: 47149 | P7: CAGR:
C8: Segment-Level Statistics:
C10: Product Revenue | E10: $T | G10: =Drivers!G12 -> 50263 | H10: =Drivers!H12 -> 40036 | I10: =Drivers!I12 -> 54200 | J10: =Drivers!J12 -> 63443 | K10: =Drivers!K12 -> 56950 | L10: =Drivers!L12 -> 77000 | M10: =Drivers!M12 -> 84000 | N10: =Drivers!N12 -> 105000 | P10: =(M10/H10)^(1/YEARFRAC(G$7,L$7,))-1 -> 0.15975358
E11: % | H11: =H10/G10-1 -> -0.20346975 | I11: =I10/H10-1 -> 0.3537816 | J11: =J10/I10-1 -> 0.17053506 | K11: =K10/J10-1 -> -0.10234384 | L11: =L10/K10-1 -> 0.35206321 | M11: =M10/L10-1 -> 0.090909091 | N11: =N10/M10-1 -> 0.25
C12: Software Revenue | E12: $T | G12: =Drivers!G21 -> 23127.06 | H12: =Drivers!H21 -> 25863.902 | I12: =Drivers!I21 -> 27856.041 | J12: =Drivers!J21 -> 27400 | K12: =Drivers!K21 -> 30000 | L12: =Drivers!L21 -> 36000 | M12: =Drivers!M21 -> 51000 | N12: =Drivers!N21 -> 63000 | P12: =(M12/H12)^(1/YEARFRAC(G$7,L$7,))-1 -> 0.1454476
E13: % | H13: =H12/G12-1 -> 0.11833938 | I13: =I12/H12-1 -> 0.077023915 | J13: =J12/I12-1 -> -0.01637135 | K13: =K12/J12-1 -> 0.094890511 | L13: =L12/K12-1 -> 0.2 | M13: =M12/L12-1 -> 0.41666667 | N13: =N12/M12-1 -> 0.23529412
C14: Embedded Revenue | E14: $T | G14: =Drivers!G23 -> 0 | H14: =Drivers!H23 -> 0 | I14: =Drivers!I23 -> 0 | J14: =Drivers!J23 -> 6800 | K14: =Drivers!K23 -> 25000 | L14: =Drivers!L23 -> 25000 | M14: =Drivers!M23 -> 40000 | N14: =Drivers!N23 -> 40000
E15: % | K15: =K14/J14-1 -> 2.6764706 | L15: =L14/K14-1 -> 0 | M15: =M14/L14-1 -> 0.6 | N15: =N14/M14-1 -> 0
C16: Home Care Revenue | E16: $T | G16: =Drivers!G28 -> 0 | H16: =Drivers!H28 -> 0 | I16: =Drivers!I28 -> 0 | J16: =Drivers!J28 -> 0 | K16: =Drivers!K28 -> 1000 | L16: =Drivers!L28 -> 5000 | M16: =Drivers!M28 -> 15000 | N16: =Drivers!N28 -> 20000
E17: % | L17: =L16/K16-1 -> 4 | M17: =M16/L16-1 -> 2 | N17: =N16/M16-1 -> 0.33333333
C19: Company-Wide:
C21: Revenue: | E21: $T | G21: =Model!G72 -> 73390 | H21: =Model!H72 -> 65900 | I21: =Model!I72 -> 82056 | J21: =Model!J72 -> 97643 | K21: =Model!K72 -> 112950 | L21: =Model!L72 -> 143000 | M21: =Model!M72 -> 190000 | N21: =Model!N72 -> 228000 | P21: =(L21/G21)^(1/YEARFRAC(G$7,L$7,))-1 -> 0.14272
C22: Revenue Growth: | E22: % | H22: =H21/G21-1 -> -0.1020575 | I22: =I21/H21-1 -> 0.24515933 | J22: =J21/I21-1 -> 0.18995564 | K22: =K21/J21-1 -> 0.15676495 | L22: =L21/K21-1 -> 0.26604692 | M22: =M21/L21-1 -> 0.32867133 | N22: =N21/M21-1 -> 0.2
C24: Gross Profit: | E24: $T | G24: =Model!G78 -> 39460 | H24: =Model!H78 -> 16856 | I24: =Model!I78 -> 48831 | J24: =Model!J78 -> 45767 | K24: =Model!K78 -> 81170 | L24: =Model!L78 -> 101400 | M24: =Model!M78 -> 141100 | N24: =Model!N78 -> 167100 | P24: =(L24/G24)^(1/YEARFRAC(G$7,L$7,))-1 -> 0.20774758
C25: Profit Margin: | E25: % | G25: =G24/G21 -> 0.53767543 | H25: =H24/H21 -> 0.25578149 | I25: =I24/I21 -> 0.59509359 | J25: =J24/J21 -> 0.46871768 | K25: =K24/K21 -> 0.71863656 | L25: =L24/L21 -> 0.70909091 | M25: =M24/M21 -> 0.74263158 | N25: =N24/N21 -> 0.73289474
C27: =Model!C85 -> Total operating expenses | E27: $T | G27: =-Model!G85 -> 232480 | H27: =-Model!H85 -> 162466 | I27: =-Model!I85 -> 123242 | J27: =-Model!J85 -> 98619.43 | K27: =-Model!K85 -> 90360 | L27: =-Model!L85 -> 92950 | M27: =-Model!M85 -> 104500 | N27: =-Model!N85 -> 104880
C29: EBIT | G29: {=Model!G87:N87} -> -193020 | H29: -145610 | I29: -74411 | J29: -52852.43 | K29: -9190 | L29: 8450 | M29: 36600 | N29: 62220 | P29: =(L29/G29)^(1/YEARFRAC(G$7,L$7,))-1 -> -1.5348733
C30: Ebit Margin: | G30: =G29/G21 -> -2.6300586 | H30: =H29/H21 -> -2.2095599 | I30: =I29/I21 -> -0.90683192 | J30: =J29/J21 -> -0.54128232 | K30: =K29/K21 -> -0.081363435 | L30: =L29/L21 -> 0.059090909 | M30: =M29/M21 -> 0.19263158 | N30: =N29/N21 -> 0.27289474
C32: Comprehensive Income: | E32: $T | G32: =Model!G97 -> -168723 | H32: =Model!H97 -> -133700 | I32: =Model!I97 -> -72492 | J32: =Model!J97 -> -49463.491 | K32: =Model!K97 -> -8501.9708 | L32: =Model!L97 -> 10798.983 | M32: =Model!M97 -> 40699.678 | N32: =Model!N97 -> 69395.855 | P32: =(L32/G32)^(1/YEARFRAC(G$7,L$7,))-1 -> -1.5770876
C33: Basic Earnings per Share (EPS): | E33: $ as Stated | G33: =G32/(Diluted*Units) -> -0.74199833 | H33: =H32/(Diluted*Units) -> -0.5879766 | I33: =I32/(Diluted*Units) -> -0.3188003 | J33: =J32/(Diluted*Units) -> -0.21752711 | K33: =K32/(Diluted*Units) -> -0.037389379 | L33: =L32/(Diluted*Units) -> 0.047491019 | M33: =M32/(Diluted*Units) -> 0.17898623 | N33: =N32/(Diluted*Units) -> 0.30518429
C35: Capital expenditures: | E35: $T | G35: =Model!G170 -> -18302 | H35: =Model!H170 -> -5783 | I35: =Model!I170 -> -2694 | J35: =Model!J170 -> -2465.4858 | K35: =Model!K170 -> -2710.8 | L35: =Model!L170 -> -2788.5 | M35: =Model!M170 -> -3135 | N35: =Model!N170 -> -3146.4 | P35: =(L35/G35)^(1/YEARFRAC(G$7,L$7,))-1 -> -0.31360451
C36: % Revenue: | E36: %
C38: Cash Flow From Operations: | E38: $T | G38: =Model!G164 -> -169115 | H38: =Model!H164 -> -98820 | I38: =Model!I164 -> -41707 | J38: =Model!J164 -> -26415.297 | K38: =Model!K164 -> 19332.207 | L38: =Model!L164 -> 41923.908 | M38: =Model!M164 -> 62324.023 | N38: =Model!N164 -> 88317.806
C39: Cash Flow From Investing: | E39: $T | G39: =Model!G172 -> -93779 | H39: =Model!H172 -> 70414 | I39: =Model!I172 -> -2658 | J39: =Model!J172 -> -2431.1524 | K39: =Model!K172 -> -2676.4667 | L39: =Model!L172 -> -2754.1667 | M39: =Model!M172 -> -3100.6667 | N39: =Model!N172 -> -3112.0667
C40: Cash Flows From Financing Activities: | E40: $T | G40: =Model!G180 -> 2881 | H40: =Model!H180 -> 228 | I40: =Model!I180 -> -1495 | J40: =Model!J180 -> -542.5 | K40: =Model!K180 -> -424.15 | L40: =Model!L180 -> -317.635 | M40: =Model!M180 -> -221.7715 | N40: =Model!N180 -> -135.49435
C42: Total Assets: | E42: $T | H42: =Model!H118 -> 304274 | I42: =Model!I118 -> 256082 | J42: =Model!J118 -> 206567.46 | K42: =Model!K118 -> 217521.15 | L42: =Model!L118 -> 257365.92 | M42: =Model!M118 -> 333442.51 | N42: =Model!N118 -> 439663.33
C43: Cash and Cash Equivalents: | E43: $T | H43: =Model!H108 -> 134437 | I43: =Model!I108 -> 88775 | J43: =Model!J108 -> 59386.051 | K43: =Model!K108 -> 75617.641 | L43: =Model!L108 -> 114469.75 | M43: =Model!M108 -> 173471.33 | N43: =Model!N108 -> 258541.58
C45: EBITDA: | E45: $T | G45: =DCF!H62 -> -183703 | H45: =DCF!I62 -> -127586 | I45: =DCF!J62 -> -60310 | J45: =DCF!K62 -> -46163.568 | K45: =DCF!L62 -> -3779.9891 | L45: =DCF!M62 -> 14395.194 | M45: =DCF!N62 -> 44029.711 | N45: =DCF!O62 -> 71482.662 | P45: =(L45/G45)^(1/YEARFRAC(G$7,L$7,))-1 -> -1.600925
C46: EBITDA Margin: | E46: % | G46: =G45/G21 -> -2.5031067 | H46: =H45/H21 -> -1.9360546 | I46: =I45/I21 -> -0.73498586 | J46: =J45/J21 -> -0.47277908 | K46: =K45/K21 -> -0.033466039 | L46: =L45/L21 -> 0.10066569 | M46: =M45/M21 -> 0.23173532 | N46: =N45/N21 -> 0.31352045
G48: LTM | I48: Projected:
C49: Summary of Valuation Multiples: | E49: Units: | H49: =J7 -> 45688 | I49: =K7 -> 46053
C50: EV / Revenue - Comparables: | E50: x | G50: {=PubComps!N36:P36} -> 1.9782445 | H50: 2.1391078 | I50: 1.9808956
C51: ="EV / Revenue - "&Company_Name&":" -> EV / Revenue - Butterfly Network, inc.: | E51: x | G51: {=PubComps!N40:P40} -> 2.9859621 | H51: 9.5966092 | I51: 10.690741
C52: Projected Revenue Growth - Comparables: | E52: % | I52: =PubComps!W17 -> 0.044081831
C53: ="Projected Revenue Growth - "&Company_Name&":" -> Projected Revenue Growth - Butterfly Network, inc.: | E53: % | I53: =PubComps!W21 -> 0.026878436
C55: EV / EBITDA - Comparables: | E55: x | G55: {=PubComps!Q36:S36} -> 8.59825 | H55: 12.563107 | I55: 11.70442
C56: ="EV / EBITDA - "&Company_Name&":" -> EV / EBITDA - Butterfly Network, inc.: | E56: x | G56: {=PubComps!Q40:S40} -> 2.3516326 | H56: NM | I56: NM
...

Sheet Graphs
B2: ="Graphs and Analysis of Financial Model Output - "&TEXT(Company_Name,"") -> Graphs and Analysis of Financial Model Output - Butterfly Network, inc.
P4: Year | Q4: Revenue | R4: EBITDA | S4: EBITDA Margin
P5: {=TRANSPOSE(Model!G66:N66)} -> 44926 | Q5: {=TRANSPOSE(Model!G72:N72)} -> 73390 | R5: {=TRANSPOSE(DCF!H62:O62)} -> -183703 | S5: =R5/Q5 -> -2.5031067 | X5: ="Revenue & Normalized Gross Margin" -> Revenue & Normalized Gross Margin
P6: 45291 | Q6: 65900 | R6: -127586 | S6: =R6/Q6 -> -1.9360546
P7: 45657 | Q7: 82056 | R7: -60310 | S7: =R7/Q7 -> -0.73498586
P8: 46022 | Q8: 97643 | R8: -46163.568 | S8: =R8/Q8 -> -0.47277908
P9: 46387 | Q9: 112950 | R9: -3779.9891 | S9: =R9/Q9 -> -0.033466039
P10: 46752 | Q10: 143000 | R10: 14395.194 | S10: =R10/Q10 -> 0.10066569
P11: 47118 | Q11: 190000 | R11: 44029.711 | S11: =R11/Q11 -> 0.23173532
P12: 47483 | Q12: 228000 | R12: 71482.662 | S12: =R12/Q12 -> 0.31352045
P16: Current Region Selected: | Q16: 1
P18: Status: | R18: TRUE | S18: TRUE
P19: Year | Q19: Revenue | R19: EBITDA | S19: EBITDA Margin
P20: =INDEX($P$4:$P$14,$Q$16+ROWS(P$21:$P23)) -> 45657 | Q20: =INDEX($Q$4:$Q$14,$Q$16+ROWS(Q$19:Q23)) -> 112950 | R20: =IF($Q$16,INDEX($R$4:$R$14,$Q$16+ROWS(R$19:R23)),"") -> -3779.9891 | S20: =IF($Q$16,INDEX($S$4:$S$14,$Q$16+ROWS(S$19:S23)),NA()) -> -0.033466039 | X20: Unlevered Free Cash Flow
P21: =INDEX($P$4:$P$14,$Q$16+ROWS(P$21:$P24)) -> 46022 | Q21: =INDEX($Q$4:$Q$14,$Q$16+ROWS(Q$19:Q24)) -> 143000 | R21: =IF($Q$16,INDEX($R$4:$R$14,$Q$16+ROWS(R$19:R24)),"") -> 14395.194 | S21: =IF($Q$16,INDEX($S$4:$S$14,$Q$16+ROWS(S$19:S24)),NA()) -> 0.10066569
P22: =INDEX($P$4:$P$14,$Q$16+ROWS(P$21:$P25)) -> 46387 | Q22: =INDEX($Q$4:$Q$14,$Q$16+ROWS(Q$19:Q25)) -> 190000 | R22: =IF($Q$16,INDEX($R$4:$R$14,$Q$16+ROWS(R$19:R25)),"") -> 44029.711 | S22: =IF($Q$16,INDEX($S$4:$S$14,$Q$16+ROWS(S$19:S25)),NA()) -> 0.23173532
P23: =INDEX($P$4:$P$14,$Q$16+ROWS(P$21:$P26)) -> 46752 | Q23: =INDEX($Q$4:$Q$14,$Q$16+ROWS(Q$19:Q26)) -> 228000 | R23: =IF($Q$16,INDEX($R$4:$R$14,$Q$16+ROWS(R$19:R26)),"") -> 71482.662 | S23: =IF($Q$16,INDEX($S$4:$S$14,$Q$16+ROWS(S$19:S26)),NA()) -> 0.31352045
P27: =Company_Name&": Revenue, EBITDA, and Margins, FY"&TEXT(P20,"yy")&" to FY"&TEXT(P23,"yy") -> Butterfly Network, inc.: Revenue, EBITDA, and Margins, FY24 to FY27
P33: =Company_Name&": Revenue, Operating Expenses, EBIT" -> Butterfly Network, inc.: Revenue, Operating Expenses, EBIT | X33: Revenue by Segment
P48: =Company_Name&": Revenue by Segment" -> Butterfly Network, inc.: Revenue by Segment
P65: ="Annual Revenue, FY"&TEXT(Forward_Year_1,"yy")&" - FY"&TEXT(Forward_Year_2,"yy") -> Annual Revenue, FY25 - FY26 | Q65: ="FY"&TEXT(Forward_Year_1,"yy") -> FY25 | R65: ="FY"&TEXT(Forward_Year_2,"yy") -> FY26
P66: ="Annual EBITDA, FY"&TEXT(Forward_Year_1,"yy")&" - FY"&TEXT(Forward_Year_2,"yy") -> Annual EBITDA, FY25 - FY26 | Q66: ="FY"&TEXT(Forward_Year_1,"yy") -> FY25 | R66: ="FY"&TEXT(Forward_Year_2,"yy") -> FY26
P80: ="Projected Revenue Growth, FY"&TEXT(Forward_Year_1,"yy")&" - FY"&TEXT(Forward_Year_2,"yy") -> Projected Revenue Growth, FY25 - FY26
P81: ="Projected EBITDA Growth, FY"&TEXT(Forward_Year_1,"yy")&" - FY"&TEXT(Forward_Year_2,"yy") -> Projected EBITDA Growth, FY25 - FY26
P83: ="FY"&TEXT(Forward_Year_2,"yy")&" Revenue Multiples" -> FY26 Revenue Multiples
P84: ="FY"&TEXT(Forward_Year_2,"yy")&" EBITDA Multiples" -> FY26 EBITDA Multiples
P90: Supporting Data (Sorted by revenue in ascending order): | Q90: Revenue: | T90: EBITDA: | W90: Rev. Multiples: | Z90: EBITDA Multiples:
Q91: =PubComps_Data!C73 -> 2025-12-31 Revenue: | R91: =PubComps_Data!C77 -> 2026-12-31 Revenue: | T91: =PubComps_Data!C74 -> 2025-12-31 EBITDA: | U91: =PubComps_Data!C78 -> 2026-12-31 EBITDA: | W91: =PubComps_Data!C96 -> 2025-12-31 EV / Revenue: | X91: =PubComps_Data!C100 -> 2026-12-31 EV / Revenue: | Z91: =PubComps_Data!C97 -> 2025-12-31 EV / EBITDA: | AA91: =PubComps_Data!C101 -> 2026-12-31 EV / EBITDA:
P92: GEHC | Q92: =INDEX(Pub_Comps_Range,MATCH(Q$91,Pub_Comps_Params,0),MATCH($P92,Pub_Comps_Tickers,0)) -> 20530 | R92: =INDEX(Pub_Comps_Range,MATCH(R$91,Pub_Comps_Params,0),MATCH($P92,Pub_Comps_Tickers,0)) -> 21435 | T92: =INDEX(Pub_Comps_Range,MATCH(T$91,Pub_Comps_Params,0),MATCH($P92,Pub_Comps_Tickers,0)) -> 3653 | U92: =INDEX(Pub_Comps_Range,MATCH(U$91,Pub_Comps_Params,0),MATCH($P92,Pub_Comps_Tickers,0)) -> 3921 | W92: =INDEX(Pub_Comps_Range,MATCH(W$91,Pub_Comps_Params,0),MATCH($P92,Pub_Comps_Tickers,0)) -> 2.2354131 | X92: =INDEX(Pub_Comps_Range,MATCH(X$91,Pub_Comps_Params,0),MATCH($P92,Pub_Comps_Tickers,0)) -> 2.1410324 | Z92: =INDEX(Pub_Comps_Range,MATCH(Z$91,Pub_Comps_Params,0),MATCH($P92,Pub_Comps_Tickers,0)) -> 12.563107 | AA92: =INDEX(Pub_Comps_Range,MATCH(AA$91,Pub_Comps_Params,0),MATCH($P92,Pub_Comps_Tickers,0)) -> 11.70442
P93: MASI | Q93: =INDEX(Pub_Comps_Range,MATCH(Q$91,Pub_Comps_Params,0),MATCH($P93,Pub_Comps_Tickers,0)) -> 1521 | R93: =INDEX(Pub_Comps_Range,MATCH(R$91,Pub_Comps_Params,0),MATCH($P93,Pub_Comps_Tickers,0)) -> 1639 | T93: =INDEX(Pub_Comps_Range,MATCH(T$91,Pub_Comps_Params,0),MATCH($P93,Pub_Comps_Tickers,0)) -> 497 | U93: =INDEX(Pub_Comps_Range,MATCH(U$91,Pub_Comps_Params,0),MATCH($P93,Pub_Comps_Tickers,0)) -> 544 | W93: =INDEX(Pub_Comps_Range,MATCH(W$91,Pub_Comps_Params,0),MATCH($P93,Pub_Comps_Tickers,0)) -> 5.4004997 | X93: =INDEX(Pub_Comps_Range,MATCH(X$91,Pub_Comps_Params,0),MATCH($P93,Pub_Comps_Tickers,0)) -> 5.0116901 | Z93: =INDEX(Pub_Comps_Range,MATCH(Z$91,Pub_Comps_Params,0),MATCH($P93,Pub_Comps_Tickers,0)) -> 16.527485 | AA93: =INDEX(Pub_Comps_Range,MATCH(AA$91,Pub_Comps_Params,0),MATCH($P93,Pub_Comps_Tickers,0)) -> 15.099559
P94: INMD | Q94: =INDEX(Pub_Comps_Range,MATCH(Q$91,Pub_Comps_Params,0),MATCH($P94,Pub_Comps_Tickers,0)) -> 368 | R94: =INDEX(Pub_Comps_Range,MATCH(R$91,Pub_Comps_Params,0),MATCH($P94,Pub_Comps_Tickers,0)) -> 383 | T94: =INDEX(Pub_Comps_Range,MATCH(T$91,Pub_Comps_Params,0),MATCH($P94,Pub_Comps_Tickers,0)) -> 94 | U94: =INDEX(Pub_Comps_Range,MATCH(U$91,Pub_Comps_Params,0),MATCH($P94,Pub_Comps_Tickers,0)) -> 101 | W94: =INDEX(Pub_Comps_Range,MATCH(W$91,Pub_Comps_Params,0),MATCH($P94,Pub_Comps_Tickers,0)) -> 1.1954076 | X94: =INDEX(Pub_Comps_Range,MATCH(X$91,Pub_Comps_Params,0),MATCH($P94,Pub_Comps_Tickers,0)) -> 1.1485901 | Z94: =INDEX(Pub_Comps_Range,MATCH(Z$91,Pub_Comps_Params,0),MATCH($P94,Pub_Comps_Tickers,0)) -> 4.6798936 | AA94: =INDEX(Pub_Comps_Range,MATCH(AA$91,Pub_Comps_Params,0),MATCH($P94,Pub_Comps_Tickers,0)) -> 4.3555446
P95: IART | Q95: =INDEX(Pub_Comps_Range,MATCH(Q$91,Pub_Comps_Params,0),MATCH($P95,Pub_Comps_Tickers,0)) -> 1637 | R95: =INDEX(Pub_Comps_Range,MATCH(R$91,Pub_Comps_Params,0),MATCH($P95,Pub_Comps_Tickers,0)) -> 1681 | T95: =INDEX(Pub_Comps_Range,MATCH(T$91,Pub_Comps_Params,0),MATCH($P95,Pub_Comps_Tickers,0)) -> 314 | U95: =INDEX(Pub_Comps_Range,MATCH(U$91,Pub_Comps_Params,0),MATCH($P95,Pub_Comps_Tickers,0)) -> 333 | W95: =INDEX(Pub_Comps_Range,MATCH(W$91,Pub_Comps_Params,0),MATCH($P95,Pub_Comps_Tickers,0)) -> 1.6958809 | X95: =INDEX(Pub_Comps_Range,MATCH(X$91,Pub_Comps_Params,0),MATCH($P95,Pub_Comps_Tickers,0)) -> 1.6514914 | Z95: =INDEX(Pub_Comps_Range,MATCH(Z$91,Pub_Comps_Params,0),MATCH($P95,Pub_Comps_Tickers,0)) -> 8.8412647 | AA95: =INDEX(Pub_Comps_Range,MATCH(AA$91,Pub_Comps_Params,0),MATCH($P95,Pub_Comps_Tickers,0)) -> 8.3368081
P96: CVAC | Q96: =INDEX(Pub_Comps_Range,MATCH(Q$91,Pub_Comps_Params,0),MATCH($P96,Pub_Comps_Tickers,0)) -> 77 | R96: =INDEX(Pub_Comps_Range,MATCH(R$91,Pub_Comps_Params,0),MATCH($P96,Pub_Comps_Tickers,0)) -> 99 | T96: =INDEX(Pub_Comps_Range,MATCH(T$91,Pub_Comps_Params,0),MATCH($P96,Pub_Comps_Tickers,0)) -> -129 | U96: =INDEX(Pub_Comps_Range,MATCH(U$91,Pub_Comps_Params,0),MATCH($P96,Pub_Comps_Tickers,0)) -> -130 | W96: =INDEX(Pub_Comps_Range,MATCH(W$91,Pub_Comps_Params,0),MATCH($P96,Pub_Comps_Tickers,0)) -> 9.7895338 | X96: =INDEX(Pub_Comps_Range,MATCH(X$91,Pub_Comps_Params,0),MATCH($P96,Pub_Comps_Tickers,0)) -> 7.6140819 | Z96: =INDEX(Pub_Comps_Range,MATCH(Z$91,Pub_Comps_Params,0),MATCH($P96,Pub_Comps_Tickers,0)) -> NM | AA96: =INDEX(Pub_Comps_Range,MATCH(AA$91,Pub_Comps_Params,0),MATCH($P96,Pub_Comps_Tickers,0)) -> NM
P97: CDNA | Q97: =INDEX(Pub_Comps_Range,MATCH(Q$91,Pub_Comps_Params,0),MATCH($P97,Pub_Comps_Tickers,0)) -> 369 | R97: =INDEX(Pub_Comps_Range,MATCH(R$91,Pub_Comps_Params,0),MATCH($P97,Pub_Comps_Tickers,0)) -> 414 | T97: =INDEX(Pub_Comps_Range,MATCH(T$91,Pub_Comps_Params,0),MATCH($P97,Pub_Comps_Tickers,0)) -> 30 | U97: =INDEX(Pub_Comps_Range,MATCH(U$91,Pub_Comps_Params,0),MATCH($P97,Pub_Comps_Tickers,0)) -> 46 | W97: =INDEX(Pub_Comps_Range,MATCH(W$91,Pub_Comps_Params,0),MATCH($P97,Pub_Comps_Tickers,0)) -> 2.0428025 | X97: =INDEX(Pub_Comps_Range,MATCH(X$91,Pub_Comps_Params,0),MATCH($P97,Pub_Comps_Tickers,0)) -> 1.8207587 | Z97: =INDEX(Pub_Comps_Range,MATCH(Z$91,Pub_Comps_Params,0),MATCH($P97,Pub_Comps_Tickers,0)) -> 25.12647 | AA97: =INDEX(Pub_Comps_Range,MATCH(AA$91,Pub_Comps_Params,0),MATCH($P97,Pub_Comps_Tickers,0)) -> 16.386828
P98: BFLY | Q98: =INDEX(Pub_Comps_Range,MATCH(Q$91,Pub_Comps_Params,0),MATCH($P98,Pub_Comps_Tickers,0)) -> 63.443 | R98: =INDEX(Pub_Comps_Range,MATCH(R$91,Pub_Comps_Params,0),MATCH($P98,Pub_Comps_Tickers,0)) -> 56.95 | T98: =INDEX(Pub_Comps_Range,MATCH(T$91,Pub_Comps_Params,0),MATCH($P98,Pub_Comps_Tickers,0)) -> -46.163568 | U98: =INDEX(Pub_Comps_Range,MATCH(U$91,Pub_Comps_Params,0),MATCH($P98,Pub_Comps_Tickers,0)) -> -3.7799891 | W98: =INDEX(Pub_Comps_Range,MATCH(W$91,Pub_Comps_Params,0),MATCH($P98,Pub_Comps_Tickers,0)) -> 9.5966092 | X98: =INDEX(Pub_Comps_Range,MATCH(X$91,Pub_Comps_Params,0),MATCH($P98,Pub_Comps_Tickers,0)) -> 10.690741 | Z98: =INDEX(Pub_Comps_Range,MATCH(Z$91,Pub_Comps_Params,0),MATCH($P98,Pub_Comps_Tickers,0)) -> NM | AA98: =INDEX(Pub_Comps_Range,MATCH(AA$91,Pub_Comps_Params,0),MATCH($P98,Pub_Comps_Tickers,0)) -> NM
P100: Data for Graphs (Sorted by revenue growth in ascending order):
Q101: Revenue Growth: | T101: EBITDA Growth: | W101: Year 2 Rev. Multiple: | Z101: Year 2 EBITDA Multiple:
Q102: =PubComps_Data!C85 -> Year 1 Projected Revenue Growth: | R102: Helper | T102: =PubComps_Data!C86 -> Year 1 Projected EBITDA Growth: | U102: Helper | W102: =PubComps_Data!C102 -> 2026-12-31 P / E: | X102: Helper | Z102: =PubComps_Data!C101 -> 2026-12-31 EV / EBITDA: | AA102: Helper
P103: GEHC | Q103: =INDEX(Pub_Comps_Range,MATCH(Q$102,Pub_Comps_Params,0),MATCH($P103,Pub_Comps_Tickers,0)) -> 0.044081831 | R103: =IF($P103=Ticker,Q103,NA()) -> #N/A | T103: =INDEX(Pub_Comps_Range,MATCH(T$102,Pub_Comps_Params,0),MATCH($P103,Pub_Comps_Tickers,0)) -> 0.073364358 | U103: =IF($P103=Ticker,T103,NA()) -> #N/A | W103: =INDEX(Pub_Comps_Range,MATCH(W$102,Pub_Comps_Params,0),MATCH($P103,Pub_Comps_Tickers,0)) -> 18.130894 | X103: =IF($P103=Ticker,W103,NA()) -> #N/A | Z103: =INDEX(Pub_Comps_Range,MATCH(Z$102,Pub_Comps_Params,0),MATCH($P103,Pub_Comps_Tickers,0)) -> 11.70442 | AA103: =IF($P103=Ticker,Z103,NA()) -> #N/A
P104: MASI | Q104: =INDEX(Pub_Comps_Range,MATCH(Q$102,Pub_Comps_Params,0),MATCH($P104,Pub_Comps_Tickers,0)) -> 0.077580539 | R104: =IF($P104=Ticker,Q104,NA()) -> #N/A | T104: =INDEX(Pub_Comps_Range,MATCH(T$102,Pub_Comps_Params,0),MATCH($P104,Pub_Comps_Tickers,0)) -> 0.094567404 | U104: =IF($P104=Ticker,T104,NA()) -> #N/A | W104: =INDEX(Pub_Comps_Range,MATCH(W$102,Pub_Comps_Params,0),MATCH($P104,Pub_Comps_Tickers,0)) -> 29.137962 | X104: =IF($P104=Ticker,W104,NA()) -> #N/A | Z104: =INDEX(Pub_Comps_Range,MATCH(Z$102,Pub_Comps_Params,0),MATCH($P104,Pub_Comps_Tickers,0)) -> 15.099559 | AA104: =IF($P104=Ticker,Z104,NA()) -> #N/A
...

Sheet Q3
B2: =Company_Name&" - Q4 Financial Results" -> Butterfly Network, inc. - Q4 Financial Results
B3: ($ in Thousands Except Per Share and Per Unit Data)
B6: Reported Income Statement and Cash Flow Statement Figures from Q1: | E6: Q1-25 | F6: Q2-25 | G6: Q3-25 | H6: Q4-25
C8: Product revenue | E8: 14164 | F8: 16621 | G8: 14556 | H8: 18102
C9: Software and other services revenue | E9: 7061 | F9: 6762 | G9: 6933 | H9: 13412
C10: Embedded Revenue | E10: 0 | F10: 0 | G10: 0 | H10: 6800
C11: Revenue: | E11: 21225 | F11: 23383 | G11: 21489 | H11: 31514
C12: Annual Revenue Growth Rate: | F12: =F11/E11-1 -> 0.10167256 | G12: =G11/F11-1 -> -0.080999016 | H12: =H11/G11-1 -> 0.46651775
C14: Normalized Gross Profit | E14: 13380 | F14: 14891 | G14: 13839 | H14: 21221
C15: % Margin | E15: =E14/E11 -> 0.63038869 | F15: =F14/F11 -> 0.63683018 | G15: =G14/G11 -> 0.64400391 | H15: =H14/H11 -> 0.67338326
C17: Operating Income (EBIT): | E17: -18468 | F17: -16100 | G17: -35134 | H17: -16711
C18: % Quarterly Operating Margin | F18: =+F17/F11 -> -0.68853441 | G18: =+G17/G11 -> -1.634976 | H18: =+H17/H11 -> -0.53027226
C20: Taxes, Excluding Effect of Interest: | E20: 7 | F20: 20 | G20: 16 | H20: 66
C22: Net Operating Profit After Tax (NOPAT): | E22: =+E17+E20 -> -18461 | F22: =+F17+F20 -> -16080 | G22: =+G17+G20 -> -35118 | H22: =+H17+H20 -> -16645
C24: Adjustments for Non-Cash Charges:
C25: Depreciation & Amortization: | E25: 2360 | F25: 2082 | G25: 1885 | H25: 1754
C26: Deferred Income Taxes: | E26: 0 | F26: 0 | G26: 0 | H26: 0
C27: Other Operating Activities: | E27: 5912 | F27: 5741 | G27: 22766 | H27: 6629
C28: Total Adjustments for Non-Cash Charges: | E28: =SUM(E25:E27) -> 8272 | F28: =SUM(F25:F27) -> 7823 | G28: =SUM(G25:G27) -> 24651 | H28: =SUM(H25:H27) -> 8383
C30: Net Change in Working Capital:
C31: Accounts Receivable: | E31: 857 | F31: -4766 | G31: -63 | H31: -2781
C32: Inventories: | E32: 1423 | F32: 393 | G32: -1190 | H32: 799
C33: Accounts Payable: | E33: -1970 | F33: 1043 | G33: -16 | H33: 2138
C34: Other Liabilities: | E34: -6292 | F34: 2174 | G34: 7702 | H34: 15784
C35: Total Net Change in Working Capital: | E35: =SUM(E31:E34) -> -5982 | F35: =SUM(F31:F34) -> -1156 | G35: =SUM(G31:G34) -> 6433 | H35: =SUM(H31:H34) -> 15940
C37: Capital Expenditures and Acquisitions: | E37: -353 | F37: -896 | G37: -1016 | H37: -1083
C39: Q3 Unlevered Free Cash Flow: | E39: =SUM(E22,E28,E35,E37) -> -16524 | F39: =SUM(F22,F28,F35,F37) -> -10309 | G39: =SUM(G22,G28,G35,G37) -> -5050 | H39: =SUM(H22,H28,H35,H37) -> 6595

Sheet Model
H4: Historical | N4: Projected:
B5: =Company_Name -> Butterfly Network, inc. | E5: Units: | G5: 44926 | H5: =EOMONTH(G5,12) -> 45291 | I5: =EOMONTH(H5,12) -> 45657 | J5: =EOMONTH(I5,12) -> 46022 | K5: =EOMONTH(J5,12) -> 46387 | L5: =EOMONTH(K5,12) -> 46752 | M5: =EOMONTH(L5,12) -> 47118 | N5: =EOMONTH(M5,12) -> 47483 | O5: =EOMONTH(N5,12) -> 47848
C7: Company Name: | E7: Name | G7: Butterfly Network, inc. | K7: Last Fiscal Year: | N7: 45657
C8: Ticker: | E8: Name | G8: BFLY | K8: Next Fiscal Year: | N8: =EOMONTH(N7,12) -> 46022
C9: Current Share Price: | E9: $ / Share | G9: 3.06 | K9: Most Recent Quarter End Date: | N9: 45608
C10: Diluted Shares Outstanding: | E10: M Shares | G10: 227.39 | K10: Valuation Date: | N10: 45966
C12: Effective Tax Rate: | E12: % | G12: 0.12
C13: Discount Rate (WACC): | E13: % | G13: =Discount_Rate -> 0.10883792 | K13: LTM Period: | N13: 45930
K14: Forward Year 1: | N14: =EOMONTH(N7,12) -> 46022
C15: Conversion Units: | E15: # | G15: 1000 | K15: Forward Year 2: | N15: =EOMONTH(N14,12) -> 46387
K16: Forward Year 3: | N16: =EOMONTH(N15,12) -> 46752
H18: Historical | N18: Projected:
B19: =Company_Name&" - Model Drivers and Assumptions" -> Butterfly Network, inc. - Model Drivers and Assumptions | E19: Units: | G19: =G5 -> 44926 | H19: =H5 -> 45291 | I19: =I5 -> 45657 | J19: =J5 -> 46022 | K19: =K5 -> 46387 | L19: =L5 -> 46752 | M19: =M5 -> 47118 | N19: =N5 -> 47483 | O19: =O5 -> 47848
C20: Income Statement
C22: Cost of product revenue % Revenue | E22: % | G22: =G74/G68 -> 0.53327497 | H22: =(H74-21000)/H68 -> 0.49093316 | I22: =I74/I68 -> 0.4498155 | J22: 0.4 | K22: 0.4 | L22: 0.4 | M22: 0.4 | N22: 0.4 | O22: 0.4
C23: Cost of software and services revenue % Revenue | E23: % | G23: =G75/G69 -> 0.3081247 | H23: =H75/H69 -> 0.32435045 | I23: =I75/I69 -> 0.31752585 | J23: 0.3 | K23: 0.3 | L23: 0.3 | M23: 0.3 | N23: 0.3 | O23: 0.3
C25: Research and development | E25: % | G25: =G81/(SUM(G$68:G$69)) -> 1.199673 | H25: =H81/(SUM(H$68:H$69)) -> 0.84394537 | I25: =I81/(SUM(I$68:I$69)) -> 0.46066101 | J25: 0.32 | K25: 0.25 | L25: =K25-3% -> 0.22 | M25: =L25-3% -> 0.19 | N25: =M25-3% -> 0.16 | O25: =N25-3% -> 0.13
C26: Sales and marketing | E26: % | G26: =G82/(SUM(G$68:G$69)) -> 0.8106554 | H26: =H82/(SUM(H$68:H$69)) -> 0.59291351 | I26: =I82/(SUM(I$68:I$69)) -> 0.50656868 | J26: 0.34 | K26: 0.28 | L26: 0.22 | M26: 0.2 | N26: 0.15 | O26: 0.15
C27: General and administrative | E27: % | G27: =G83/(SUM(G$68:G$69)) -> 1.0573103 | H27: =H83/(SUM(H$68:H$69)) -> 0.75285281 | I27: =I83/(SUM(I$68:I$69)) -> 0.48515648 | J27: 0.31 | K27: 0.25 | L27: 0.2 | M27: 0.15 | N27: 0.14 | O27: 0.14
C28: Other operating expenses | E28: % | G28: =G84/(SUM(G$68:G$69)) -> 0.10009538 | H28: =H84/(SUM(H$68:H$69)) -> 0.27562974 | I28: =I84/(SUM(I$68:I$69)) -> 0.049539339 | J28: 0.04 | K28: 0.02 | L28: 0.01 | M28: 0.01 | N28: 0.01 | O28: 0.01
C30: Interest income | E30: % | I30: =I89/H108 -> 0.037340911 | J30: =I30 -> 0.037340911 | K30: =J30 -> 0.037340911 | L30: =K30 -> 0.037340911 | M30: =L30 -> 0.037340911 | N30: =M30 -> 0.037340911 | O30: =N30 -> 0.037340911
C32: Beginning Balance | E32: $T | G32: 0 | H32: =G35 -> 461681 | I32: =H35 -> 595299 | J32: =I35 -> 667823 | K32: =J35 -> 717286.49 | L32: =K35 -> 725788.46 | M32: =L35 -> 717351.76 | N32: =M35 -> 685555.13 | O32: =N35 -> 631339.62
C33: (+) NOLs Created | E33: $T | G33: 461681 | H33: =IF(H94<0,H94*-1,0) -> 133618 | I33: =IF(I94<0,I94*-1,0) -> 72524 | J33: =IF(J94<0,J94*-1,0) -> 49463.491 | K33: =IF(K94<0,K94*-1,0) -> 8501.9708 | L33: =IF(L94<0,L94*-1,0) -> 0 | M33: =IF(M94<0,M94*-1,0) -> 0 | N33: =IF(N94<0,N94*-1,0) -> 0 | O33: =IF(O94<0,O94*-1,0) -> 0
C34: (-) NOLs Used | E34: $T | G34: 0 | H34: =IF(H94>0,H94*-1,0) -> 0 | I34: 0 | J34: =-MIN(+J32+J33,MAX(J94*J39,0)) -> 0 | K34: =-MIN(+K32+K33,MAX(K94*K39,0)) -> 0 | L34: =-MIN(+L32+L33,MAX(L94*L39,0)) -> -8436.7053 | M34: =-MIN(+M32+M33,MAX(M94*M39,0)) -> -31796.624 | N34: =-MIN(+N32+N33,MAX(N94*N39,0)) -> -54215.512 | O34: =-MIN(+O32+O33,MAX(O94*O39,0)) -> -77532.617
C35: Ending Balance | E35: $T | G35: =SUM(G32:G34) -> 461681 | H35: =SUM(H32:H34) -> 595299 | I35: =SUM(I32:I34) -> 667823 | J35: =SUM(J32:J34) -> 717286.49 | K35: =SUM(K32:K34) -> 725788.46 | L35: =SUM(L32:L34) -> 717351.76 | M35: =SUM(M32:M34) -> 685555.13 | N35: =SUM(N32:N34) -> 631339.62 | O35: =SUM(O32:O34) -> 553807
C37: Taxable Income After NOL | E37: $T | G37: 0 | H37: 0 | I37: 0 | J37: =SUM(J94,J34) -> -49463.491 | K37: =SUM(K94,K34) -> -8501.9708 | L37: =SUM(L94,L34) -> 2109.1763 | M37: =SUM(M94,M34) -> 7949.1559 | N37: =SUM(N94,N34) -> 13553.878 | O37: =SUM(O94,O34) -> 19383.154
C38: Cash Taxes Payable | E38: $T | G38: 0 | H38: 0 | I38: 0 | J38: =IF(J37<0,0,J37*Tax_Rate) -> 0 | K38: =IF(K37<0,0,K37*Tax_Rate) -> 0 | L38: =IF(L37<0,0,L37*Tax_Rate) -> 253.10116 | M38: =IF(M37<0,0,M37*Tax_Rate) -> 953.89871 | N38: =IF(N37<0,0,N37*Tax_Rate) -> 1626.4654 | O38: =IF(O37<0,0,O37*Tax_Rate) -> 2325.9785
C39: NOL Utilization Limit (% of EBT) | E39: $T | G39: 1 | H39: 1 | I39: 1 | J39: 0.8 | K39: 0.8 | L39: 0.8 | M39: 0.8 | N39: 0.8 | O39: 0.8
C41: Balance Sheet
C43: Days Receivables Outstanding | E43: % | H43: =H109*(H105-EOMONTH(H105,-12))/H72 -> 74.318209 | I43: =I109*(I105-EOMONTH(I105,-12))/I72 -> 92.744443 | J43: 85 | K43: 80 | L43: 75 | M43: 70 | N43: 70 | O43: 70
C44: Days Inventory Outstanding | E44: % | H44: =H110*(H105-EOMONTH(H105,-12))/H72 -> 404.44659 | I44: =I110*(I105-EOMONTH(I105,-12))/I72 -> 315.74503 | J44: 240 | K44: 210 | L44: 160 | M44: 140 | N44: 140 | O44: 140
C45: Current portion of vendor advances % COGS | E45: % | H45: =-H76/H72 -> 0.74421851 | I45: =-I76/I72 -> 0.40490641 | J45: 0.06 | K45: 0.05 | L45: 0.04 | M45: 0.03 | N45: 0.03 | O45: 0.03
C46: Prepaid expenses and other current assets % OpEx | E46: % | H46: =H111/-H85 -> 0.046600519 | I46: =I111/-I85 -> 0.054437611 | J46: 0.05 | K46: 0.04 | L46: 0.04 | M46: 0.03 | N46: 0.03 | O46: 0.03
C48: Non-current vendor advances | E48: % | H48: =H115/-H76 -> 0.36887285 | I48: =I115/-I76 -> 0.61968397 | J48: 0.2 | K48: 0.18 | L48: 0.16 | M48: 0.15 | N48: 0.14 | O48: 0.14
C49: Other non-current assets % Revenue | E49: % | H49: =H117/H72 -> 0.097450683 | I49: =I117/I72 -> 0.070195964 | J49: 0.06 | K49: 0.06 | L49: 0.05 | M49: 0.05 | N49: 0.04 | O49: 0.04
C51: Days Payables Outstanding | E51: % | H51: =H122*(H105-EOMONTH(H105,-12))/H72 -> 28.191958 | I51: =I122*(I105-EOMONTH(I105,-12))/I72 -> 18.956566 | J51: =AVERAGE(H51:I51) -> 23.574262 | K51: 20 | L51: 18 | M51: 16 | N51: 16 | O51: 16
C52: Deferred revenue, current % Revenue | E52: % | H52: =H127/H72 -> 0.34930197 | I52: =I127/I72 -> 0.28582919 | J52: 0.19 | K52: 0.17 | L52: 0.15 | M52: 0.13 | N52: 0.11 | O52: 0.11
C53: Accrued expenses and other current liabilities % OpEx | E53: % | H53: =H124/-H85 -> 0.14418401 | I53: =I124/-I85 -> 0.22472047 | J53: 0.2 | K53: 0.18 | L53: 0.17 | M53: 0.16 | N53: 0.15 | O53: 0.15
C55: Deferred revenue, non-current | E55: % | H55: =H127/H72 -> 0.34930197 | I55: =I127/I72 -> 0.28582919 | J55: 0.08 | K55: 0.07 | L55: 0.07 | M55: 0.06 | N55: 0.06 | O55: 0.06
C56: Operating lease liabilities | E56: %
...

Sheet Drivers
H2: Historical | N2: Projected:
B3: =Company_Name&" - Revenue Drivers" -> Butterfly Network, inc. - Revenue Drivers | E3: Units: | G3: 44926 | H3: =EOMONTH(G3,12) -> 45291 | I3: =EOMONTH(H3,12) -> 45657 | J3: =EOMONTH(I3,12) -> 46022 | K3: =EOMONTH(J3,12) -> 46387 | L3: =EOMONTH(K3,12) -> 46752 | M3: =EOMONTH(L3,12) -> 47118 | N3: =EOMONTH(M3,12) -> 47483 | O3: =EOMONTH(N3,12) -> 47848
C5: Product
C6: Hardware Units (Consolidated) | D6: # | G6: 21853.478 | H6: 17406.957 | I6: 16424.242 | J6: =J12/J11*Units -> 18938.209 | K6: =INDEX($J$7:$N$9,MATCH(Scenario,$C$7:$C$9,0),2) -> 17000 | L6: =INDEX($J$7:$N$9,MATCH(Scenario,$C$7:$C$9,0),3) -> 22000 | M6: =INDEX($J$7:$N$9,MATCH(Scenario,$C$7:$C$9,0),4) -> 24000 | N6: =INDEX($J$7:$N$9,MATCH(Scenario,$C$7:$C$9,0),5) -> 28000 | O6: =INDEX($J$7:$O$9,MATCH(Scenario,$C$7:$C$9,0),6) -> 32000
C7: Upside | D7: # | K7: 25000 | L7: 31000 | M7: 34000 | N7: 36500 | O7: 39000
C8: Base | D8: # | K8: 20000 | L8: 25000 | M8: 33000 | N8: 38000 | O8: 42000
C9: Downside | D9: # | K9: 17000 | L9: 22000 | M9: 24000 | N9: 28000 | O9: 32000
C10: % Growth | D10: % | H10: =H6/G6-1 -> -0.20346975 | I10: =I6/H6-1 -> -0.056455251 | J10: =J6/I6-1 -> 0.15306438 | K10: =K6/J6-1 -> -0.10234384 | L10: =L6/K6-1 -> 0.29411765 | M10: =M6/L6-1 -> 0.090909091 | N10: =N6/M6-1 -> 0.16666667 | O10: =O6/N6-1 -> 0.14285714
C11: Consolidated ASP | D11: $ | G11: 2300 | H11: 2300 | I11: 3300 | J11: 3350 | K11: 3350 | L11: 3500 | M11: 3500 | N11: 3750 | O11: 3750
C12: Product Revenue | D12: $T | G12: =G6*G11/Units -> 50263 | H12: =H6*H11/Units -> 40036 | I12: =I6*I11/Units -> 54200 | J12: 63443 | K12: =K6*K11/Units -> 56950 | L12: =L6*L11/Units -> 77000 | M12: =M6*M11/Units -> 84000 | N12: =N6*N11/Units -> 105000 | O12: =O6*O11/Units -> 120000
C14: Software
C15: Paying Subscribers | D15: # | G15: 70082 | H15: 80074 | I15: 90149 | J15: =J21/J20*Units -> 78285.714 | K15: =INDEX($J$16:$N$18,MATCH(Scenario,$C$16:$C$18,0),2) -> 80000 | L15: =INDEX($J$16:$N$18,MATCH(Scenario,$C$16:$C$18,0),3) -> 90000 | M15: =INDEX($J$16:$N$18,MATCH(Scenario,$C$16:$C$18,0),4) -> 120000 | N15: =INDEX($J$16:$N$18,MATCH(Scenario,$C$16:$C$18,0),5) -> 140000 | O15: =INDEX($J$16:$O$18,MATCH(Scenario,$C$16:$C$18,0),6) -> 160000
C16: Upside | D16: # | K16: 90000 | L16: 120000 | M16: 150000 | N16: 180000 | O16: 210000
C17: Base | D17: # | K17: 82000 | L17: 100000 | M17: 130000 | N17: 160000 | O17: 190000
C18: Downside | D18: # | K18: 80000 | L18: 90000 | M18: 120000 | N18: 140000 | O18: 160000
C19: % Growth | D19: % | H19: =H15/G15-1 -> 0.14257584 | I19: =I15/H15-1 -> 0.12582112 | J19: =J15/I15-1 -> -0.13159642 | K19: =K15/J15-1 -> 0.02189781 | L19: =L15/K15-1 -> 0.125 | M19: =M15/L15-1 -> 0.33333333 | N19: =N15/M15-1 -> 0.16666667 | O19: =O15/N15-1 -> 0.14285714
C20: ARPU ($ per year) | D20: $ | G20: 330 | H20: 323 | I20: 309 | J20: 350 | K20: 375 | L20: 400 | M20: 425 | N20: 450 | O20: 450
C21: Software Revenue | D21: $T | G21: =G15*G20/Units -> 23127.06 | H21: =H15*H20/Units -> 25863.902 | I21: =I15*I20/Units -> 27856.041 | J21: 27400 | K21: =K15*K20/Units -> 30000 | L21: =L15*L20/Units -> 36000 | M21: =M15*M20/Units -> 51000 | N21: =N15*N20/Units -> 63000 | O21: =O15*O20/Units -> 72000
C23: Butterfly Embedded | D23: $T | G23: 0 | H23: 0 | I23: 0 | J23: 6800 | K23: =INDEX($J$24:$N$26,MATCH(Scenario,$C$24:$C$26,0),2) -> 25000 | L23: =INDEX($J$24:$N$26,MATCH(Scenario,$C$24:$C$26,0),3) -> 25000 | M23: =INDEX($J$24:$N$26,MATCH(Scenario,$C$24:$C$26,0),4) -> 40000 | N23: =INDEX($J$24:$N$26,MATCH(Scenario,$C$24:$C$26,0),5) -> 40000 | O23: =INDEX($J$24:$O$26,MATCH(Scenario,$C$24:$C$26,0),6) -> 60000
C24: Upside | D24: $T | K24: 45000 | L24: 85000 | M24: 140000 | N24: 200000 | O24: 260000
C25: Base | D25: $T | K25: 29100 | L25: 50000 | M25: 70000 | N25: 95000 | O25: 125000
C26: Downside | D26: $T | K26: 25000 | L26: 25000 | M26: 40000 | N26: 40000 | O26: 60000
C28: Home Care & AI Workflow Revenue | D28: $T | G28: 0 | H28: 0 | I28: 0 | J28: =INDEX($J$29:$N$31,MATCH(Scenario,$C$29:$C$31,0),1) -> 0 | K28: =INDEX($J$29:$N$31,MATCH(Scenario,$C$29:$C$31,0),2) -> 1000 | L28: =INDEX($J$29:$N$31,MATCH(Scenario,$C$29:$C$31,0),3) -> 5000 | M28: =INDEX($J$29:$N$31,MATCH(Scenario,$C$29:$C$31,0),4) -> 15000 | N28: =INDEX($J$29:$N$31,MATCH(Scenario,$C$29:$C$31,0),5) -> 20000 | O28: =INDEX($J$29:$O$31,MATCH(Scenario,$C$29:$C$31,0),6) -> 25000
C29: Upside | D29: $T | J29: 0 | K29: 5000 | L29: 15000 | M29: 25000 | N29: 35000 | O29: 45000
C30: Base | D30: $T | J30: 0 | K30: 3000 | L30: 10000 | M30: 20000 | N30: 30000 | O30: 40000
C31: Downside | D31: $T | J31: 0 | K31: 1000 | L31: 5000 | M31: 15000 | N31: 20000 | O31: 25000
C33: Total Revenue | D33: $T | G33: =SUM(G12,G21,G23,G28) -> 73390.06 | H33: =SUM(H12,H21,H23,H28) -> 65899.902 | I33: =SUM(I12,I21,I23,I28) -> 82056.041 | J33: =SUM(J12,J21,J23,J28) -> 97643 | K33: =SUM(K12,K21,K23,K28) -> 112950 | L33: =SUM(L12,L21,L23,L28) -> 143000 | M33: =SUM(M12,M21,M23,M28) -> 190000 | N33: =SUM(N12,N21,N23,N28) -> 228000 | O33: =SUM(O12,O21,O23,O28) -> 277000
C34: % Growth | H34: =H33/G33-1 -> -0.10205957 | I34: =I33/H33-1 -> 0.24516181 | J34: =J33/I33-1 -> 0.18995505 | K34: =K33/J33-1 -> 0.15676495 | L34: =L33/K33-1 -> 0.26604692 | M34: =M33/L33-1 -> 0.32867133 | N34: =N33/M33-1 -> 0.2 | O34: =O33/N33-1 -> 0.21491228
H37: Historical | L37: Projected:
B38: ="CapEx & Depreciation - "&Company_Name -> CapEx & Depreciation - Butterfly Network, inc. | E38: Units: | G38: =G3 -> 44926 | H38: =H3 -> 45291 | I38: =I3 -> 45657 | J38: =J3 -> 46022 | K38: =K3 -> 46387 | L38: =L3 -> 46752 | M38: =M3 -> 47118 | N38: =N3 -> 47483 | O38: =O3 -> 47848
C40: CapEx: | E40: $T | G40: =-Model!G170 -> 18302 | H40: =-Model!H170 -> 5783 | I40: =-Model!I170 -> 2694 | J40: =J41*-Model!J85 -> 2465.4858 | K40: =K41*-Model!K85 -> 2710.8 | L40: =L41*-Model!L85 -> 2788.5 | M40: =M41*-Model!M85 -> 3135 | N40: =N41*-Model!N85 -> 3146.4 | O40: =O41*-Model!O85 -> 3573.3
C41: CapEx % OpEx (Cash only): | E41: % | G41: =G40/-Model!G85 -> 0.078725052 | H41: =H40/-Model!H85 -> 0.03559514 | I41: =I40/-Model!I85 -> 0.021859431 | J41: 0.025 | K41: 0.03 | L41: 0.03 | M41: 0.03 | N41: 0.03 | O41: 0.03
C43: Property, Plant and Equipment, Net: | E43: $T | G43: 23271 | H43: =Model!H114 -> 35638 | I43: =Model!I114 -> 28434 | J43: =I43+J40-J55 -> 26264.563 | K43: =J43+K40-K55 -> 24521.881 | L43: =K43+L40-L55 -> 22927.819 | M43: =L43+M40-M55 -> 21646.513 | N43: =M43+N40-N55 -> 20746.828 | O43: =N43+O40-O55 -> 20580.478
C45: D&A of Existing Net PP&E and Intangibles: | E45: % | G45: =G48/G43 -> 0.25503846 | H45: =H48/H43 -> 0.29670576 | I45: =I48/I43 -> 0.36371949 | J45: 0.15 | K45: =J45-1% -> 0.14 | L45: =K45-1% -> 0.13 | M45: =L45-1% -> 0.12 | N45: =M45-1% -> 0.11 | O45: =N45-1% -> 0.1
C46: D&A of NEW CapEx & Intangible Purchases: | E46: % | J46: 0.15 | K46: 0.15 | L46: 0.15 | M46: 0.15 | N46: 0.15 | O46: 0.15
C48: D&A - Existing PP&E and Intangibles, Net: | E48: $T | G48: =Model!G148 -> 5935 | H48: =Model!H148 -> 10574 | I48: =Model!I148 -> 10342 | J48: =I43*J45 -> 4265.1 | K48: =J43*K45 -> 3677.0388 | L48: =K43*L45 -> 3187.8446 | M48: =L43*M45 -> 2751.3383 | N48: =M43*N45 -> 2381.1164 | O48: =N43*O45 -> 2074.6828
C49: D&A - Year 1 CapEx & Intangible Purchases: | E49: $T | J49: =$J$40*J46 -> 369.82286 | K49: =$J$40*K46 -> 369.82286 | L49: =$J$40*L46 -> 369.82286 | M49: =$J$40*M46 -> 369.82286 | N49: =$J$40*N46 -> 369.82286 | O49: =$J$40*O46 -> 369.82286
C50: D&A - Year 2 CapEx & Intangible Purchases: | E50: $T | K50: =$K$40*J46 -> 406.62 | L50: =$K$40*K46 -> 406.62 | M50: =$K$40*L46 -> 406.62 | N50: =$K$40*M46 -> 406.62 | O50: =$K$40*N46 -> 406.62
C51: D&A - Year 3 CapEx & Intangible Purchases: | E51: $T | L51: =$L$40*J46 -> 418.275 | M51: =$L$40*K46 -> 418.275 | N51: =$L$40*L46 -> 418.275 | O51: =$L$40*M46 -> 418.275
C52: D&A - Year 4 CapEx & Intangible Purchases: | E52: $T | M52: =$M$40*J46 -> 470.25 | N52: =$M$40*K46 -> 470.25 | O52: =$M$40*L46 -> 470.25
...

Sheet DCF
I2: Historical | M2: Projected:
B3: =Company_Name&" - Discounted Cash Flow Analysis" -> Butterfly Network, inc. - Discounted Cash Flow Analysis | E3: Units: | H3: 44926 | I3: 45291 | J3: 45657 | K3: 46022 | L3: 46387 | M3: 46752 | N3: 47118 | O3: 47483 | P3: 47848
E5: Scenario: | G5: Downside | I5: Terminal Value - Multiples Method: | N5: Terminal Value - Perpetuity Growth Method:
C7: Company Name: | E7: Name | G7: =Company_Name -> Butterfly Network, inc. | I7: Median CY 26 TEV / EBITDA of Comps: | L7: =PubComps!S36 -> 11.70442 | N7: Expected Long-Term GDP Growth: | Q7: 0.015
C8: Ticker: | E8: Name | G8: =Ticker -> BFLY | I8: Median CY 26 TEV / EBITDA of Target: | L8: =PubComps!S40 -> NM
C9: Current Share Price: | E9: $ / Share | G9: 3.79
C10: Diluted Shares Outstanding: | E10: M Shares | G10: =Diluted -> 227.39 | I10: Baseline Terminal EBITDA Multiple: | L10: =INDEX(L11:L13,MATCH(Scenario,I11:I13,0),1) -> 9 | N10: Baseline Terminal FCF Growth Rate: | Q10: =INDEX(Q11:Q13,MATCH(Scenario,N11:N13,0),1) -> 0.01
I11: Upside | L11: 11 | N11: Upside | Q11: 0.02
C12: Effective Tax Rate: | E12: % | G12: =Tax_Rate -> 0.12 | I12: Base | L12: 10 | N12: Base | Q12: 0.015
C13: Discount Rate (WACC): | E13: % | G13: =WACC!L40 -> 0.10883792 | I13: Downside | L13: 9 | N13: Downside | Q13: 0.01
I16: Baseline Terminal Value: | L16: =L10*(P62/Units) -> 903.80546 | N16: Baseline Terminal Value: | Q16: =(+P60*(1+Terminal_Growth_Rate)/(Discount_Rate-Q10)*(1+Discount_Rate)^0.5)/Units -> 1326.9554
I17: Implied Terminal FCF Growth Rate: | L17: =(O62*(1+Discount_Rate)^0.5*Discount_Rate - L16) / (O62*(1+Discount_Rate)^0.5 + L16) -> 0.095681891 | N17: Implied Terminal EBITDA Multiple: | Q17: =Q16/(O62/Units) -> 18.563318
I19: (+) Present Value of Terminal Value: | L19: =L16/((1+Discount_Rate)^5) -> 539.18105 | N19: (+) Present Value of Terminal Value: | Q19: =Q16/((1+Discount_Rate)^5) -> 791.61857
C20: Current Equity Value: | G20: =$G$9*$G$10 -> 861.8081 | I20: (+) Present Value of UFCF: | L20: =NPV(Discount_Rate,L60:P60)/Units -> 187.19541 | N20: (+) Present Value of UFCF: | Q20: =NPV(Discount_Rate,L60:P60)/Units -> 187.19541
C21: (-) Cash & Investments: | G21: =-Model!I108/Units -> -88.775 | I21: Implied Enterprise Value: | L21: =SUM(L19:L20) -> 726.37646 | N21: Implied Enterprise Value: | Q21: =SUM(Q19:Q20) -> 978.81398
C22: (-) Net Operating Losses: | G22: 0
C23: (+) Debt & Finance Leases: | G23: 0 | I23: % of implied TEV from Terminal Value: | L23: =L20/L19 -> 0.3471847 | N23: % of implied TEV from Terminal Value: | Q23: =Q20/Q19 -> 0.23647173
C24: (+) Preferred Stock: | G24: 0
C25: (+) Operating Leases: | G25: 0 | I25: (+) Cash and Investments: | L25: =-G21 -> 88.775 | N25: (+) Cash and Investments: | Q25: =L25 -> 88.775
C26: (+) Noncontrolling Interests: | G26: 0 | I26: (+) Net Operating Losses: | L26: =-G22 -> 0 | N26: (+) Net Operating Losses: | Q26: =L26 -> 0
C27: (+) Unfunded Pensions: | G27: 0 | I27: (-)Debt and Finance Leases: | L27: =-G23 -> 0 | N27: (-)Debt and Finance Leases: | Q27: =L27 -> 0
C28: Current Enterprise Value: | G28: =SUM($G$20:$G$27) -> 773.0331 | I28: (-)Preferred Stock: | L28: =-G24 -> 0 | N28: (-)Preferred Stock: | Q28: =L28 -> 0
I29: (-) Operating Leases: | L29: =-G25 -> 0 | N29: (-) Operating Leases: | Q29: =L29 -> 0
I30: (-) Noncontrolling Interests: | L30: =-G26 -> 0 | N30: (-) Noncontrolling Interests: | Q30: =L30 -> 0
I31: (-)Unfunded Pensions: | L31: =-G27 -> 0 | N31: (-)Unfunded Pensions: | Q31: =L31 -> 0
I33: Implied Equity Value: | L33: =L21+SUM(L25:L31) -> 815.15146 | N33: Implied Equity Value: | Q33: =SUM(Q21:Q32) -> 1067.8255
I35: Diluted Shares Outstanding: | L35: =_xlfn.SINGLE(Diluted) -> 227.39 | N35: Diluted Shares Outstanding: | Q35: =_xlfn.SINGLE(Diluted) -> 227.39
I37: Implied Share Price from DCF: | L37: =L33/L35 -> 3.5848166 | N37: Implied Share Price from DCF: | Q37: =Q33/Q35 -> 4.6960088
I38: Premium / (Discount) to Current: | L38: =L37/G9-1 -> -0.054138088 | N38: Premium / (Discount) to Current: | Q38: =Q37/G9-1 -> 0.23905246
I40: Historical | M40: Projected:
B41: =Company_Name&" - Free Cash Flow Calculation" -> Butterfly Network, inc. - Free Cash Flow Calculation | E41: Units: | H41: 44926 | I41: 45291 | J41: 45657 | K41: 46022 | L41: 46387 | M41: 46752 | N41: 47118 | O41: 47483 | P41: 47848
C43: Revenue | E43: $T | H43: =Model!G72 -> 73390 | I43: =Model!H72 -> 65900 | J43: =Model!I72 -> 82056 | K43: =Model!J72 -> 97643 | L43: =Model!K72 -> 112950 | M43: =Model!L72 -> 143000 | N43: =Model!M72 -> 190000 | O43: =Model!N72 -> 228000 | P43: =Model!O72 -> 277000
C44: % Change | H44: 0 | I44: =I43/H43-1 -> -0.1020575 | J44: =J43/I43-1 -> 0.24515933 | K44: =K43/J43-1 -> 0.18995564 | L44: =L43/K43-1 -> 0.15676495 | M44: =M43/L43-1 -> 0.26604692 | N44: =N43/M43-1 -> 0.32867133 | O44: =O43/N43-1 -> 0.2 | P44: =P43/O43-1 -> 0.21491228
C46: Operating Expenses | E46: $T | H46: =Model!G85 -> -232480 | I46: =Model!H85 -> -162466 | J46: =Model!I85 -> -123242 | K46: =Model!J85 -> -98619.43 | L46: =Model!K85 -> -90360 | M46: =Model!L85 -> -92950 | N46: =Model!M85 -> -104500 | O46: =Model!N85 -> -104880 | P46: =Model!O85 -> -119110
C48: Operating Income (EBIT) | E48: $T | H48: =Model!G87 -> -193020 | I48: =Model!H87 -> -145610 | J48: =Model!I87 -> -74411 | K48: =Model!J87 -> -52852.43 | L48: =Model!K87 -> -9190 | M48: =Model!L87 -> 8450 | N48: =Model!M87 -> 36600 | O48: =Model!N87 -> 62220 | P48: =Model!O87 -> 88290
C50: (-) Taxes, Excluding Effect of Interest | E50: $T | H50: =Model!G96 -> -42 | I50: =Model!H96 -> -82 | J50: =Model!I96 -> 32 | K50: =Model!J96 -> 0 | L50: =Model!K96 -> 0 | M50: =Model!L96 -> 253.10116 | N50: =Model!M96 -> 953.89871 | O50: =Model!N96 -> 1626.4654 | P50: =Model!O96 -> 2325.9785
C52: Net Operating Profit After Taxes (NOPAT) | E52: $T | H52: =Model!G97 -> -168723 | I52: =Model!H97 -> -133700 | J52: =Model!I97 -> -72492 | K52: =Model!J97 -> -49463.491 | L52: =Model!K97 -> -8501.9708 | M52: =Model!L97 -> 10798.983 | N52: =Model!M97 -> 40699.678 | O52: =Model!N97 -> 69395.855 | P52: =Model!O97 -> 99241.75
C54: Depreciation and amortization: | E54: $T | H54: =Model!G148 -> 5935 | I54: =Model!H148 -> 10574 | J54: =Model!I148 -> 10342 | K54: =Model!J148 -> 4634.9229 | L54: =Model!K148 -> 4453.4817 | M54: =Model!L148 -> 4382.5624 | N54: =Model!M148 -> 4416.3061 | O54: =Model!N148 -> 4046.0843 | P54: =Model!O148 -> 3739.6507
C56: Change in Working Capital | E56: $T | H56: 0 | I56: 0 | J56: =J65-I65 -> 1712 | K56: =K65-J65 -> 1275.041 | L56: =L65-K65 -> 6375.2138 | M56: =M65-L65 -> 1927.6836 | N56: =N65-M65 -> 14775.444 | O56: =O65-N65 -> 21461.179 | P56: =P65-O65 -> 23909.336
C58: Capital Expenditures: | E58: $T | H58: =Model!G170 -> -18302 | I58: =Model!H170 -> -5783 | J58: =Model!I170 -> -2694 | K58: =Model!J170 -> -2465.4858 | L58: =Model!K170 -> -2710.8 | M58: =Model!L170 -> -2788.5 | N58: =Model!M170 -> -3135 | O58: =Model!N170 -> -3146.4 | P58: =Model!O170 -> -3573.3
...

Sheet WACC
B2: ="WACC Analysis - "&_xlfn.SINGLE(Company_Name) -> WACC Analysis - Butterfly Network, inc.
B3: ($ USD in Millions Except Per Share Amounts in USD as Stated)
B5: Discount Rate Calculations - Assumptions:
B6: Risk-Free Rate: | F6: 0.045
B7: Equity Risk Premium: | F7: 0.035
B8: Pre-Tax Cost of Debt: | F8: 0.02532108
B9: Cost of Preferred Stock: | F9: 0
B11: Company Name: | C11: Ticker: | D11: Levered Beta: | E11: (+) Debt & Capital Leases: | G11: (+) Preferred Stock: | I11: Equity Value: | K11: Effective Tax Rate:
B12: Comparable Companies - Unlevered Beta Calculation:
D13: Levered | G13: Preferred | I13: Equity | L13: Unlevered
B14: Name | C14: Ticker | D14: Beta | E14: Debt | F14: % Debt | G14: Stock | H14: % Preferred | I14: Value | J14: % Equity | K14: Tax Rate | L14: Beta
B15: =INDEX(Pub_Comps_Range,MATCH(B$11,Pub_Comps_Params,0),MATCH($C15,Pub_Comps_Tickers,0)) -> GE Healthcare Technologies Inc. | C15: GEHC | D15: =INDEX(Pub_Comps_Range,MATCH(D$11,Pub_Comps_Params,0),MATCH($C15,Pub_Comps_Tickers,0)) -> 1.27 | E15: =INDEX(Pub_Comps_Range,MATCH(E$11,Pub_Comps_Params,0),MATCH($C15,Pub_Comps_Tickers,0)) -> 10744 | F15: =E15/(E15+G15+I15) -> 0.21630314 | G15: =INDEX(Pub_Comps_Range,MATCH(G$11,Pub_Comps_Params,0),MATCH($C15,Pub_Comps_Tickers,0)) -> 0 | H15: =G15/(E15+G15+I15) -> 0 | I15: =INDEX(Pub_Comps_Range,MATCH(I$11,Pub_Comps_Params,0),MATCH($C15,Pub_Comps_Tickers,0)) -> 38927.03 | J15: =$I15/($E15+$G15+$I15) -> 0.78369686 | K15: =INDEX(Pub_Comps_Range,MATCH(K$11,Pub_Comps_Params,0),MATCH($C15,Pub_Comps_Tickers,0)) -> 0.177 | L15: =IFERROR(D15/(1+(E15/I15)*(1-K15)+G15/I15),"N/A") -> 1.0349175
B16: =INDEX(Pub_Comps_Range,MATCH(B$11,Pub_Comps_Params,0),MATCH($C16,Pub_Comps_Tickers,0)) -> Masimo Corporation | C16: MASI | D16: =INDEX(Pub_Comps_Range,MATCH(D$11,Pub_Comps_Params,0),MATCH($C16,Pub_Comps_Tickers,0)) -> 1.26 | E16: =INDEX(Pub_Comps_Range,MATCH(E$11,Pub_Comps_Params,0),MATCH($C16,Pub_Comps_Tickers,0)) -> 642.2 | F16: =E16/(E16+G16+I16) -> 0.076783648 | G16: =INDEX(Pub_Comps_Range,MATCH(G$11,Pub_Comps_Params,0),MATCH($C16,Pub_Comps_Tickers,0)) -> 0 | H16: =G16/(E16+G16+I16) -> 0 | I16: =INDEX(Pub_Comps_Range,MATCH(I$11,Pub_Comps_Params,0),MATCH($C16,Pub_Comps_Tickers,0)) -> 7721.56 | J16: =$I16/($E16+$G16+$I16) -> 0.92321635 | K16: =INDEX(Pub_Comps_Range,MATCH(K$11,Pub_Comps_Params,0),MATCH($C16,Pub_Comps_Tickers,0)) -> 0.2 | L16: =IFERROR(D16/(1+(E16/I16)*(1-K16)+G16/I16),"N/A") -> 1.181395
B17: =INDEX(Pub_Comps_Range,MATCH(B$11,Pub_Comps_Params,0),MATCH($C17,Pub_Comps_Tickers,0)) -> InMode, Ltd. | C17: INMD | D17: =INDEX(Pub_Comps_Range,MATCH(D$11,Pub_Comps_Params,0),MATCH($C17,Pub_Comps_Tickers,0)) -> 2.15 | E17: =INDEX(Pub_Comps_Range,MATCH(E$11,Pub_Comps_Params,0),MATCH($C17,Pub_Comps_Tickers,0)) -> 6.1 | F17: =E17/(E17+G17+I17) -> 0.0064169323 | G17: =INDEX(Pub_Comps_Range,MATCH(G$11,Pub_Comps_Params,0),MATCH($C17,Pub_Comps_Tickers,0)) -> 0 | H17: =G17/(E17+G17+I17) -> 0 | I17: =INDEX(Pub_Comps_Range,MATCH(I$11,Pub_Comps_Params,0),MATCH($C17,Pub_Comps_Tickers,0)) -> 944.51 | J17: =$I17/($E17+$G17+$I17) -> 0.99358307 | K17: =INDEX(Pub_Comps_Range,MATCH(K$11,Pub_Comps_Params,0),MATCH($C17,Pub_Comps_Tickers,0)) -> 0.2 | L17: =IFERROR(D17/(1+(E17/I17)*(1-K17)+G17/I17),"N/A") -> 2.1389487
B18: =INDEX(Pub_Comps_Range,MATCH(B$11,Pub_Comps_Params,0),MATCH($C18,Pub_Comps_Tickers,0)) -> Integra LifeSciences Holdings Corporation | C18: IART | D18: =INDEX(Pub_Comps_Range,MATCH(D$11,Pub_Comps_Params,0),MATCH($C18,Pub_Comps_Tickers,0)) -> 1.08 | E18: =INDEX(Pub_Comps_Range,MATCH(E$11,Pub_Comps_Params,0),MATCH($C18,Pub_Comps_Tickers,0)) -> 2007.7 | F18: =E18/(E18+G18+I18) -> 0.65954742 | G18: =INDEX(Pub_Comps_Range,MATCH(G$11,Pub_Comps_Params,0),MATCH($C18,Pub_Comps_Tickers,0)) -> 0 | H18: =G18/(E18+G18+I18) -> 0 | I18: =INDEX(Pub_Comps_Range,MATCH(I$11,Pub_Comps_Params,0),MATCH($C18,Pub_Comps_Tickers,0)) -> 1036.3571 | J18: =$I18/($E18+$G18+$I18) -> 0.34045258 | K18: =INDEX(Pub_Comps_Range,MATCH(K$11,Pub_Comps_Params,0),MATCH($C18,Pub_Comps_Tickers,0)) -> 0.2 | L18: =IFERROR(D18/(1+(E18/I18)*(1-K18)+G18/I18),"N/A") -> 0.42356043
B19: =INDEX(Pub_Comps_Range,MATCH(B$11,Pub_Comps_Params,0),MATCH($C19,Pub_Comps_Tickers,0)) -> CureVac N.V. | C19: CVAC | D19: =INDEX(Pub_Comps_Range,MATCH(D$11,Pub_Comps_Params,0),MATCH($C19,Pub_Comps_Tickers,0)) -> 1.78 | E19: =INDEX(Pub_Comps_Range,MATCH(E$11,Pub_Comps_Params,0),MATCH($C19,Pub_Comps_Tickers,0)) -> 41.5 | F19: =E19/(E19+G19+I19) -> 0.034394333 | G19: =INDEX(Pub_Comps_Range,MATCH(G$11,Pub_Comps_Params,0),MATCH($C19,Pub_Comps_Tickers,0)) -> 0 | H19: =G19/(E19+G19+I19) -> 0 | I19: =INDEX(Pub_Comps_Range,MATCH(I$11,Pub_Comps_Params,0),MATCH($C19,Pub_Comps_Tickers,0)) -> 1165.0941 | J19: =$I19/($E19+$G19+$I19) -> 0.96560567 | K19: =INDEX(Pub_Comps_Range,MATCH(K$11,Pub_Comps_Params,0),MATCH($C19,Pub_Comps_Tickers,0)) -> 0.121 | L19: =IFERROR(D19/(1+(E19/I19)*(1-K19)+G19/I19),"N/A") -> 1.725961
B20: =INDEX(Pub_Comps_Range,MATCH(B$11,Pub_Comps_Params,0),MATCH($C20,Pub_Comps_Tickers,0)) -> CareDx, Inc | C20: CDNA | D20: =INDEX(Pub_Comps_Range,MATCH(D$11,Pub_Comps_Params,0),MATCH($C20,Pub_Comps_Tickers,0)) -> 2.56 | E20: =INDEX(Pub_Comps_Range,MATCH(E$11,Pub_Comps_Params,0),MATCH($C20,Pub_Comps_Tickers,0)) -> 29.1 | F20: =E20/(E20+G20+I20) -> 0.028672889 | G20: =INDEX(Pub_Comps_Range,MATCH(G$11,Pub_Comps_Params,0),MATCH($C20,Pub_Comps_Tickers,0)) -> 0 | H20: =G20/(E20+G20+I20) -> 0 | I20: =INDEX(Pub_Comps_Range,MATCH(I$11,Pub_Comps_Params,0),MATCH($C20,Pub_Comps_Tickers,0)) -> 985.796 | J20: =$I20/($E20+$G20+$I20) -> 0.97132711 | K20: =INDEX(Pub_Comps_Range,MATCH(K$11,Pub_Comps_Params,0),MATCH($C20,Pub_Comps_Tickers,0)) -> 0.005 | L20: =IFERROR(D20/(1+(E20/I20)*(1-K20)+G20/I20),"N/A") -> 2.4869539
B22: Median: | D22: =MEDIAN(D15:D19) -> 1.27 | E22: =MEDIAN(E15:E19) -> 642.2 | F22: =MEDIAN(F15:F19) -> 0.076783648 | G22: =MEDIAN(G15:G19) -> 0 | H22: =MEDIAN(H15:H19) -> 0 | I22: =MEDIAN(I15:I19) -> 1165.0941 | J22: =MEDIAN(J15:J19) -> 0.92321635 | K22: =MEDIAN(K15:K19) -> 0.2 | L22: =MEDIAN(L15:L19) -> 1.181395
B24: =Company_Name -> Butterfly Network, inc. | C24: =Ticker -> BFLY | D24: =INDEX(Pub_Comps_Range,MATCH(D$11,Pub_Comps_Params,0),MATCH($C24,Pub_Comps_Tickers,0)) -> 2.24 | E24: =INDEX(Pub_Comps_Range,MATCH(E$11,Pub_Comps_Params,0),MATCH($C24,Pub_Comps_Tickers,0)) -> 0 | F24: =E24/($E24+$G24+$I24) -> 0 | G24: =INDEX(Pub_Comps_Range,MATCH(G$11,Pub_Comps_Params,0),MATCH($C24,Pub_Comps_Tickers,0)) -> 0 | H24: =G24/($E24+$G24+$I24) -> 0 | I24: =INDEX(Pub_Comps_Range,MATCH(I$11,Pub_Comps_Params,0),MATCH($C24,Pub_Comps_Tickers,0)) -> 697.61268 | J24: =I24/($E24+$G24+$I24) -> 1 | K24: 0.132 | L24: =IFERROR(D24/(1+(E24/I24)*(1-K24)+G24/I24),"N/A") -> 2.24
B26: =TEXT(Company_Name,"")& " - Levered Beta & WACC Calculation:" -> Butterfly Network, inc. - Levered Beta & WACC Calculation:
D27: Unlevered | G27: Preferred | I27: Equity | L27: Levered
C28: Ticker | D28: Beta | E28: Debt | F28: % Debt | G28: Stock | H28: % Preferred | I28: Value | J28: % Equity | K28: Tax Rate | L28: Beta
B29: Current Capital Structure: | C29: =C24 -> BFLY | D29: =L24 -> 2.24 | E29: 5461 | F29: 0.033001557 | G29: 0 | H29: 0 | I29: 160016.04 | J29: 0.96699844 | K29: 0.132 | L29: =D29*(1+E29/I29*(1-K29)+G29/I29) -> 2.3063554
B30: "Optimal" Capital Structure: | D30: =L22 -> 1.181395 | E30: =(E29+I29)*F30 -> 12705.931 | F30: =F22 -> 0.076783648 | G30: 0 | H30: 0 | I30: =(I29+E29)*J30 -> 152771.11 | J30: =J22 -> 0.92321635 | K30: 0.132 | L30: =D30*(1+E30/I30*(1-K30)+G30/I30) -> 1.2666814
B32: Cost of Equity Based on Comparables, Current Capital Structure: | L32: =Risk_Free_Rate+Equity_Risk_Premium*L29 -> 0.12572244
B33: Cost of Equity Based on Comparables, "Optimal" Capital Structure: | L33: =Risk_Free_Rate+Equity_Risk_Premium*L30 -> 0.08933385
B34: Cost of Equity Based on Historical Beta: | L34: =Risk_Free_Rate+Equity_Risk_Premium*D24 -> 0.1234
B36: WACC, Current Capital Structure: | L36: =L32*J29+Cost_of_Debt*(1-K29)*F29+Cost_of_Preferred*H29 -> 0.12229873
B37: WACC, "Optimal" Capital Structure: | L37: =L33*J30+Cost_of_Debt*(1-K30)*F30+Cost_of_Preferred*H30 -> 0.084162076
B38: WACC, Current Capital Structure and Historical Cost of Equity: | L38: =L34*J29+Cost_of_Debt*(1-K29)*F29+Cost_of_Preferred*H29 -> 0.12005294
B40: Average WACC Produced by All Methods: | L40: =AVERAGE(L36:L38) -> 0.10883792

Sheet Valsum
B2: ="Valuation Summary - "&Company_Name -> Valuation Summary - Butterfly Network, inc.
B3: ($ USD in Millions Except Per Share Amounts in USD as Stated)
B5: ="Valuation Statistics - "&TEXT(Company_Name,"") -> Valuation Statistics - Butterfly Network, inc. | C5: Range of Valuation Multiples / Premiums | I5: Implied Per-Share Value Range
D7: 75th | F7: 25th | H7: Applicable | J7: 25th | L7: 75th
C8: Maximum | D8: Percentile | E8: Median | F8: Percentile | G8: Minimum | H8: Company | I8: Minimum | J8: Percentile | K8: Median | L8: Percentile | M8: Maximum
B9: Methodology Name | C9: Multiple | D9: Multiple | E9: Multiple | F9: Multiple | G9: Multiple | H9: Figure | I9: Multiple | J9: Multiple | K9: Multiple | L9: Multiple | M9: Multiple
B11: Public Company Comparables:
B12: LTM TEV / Revenue: | C12: {=TRANSPOSE(PubComps!N34:V38)} -> 3.8137989 | D12: 2.3900268 | E12: 1.9782445 | F12: 1.5900166 | G12: 1.0954753 | H12: {=TRANSPOSE(PubComps!N21:V21)} -> 203.9 | I12: =(I34+SUM($E$33:$E$39))/$E$42 -> 1.3727183 | J12: =(J34+SUM($E$33:$E$39))/$E$42 -> 1.8161721 | K12: =(K34+SUM($E$33:$E$39))/$E$42 -> 2.164295 | L12: =(L34+SUM($E$33:$E$39))/$E$42 -> 2.5335391 | M12: =(M34+SUM($E$33:$E$39))/$E$42 -> 3.8102317
B13: ="CY "&TEXT(EOMONTH(Hist_Year,12),"YY")&" TEV / Revenue:" -> CY 25 TEV / Revenue: | C13: 9.7895338 | D13: 4.609228 | E13: 2.1391078 | F13: 1.7826113 | G13: 1.1954076 | H13: 63.443 | I13: =(I35+SUM($E$33:$E$39))/$E$42 -> 0.72393353 | J13: =(J35+SUM($E$33:$E$39))/$E$42 -> 0.88776644 | K13: =(K35+SUM($E$33:$E$39))/$E$42 -> 0.98723081 | L13: =(L35+SUM($E$33:$E$39))/$E$42 -> 1.6764073 | M13: =(M35+SUM($E$33:$E$39))/$E$42 -> 3.1217397
B14: ="CY "&TEXT(EOMONTH(Hist_Year,24),"YY")&" TEV / Revenue:" -> CY 26 TEV / Revenue: | C14: 7.6140819 | D14: 4.2940256 | E14: 1.9808956 | F14: 1.6938083 | G14: 1.1485901 | H14: 56.95 | I14: =(I36+SUM($E$33:$E$39))/$E$42 -> 0.67807382 | J14: =(J36+SUM($E$33:$E$39))/$E$42 -> 0.81462413 | K14: =(K36+SUM($E$33:$E$39))/$E$42 -> 0.88652536 | L14: =(L36+SUM($E$33:$E$39))/$E$42 -> 1.4658506 | M14: =(M36+SUM($E$33:$E$39))/$E$42 -> 2.2973612
B15: LTM TEV / EBITDA: | C15: 19.048184 | D15: 14.799892 | E15: 8.59825 | F15: 3.7193967 | G15: 3.4394694 | H15: 258.9 | I15: =(I37+SUM($E$33:$E$39))/$E$42 -> 4.3064938 | J15: =(J37+SUM($E$33:$E$39))/$E$42 -> 4.6252114 | K15: =(K37+SUM($E$33:$E$39))/$E$42 -> 10.180139 | L15: =(L37+SUM($E$33:$E$39))/$E$42 -> 17.241158 | M15: =(M37+SUM($E$33:$E$39))/$E$42 -> 22.078147
B16: ="CY "&TEXT(EOMONTH(Hist_Year,12),"YY")&" TEV / EBITDA:" -> CY 25 TEV / EBITDA: | C16: 25.12647 | D16: 16.527485 | E16: 12.563107 | F16: 8.8412647 | G16: 4.6798936 | H16: -46.163568 | I16: =(I38+SUM($E$33:$E$39))/$E$42 -> -0.55967978 | J16: =(J38+SUM($E$33:$E$39))/$E$42 -> -1.4045003 | K16: =(K38+SUM($E$33:$E$39))/$E$42 -> -2.1600899 | L16: =(L38+SUM($E$33:$E$39))/$E$42 -> -2.9649179 | M16: =(M38+SUM($E$33:$E$39))/$E$42 -> -4.7106403
B17: ="CY "&TEXT(EOMONTH(Hist_Year,24),"YY")&" TEV / EBITDA:" -> CY 26 TEV / EBITDA: | C17: 16.386828 | D17: 15.099559 | E17: 11.70442 | F17: 8.3368081 | G17: 4.3555446 | H17: -3.7799891 | I17: =(I39+SUM($E$33:$E$39))/$E$42 -> 0.3180047 | J17: =(J39+SUM($E$33:$E$39))/$E$42 -> 0.25182267 | K17: =(K39+SUM($E$33:$E$39))/$E$42 -> 0.1958416 | L17: =(L39+SUM($E$33:$E$39))/$E$42 -> 0.13940293 | M17: =(M39+SUM($E$33:$E$39))/$E$42 -> 0.11800416
B18: LTM P / E: | C18: 16.998703 | D18: 16.966342 | E18: 11.486025 | F18: 5.8336593 | G18: 5.2851547 | H18: -65.4 | I18: =(I40+SUM($E$33:$E$39))/$E$42 -> -1.1296632 | J18: =(J40+SUM($E$33:$E$39))/$E$42 -> -1.2874195 | K18: =(K40+SUM($E$33:$E$39))/$E$42 -> -2.9131054 | L18: =(L40+SUM($E$33:$E$39))/$E$42 -> -4.4893082 | M18: =(M40+SUM($E$33:$E$39))/$E$42 -> -4.4986155
B19: ="CY "&TEXT(EOMONTH(Hist_Year,12),"YY")&" P / E:" -> CY 25 P / E: | C19: 36.945263 | D19: 23.165358 | E19: 14.310018 | F19: 9.0690567 | G19: 6.1322906 | H19: -49.463491 | I19: =(I41+SUM($E$33:$E$39))/$E$42 -> -0.94353093 | J19: =(J41+SUM($E$33:$E$39))/$E$42 -> -1.5823572 | K19: =(K41+SUM($E$33:$E$39))/$E$42 -> -2.7224083 | L19: =(L41+SUM($E$33:$E$39))/$E$42 -> -4.6486849 | M19: =(M41+SUM($E$33:$E$39))/$E$42 -> -7.646188
