Workbook
Name Bundle: DCF!$F$6
Name COGS: DCF!$E$121
Name Company_Name: Model!$H$7
Name Cost_of_Debt: WACC!$F$8
Name Cost_of_Preferred: WACC!$F$9
Name Diluted: Model!$H$10
Name Discount_Rate: DCF!$F$15
Name Equity_Risk_Premium: WACC!$F$7
Name Forward_Year_1: Model!$O$14
Name Forward_Year_2: Model!$O$15
Name Forward_Year_3: Model!$O$16
Name Hist_Year: Model!$O$7
Name LTM: Model!$O$13
Name Pub_Comps_Params: PubComps_Data!$C$3:$C$99
Name Pub_Comps_Range: PubComps_Data!$C$3:$AL$99
Name Pub_Comps_Tickers: PubComps_Data!$C$3:$AL$3
Name Risk_Free_Rate: WACC!$F$6
Name Scenario: DCF!$F$5
Name Share_Price: Model!$H$9
Name Tax_Rate: Model!$H$12
Name Terminal_Growth_Rate: DCF!$P$10
Name Ticker: Model!$H$8
Name Units: Model!$H$15
Name Uplift: DCF!$F$7
Name Valuation_Date: Model!$O$10

Sheet Cover
B2: =Company_Name&" - Operating Model and Valuation - Cover Page and Navigation" -> Ouster, Inc. - Operating Model and Valuation - Cover Page and Navigation
C12: Company Name: | D12: =Company_Name -> Ouster, Inc.
C13: Model Name: | D13: Operating Model and Valuation (5-Year Forecast)
C14: Author: | D14: Glenn Rentrop, Atlantic Walk Research
C16: File Name: | D16: =MID(CELL("filename"),SEARCH("[",CELL("filename"))+1, SEARCH("]",CELL("filename"))-SEARCH("[",CELL("filename"))-1) -> OUSTMODEL.xlsx
C17: Analysis Date: | D17: =Valuation_Date -> 46062
C19: Navigation, Summary, or Graph Worksheet:
C20: Financial Model Worksheet:
C21: Data and Back-End Calculation Worksheet:
B23: # | C23: Sheet Name | D23: Link to Sheet
B24: =_xlfn.SHEET(INDIRECT(D24&"!A1")) -> 2 | C24: Model and Valuation Summary | D24: Summary
B25: =_xlfn.SHEET(INDIRECT(D25&"!A1")) -> 3 | C25: Graphs | D25: Graphs
B26: =_xlfn.SHEET(INDIRECT(D26&"!A1")) -> 4 | C26: Quarterly figures & KPIs | D26: Q
B27: =_xlfn.SHEET(INDIRECT(D27&"!A1")) -> 5 | C27: Operating Scenarios and 3-Statement Model | D27: Model
B28: =_xlfn.SHEET(INDIRECT(D28&"!A1")) -> 6 | C28: Debt, Capex, D&A | D28: Drivers
B29: =_xlfn.SHEET(INDIRECT(D29&"!A1")) -> 7 | C29: Discounted Cash Flow Analysis and Sensitivities | D29: DCF
B30: =_xlfn.SHEET(INDIRECT(D30&"!A1")) -> 8 | C30: Weighted Average Cost of Capital (WACC) Calculations | D30: WACC
B31: =_xlfn.SHEET(INDIRECT(D31&"!A1")) -> 9 | C31: Comparable Public Companies - Output | D31: PubComps
B32: =_xlfn.SHEET(INDIRECT(D32&"!A1")) -> 10 | C32: Comparable Public Companies - Data and Calculations | D32: PubComps_Data
B33: =_xlfn.SHEET(INDIRECT(D33&"!A1")) -> 11 | C33: Precedent Transactions | D33: MAComps

Sheet Summary
C3: =Company_Name&" - Summary of Operating Model and Valuation - "&Scenario&" Case" -> Ouster, Inc. - Summary of Operating Model and Valuation - Base Case
C4: ($ in Thousands Except Per Share and Per Unit Data)
G6: Historical: | K6: Projected: | R6: Projected
C7: Summary of Operational Performance: | E7: Units: | G7: =[1]Model!H17 -> 44561 | H7: =[1]Model!I17 -> 44926 | I7: =[1]Model!J17 -> 45291 | J7: =[1]Model!K17 -> 45657 | K7: =[1]Model!L17 -> 46022 | L7: =[1]Model!M17 -> 46387 | M7: =[1]Model!N17 -> 46752 | N7: =[1]Model!O17 -> 47118 | O7: =[1]Model!P17 -> 47483 | P7: =EOMONTH(O7,12) -> 47848 | R7: CAGR:
C8: Company-Wide:
C10: Revenue | E10: $T | G10: =Drivers!F6 -> 33578 | H10: =Drivers!G6 -> 41029 | I10: =Drivers!H6 -> 83279 | J10: =Drivers!I6 -> 111101 | K10: =Drivers!J6 -> 169000 | L10: =Drivers!K6 -> 254788 | M10: =Drivers!L6 -> 365254.16 | N10: =Drivers!M6 -> 535307.84 | ... P10: =Drivers!O6 -> 912910.72 | R10: =(O10/J10)^(1/YEARFRAC(J$7,O$7,))-1 -> 0.45005662
C12: Sensors Shipped | E12: # | G12: =Drivers!F8 -> 6475 | H12: =Drivers!G8 -> 8650 | I12: =Drivers!H8 -> 13400 | J12: =Drivers!I8 -> 17300 | K12: =Drivers!J8 -> 25000 | L12: =Drivers!K8 -> 33750 | M12: =Drivers!L8 -> 47250 | N12: =Drivers!M8 -> 68512.5 | ... P12: =Drivers!O8 -> 120239.44
C15: Gross Profit: | E15: $T | G15: =Model!G72 -> 9086 | H15: =Model!H72 -> 10930 | I15: =Model!I72 -> 8314 | J15: =Model!J72 -> 40460 | K15: =Model!K72 -> 82810 | L15: =Model!L72 -> 101915.2 | M15: =Model!M72 -> 146101.67 | N15: =Model!N72 -> 214123.14 | ... P15: =Model!P72 -> 365164.29 | R15: =(O15/J15)^(1/YEARFRAC(J$7,O$7,))-1 -> 0.47752683
C16: Profit Margin: | E16: % | G16: =G15/G10 -> 0.27059384 | H16: =H15/H10 -> 0.26639694 | I16: =I15/I10 -> 0.099833091 | J16: =J15/J10 -> 0.36417314 | K16: =K15/K10 -> 0.49 | L16: =L15/L10 -> 0.4 | M16: =M15/M10 -> 0.4 | N16: =N15/N10 -> 0.4 | ... P16: =P15/P10 -> 0.4
C18: Total Operating Expenses | E18: $T | G18: =-Model!G79 -> 108796 | H18: =-Model!H79 -> 156353 | I18: =-Model!I79 -> 381506 | J18: =-Model!J79 -> 144637 | K18: =-Model!K79 -> 160207.64 | L18: =-Model!L79 -> 155000 | M18: =-Model!M79 -> 155000 | N18: =-Model!N79 -> 155000 | ... P18: =-Model!P79 -> 155000
C20: EBIT | E20: $T | G20: =Model!G81 -> -99710 | H20: =Model!H81 -> -145423 | I20: =Model!I81 -> -373192 | J20: =Model!J81 -> -104177 | K20: =Model!K81 -> -77397.642 | L20: =Model!L81 -> -53084.8 | M20: =Model!M81 -> -8898.3344 | N20: =Model!N81 -> 59123.137 | ... P20: =Model!P81 -> 210164.29
C22: Comprehensive Income: | E22: $T | G22: =Model!G95 -> -93987 | H22: =Model!H95 -> -138703 | I22: =Model!I95 -> -373769 | J22: =Model!J95 -> -98240 | K22: =Model!K95 -> -67208.942 | L22: =Model!L95 -> -41538.641 | M22: =Model!M95 -> -4046.9856 | N22: =Model!N95 -> 53089.667 | ... P22: =Model!P95 -> 182422.33 | R22: =(O22/J22)^(1/YEARFRAC(J$7,O$7,))-1 -> -2.0283012
C23: Basic Earnings per Share (EPS): | E23: $ as Stated | G23: =Model!G100 -> -0.7 | H23: =Model!H100 -> -0.78 | I23: =Model!I100 -> -10.1 | J23: =Model!J100 -> -2.08 | K23: =Model!K100 -> -1.273786 | L23: =Model!L100 -> -0.75907701 | M23: =Model!M100 -> -0.064737467 | N23: =Model!N100 -> 0.94055831 | ... P23: =Model!P100 -> 3.0455256
C25: Capital expenditures: | E25: $T | G25: =Model!G183 -> -4283 | H25: =Model!H183 -> -5422 | I25: =Model!I183 -> -3006 | J25: =Model!J183 -> -3756 | K25: =Model!K183 -> -4806.2293 | L25: =Model!L183 -> -4650 | M25: =Model!M183 -> -4650 | N25: =Model!N183 -> -4650 | ... P25: =Model!P183 -> -4650 | R25: =(O25/J25)^(1/YEARFRAC(J$7,O$7,))-1 -> 0.043627403
C26: % Revenue: | E26: %
C28: Cash Flow From Operations: | E28: $T | G28: =Model!G180 -> -71061 | H28: =Model!H180 -> -110690 | I28: =Model!I180 -> -137890 | J28: =Model!J180 -> -33694 | K28: =Model!K180 -> -51116.581 | L28: =Model!L180 -> -37652.437 | M28: =Model!M180 -> -2912.2802 | N28: =Model!N180 -> 54390.923 | ... P28: =Model!P180 -> 196538.15 | R28: =(O28/J28)^(1/YEARFRAC(J$7,O$7,))-1 -> -2.2942193
C29: Cash Flow From Investing: | E29: $T | G29: =Model!G187 -> -15229 | H29: =Model!H187 -> -5147 | I29: =Model!I187 -> 50601 | J29: =Model!J187 -> 14652 | K29: =Model!K187 -> 7818.7707 | L29: =Model!L187 -> -2661.9517 | M29: =Model!M187 -> 27862.011 | N29: =Model!N187 -> -24312.76 | ... P29: =Model!P187 -> -79568.676 | R29: =(O29/J29)^(1/YEARFRAC(J$7,O$7,))-1 -> -2.1410686
C30: Cash Flows From Financing Activities: | E30: $T | G30: =Model!G204 -> 258304 | H30: =Model!H204 -> 55602 | I30: =Model!I204 -> 15657 | J30: =Model!J204 -> 15393 | K30: =Model!K204 -> 94100 | L30: =Model!L204 -> 0 | M30: =Model!M204 -> 0 | N30: =Model!N204 -> 0 | ... P30: =Model!P204 -> 0 | R30: =(O30/J30)^(1/YEARFRAC(J$7,O$7,))-1 -> -1
C32: Total Assets: | E32: $T | G32: =Model!G121 -> 307702 | H32: =Model!H121 -> 256137 | I32: =Model!I121 -> 330743 | J32: =Model!J121 -> 276148 | K32: =Model!K121 -> 332134.86 | L32: =Model!L121 -> 316873.53 | M32: =Model!M121 -> 341705.37 | N32: =Model!N121 -> 435035.49 | ... P32: =Model!P121 -> 807978.68 | R32: =(O32/J32)^(1/YEARFRAC(J$7,O$7,))-1 -> 0.16296275
C33: Long-term Debt: | E33: $T | G33: =Model!G131 -> 0 | H33: =Model!H131 -> 39574 | I33: =Model!I131 -> 43975 | J33: =Model!J131 -> 0 | K33: =Model!K131 -> 0 | L33: =Model!L131 -> 0 | M33: =Model!M131 -> 0 | N33: =Model!N131 -> 0 | ... P33: =Model!P131 -> 0 | R33: =(O33/J33)^(1/YEARFRAC(J$7,O$7,))-1 -> #DIV/0!
C34: Cash and Cash Equivalents: | E34: $T | G34: =SUM(Model!G106:G108) -> 183621 | H34: =SUM(Model!H106:H108) -> 123189 | I34: =SUM(Model!I106:I108) -> 190701 | J34: =SUM(Model!J106:J108) -> 172744 | K34: =SUM(Model!K106:K108) -> 210565.69 | L34: =SUM(Model!L106:L108) -> 132850.13 | M34: =SUM(Model!M106:M108) -> 124987.19 | N34: =SUM(Model!N106:N108) -> 174281.54 | ... P34: =SUM(Model!P106:P108) -> 483102.52 | R34: =(O34/J34)^(1/YEARFRAC(J$7,O$7,))-1 -> 0.11039289
C36: EBITDA: | E36: $T | G36: =Model!G97 -> -94233 | H36: =Model!H97 -> -135967 | I36: =Model!I97 -> -356044 | J36: =Model!J97 -> -94341 | K36: =Model!K97 -> -75152.108 | L36: =Model!L97 -> -49884.908 | M36: =Model!M97 -> -4939.6756 | N36: =Model!N97 -> 63720.509 | ... P36: =Model!P97 -> 215814.4 | R36: =(O36/J36)^(1/YEARFRAC(J$7,O$7,))-1 -> -2.0743962
C37: EBITDA Margin: | E37: % | G37: =DCF!G64 -> -2.8063911 | H37: =DCF!H64 -> -3.3139243 | I37: =DCF!I64 -> -4.2753155 | J37: =DCF!J64 -> -0.84914627 | K37: =DCF!K64 -> -0.44468703 | L37: =DCF!L64 -> -0.19578987 | M37: =DCF!M64 -> -0.013523941 | N37: =DCF!N64 -> 0.11903526 | ... P37: =DCF!P64 -> 0.23640253

Sheet Graphs
J2: ="Revenue and Gross Profit" -> Revenue and Gross Profit | V2: Revenue and EBITDA
J18: ="Revenue and OpEx" -> Revenue and OpEx | V18: ="Revenue and EBIT" -> Revenue and EBIT
J33: ="Sensors Shipped and ASP - Annual" -> Sensors Shipped and ASP - Annual | V33: Sensors Shipped and ASP - Quarterly
J52: Revenue By Segment

Sheet Q
B2: =Company_Name&" - Q3 Financial Results" -> Ouster, Inc. - Q3 Financial Results
B3: ($ in Thousands Except Per Share and Per Unit Data)
B6: Reported Income Statement and Cash Flow Statement Figures from Q3: | H6: FY25- Q1 | I6: FY25- Q2 | J6: FY25- Q3 | K6: FY25- Q4
C8: Royalty Revenue: | H8: 0 | I8: 0 | J8: 0 | K8: 21000
C10: Product Revenue: | H10: 32632 | I10: 35049 | J10: 39525 | K10: 41000
C11: % Growth | I11: =I10/H10-1 -> 0.074068399 | J11: =J10/I10-1 -> 0.12770692 | K11: =K10/J10-1 -> 0.037318153
C13: Total Revenue: | H13: =SUM(H8,H10) -> 32632 | I13: =SUM(I8,I10) -> 35049 | J13: =SUM(J8,J10) -> 39525 | K13: =SUM(K8,K10) -> 62000
C15: Operating Income (EBIT): | H15: -23830 | I15: -26822 | J15: -24251
C16: Annual Operating Margin: | H16: =+H15/H10 -> -0.73026477 | I16: =+I15/I10 -> -0.76527148 | J16: =+J15/J10 -> -0.61356104
C18: Taxes, Excluding Effect of Interest: | H18: 195 | I18: -3616 | J18: 72
C20: Net Operating Profit After Tax (NOPAT): | H20: =SUM(H15,H18) -> -23635 | I20: =SUM(I15,I18) -> -30438 | J20: =SUM(J15,J18) -> -24179
C22: Adjustments for Non-Cash Charges:
C23: Depreciation & Amortization: | H23: 1795 | I23: 1859 | J23: 2053
C24: Deferred Income Taxes: | H24: 0 | I24: 0 | J24: 0
C25: Other Operating Activities: | H25: 9402 | I25: 15211 | J25: 12060
C26: Total Adjustments for Non-Cash Charges: | H26: =SUM(H23:H25) -> 11197 | I26: =SUM(I23:I25) -> 17070 | J26: =SUM(J23:J25) -> 14113
C28: Net Change in Working Capital:
C29: Accounts Receivable: | H29: 4137 | I29: 2334 | J29: -9401
C30: Inventories: | H30: 1051 | I30: 998 | J30: -1594
C31: Accounts Payable: | H31: 4120 | I31: 2305 | J31: 2791
C32: Other Liabilities: | H32: -3367 | I32: -3404 | J32: -2518
C33: Total Net Change in Working Capital: | H33: =SUM(H29:H32) -> 5941 | I33: =SUM(I29:I32) -> 2233 | J33: =SUM(J29:J32) -> -10722
C35: Capital Expenditures and Acquisitions: | H35: -552 | I35: -889 | J35: -1702
C37: Q3 Unlevered Free Cash Flow: | H37: =SUM(H20,H26,H33,H35) -> -7049 | I37: =SUM(I20,I26,I33,I35) -> -12024 | J37: =SUM(J20,J26,J33,J35) -> -22490
C39: Sensors Shipped | H39: 4700 | I39: 5500 | J39: 7200 | K39: 8100
C40: % change | I40: =I39/H39-1 -> 0.17021277 | J40: =J39/I39-1 -> 0.30909091 | K40: =K39/J39-1 -> 0.125
C42: ASP | H42: =H10/H39*Units -> 6942.9787 | I42: =I10/I39*Units -> 6372.5455 | J42: =J10/J39*Units -> 5489.5833 | K42: 6760
C43: % change | I43: =I42/H42-1 -> -0.082159732 | J43: =J42/I42-1 -> -0.13855721

Sheet Model
I4: Historical | O4: Projected:
B5: =Company_Name -> Ouster, Inc. | E5: Units: | G5: =EOMONTH(H5,-12) -> 44561 | H5: 44926 | I5: =EOMONTH(H5,12) -> 45291 | J5: =EOMONTH(I5,12) -> 45657 | K5: =EOMONTH(J5,12) -> 46022 | L5: =EOMONTH(K5,12) -> 46387 | M5: =EOMONTH(L5,12) -> 46752 | N5: =EOMONTH(M5,12) -> 47118 | O5: =EOMONTH(N5,12) -> 47483
C7: Company Name: | E7: Name | H7: Ouster, Inc. | L7: Last Fiscal Year: | O7: 45657
C8: Ticker: | E8: Name | H8: OUST | L8: Next Fiscal Year: | O8: =EOMONTH(O7,12) -> 46022
C9: Current Share Price: | E9: $ / Share | H9: 21.06 | L9: Most Recent Quarter End Date: | O9: 45608
C10: Diluted Shares Outstanding: | E10: M Shares | H10: 52.56 | L10: Valuation Date: | O10: 46062
C12: Effective Tax Rate: | E12: % | H12: 0.21
C13: Discount Rate (WACC): | E13: % | H13: =Discount_Rate -> 0.10836181 | L13: LTM Period: | O13: 45930
L14: Forward Year 1: | O14: =EOMONTH(O7,12) -> 46022
C15: Conversion Units: | E15: # | H15: 1000 | L15: Forward Year 2: | O15: =EOMONTH(O14,12) -> 46387
L16: Forward Year 3: | O16: =EOMONTH(O15,12) -> 46752
I18: Historical | N18: Projected:
B19: =Company_Name&" - Financial Drivers" -> Ouster, Inc. - Financial Drivers | E19: Units: | G19: =EOMONTH(H19,-12) -> 44561 | H19: 44926 | I19: =EOMONTH(H19,12) -> 45291 | J19: =EOMONTH(I19,12) -> 45657 | K19: =EOMONTH(J19,12) -> 46022 | L19: =EOMONTH(K19,12) -> 46387 | M19: =EOMONTH(L19,12) -> 46752 | N19: =EOMONTH(M19,12) -> 47118 | O19: =EOMONTH(N19,12) -> 47483 | P19: =EOMONTH(O19,12) -> 47848
C20: INCOME STATEMENT
C22: Cost of product % Revenue | E22: % | G22: =G71/-G69 -> 0.72940616 | H22: =H71/-H69 -> 0.73360306 | I22: =I71/-I69 -> 0.90016691 | J22: =J71/-J69 -> 0.63582686 | K22: =INDEX($K$23:$P$25,MATCH(Scenario,$C$23:$C$25,0),1) -> 0.51 | L22: =INDEX($K$23:$P$25,MATCH(Scenario,$C$23:$C$25,0),2) -> 0.6 | M22: =INDEX($K$23:$P$25,MATCH(Scenario,$C$23:$C$25,0),3) -> 0.6 | N22: =INDEX($K$23:$P$25,MATCH(Scenario,$C$23:$C$25,0),4) -> 0.6 | O22: =INDEX($K$23:$P$25,MATCH(Scenario,$C$23:$C$25,0),5) -> 0.6 | P22: =INDEX($K$23:$P$25,MATCH(Scenario,$C$23:$C$25,0),6) -> 0.6
C23: Upside | E23: % | K23: 0.6 | L23: 0.55 | M23: =L23-2% -> 0.53 | N23: 0.55 | O23: 0.55 | P23: 0.55
C24: Base | E24: % | K24: 0.51 | L24: 0.6 | M24: 0.6 | N24: 0.6 | O24: 0.6 | P24: 0.6
C25: Downside | E25: % | K25: 0.63 | L25: 0.65 | M25: 0.61 | N25: 0.62 | O25: 0.63 | P25: 0.64
C27: Research and development % Revenue | E27: % | G27: =G75/G$69 -> 1.0298112 | H27: =H75/H$69 -> 1.5675985 | I27: =I75/I$69 -> 1.0952341 | J27: =J75/J$69 -> 0.52280358 | K27: 0.45 | L27: 0.28 | M27: 0.22 | N27: 0.17 | O27: 0.13 | P27: 0.1
C28: Sales and marketing % Revenue | E28: % | G28: =G76/G$69 -> 0.6628745 | H28: =H76/H$69 -> 0.75149285 | I28: =I76/I$69 -> 0.499994 | J28: =J76/J$69 -> 0.25069081 | K28: 0.21 | L28: 0.13 | M28: 0.11 | N28: 0.09 | O28: 0.07 | P28: 0.05
C29: General and administrative % Revenue | E29: % | G29: =G77/G$69 -> 1.547412 | H29: =H77/H$69 -> 1.491701 | I29: =I77/I$69 -> 0.98442585 | J29: =J77/J$69 -> 0.52835708 | K29: 0.37 | L29: 0.25 | M29: 0.19 | N29: 0.15 | O29: 0.12 | P29: 0.09
C31: Interest income % Cash & Equivalents | E31: % | H31: =H83/SUM(G106:G108) -> 0.012024768 | I31: =I83/SUM(H106:H108) -> 0.07336694 | J31: =J83/SUM(I106:I108) -> 0.057262416 | K31: 0.05 | L31: 0.05 | M31: 0.04 | N31: 0.04 | O31: 0.03 | P31: 0.03
C33: Beginning NOLs Balance | E33: $T | G33: 0 | H33: =G36 -> 461681 | I33: =H36 -> 595299 | J33: =I36 -> 667823 | K33: =J36 -> 701611 | L33: =K36 -> 768561.19 | M33: =L36 -> 809596.9 | N33: =M36 -> 813193.71 | O33: =N36 -> 761882.09 | P33: =O36 -> 653106.83
C34: (+) NOLs Created | E34: $T | G34: 461681 | H34: 133618 | I34: 72524 | J34: 33788 | K34: =IF(K88<0,K88*-1,0) -> 66950.192 | L34: =IF(L88<0,L88*-1,0) -> 41035.703 | M34: =IF(M88<0,M88*-1,0) -> 3596.8137 | N34: =IF(N88<0,N88*-1,0) -> 0 | O34: =IF(O88<0,O88*-1,0) -> 0 | P34: =IF(P88<0,P88*-1,0) -> 0
C35: (-) NOLs Used | E35: $T | G35: 0 | H35: 0 | I35: 0 | J35: 0 | K35: =-MIN(+K33+K34,MAX(K88*K40,0)) -> 0 | L35: =-MIN(+L33+L34,MAX(L88*L40,0)) -> 0 | M35: =-MIN(+M33+M34,MAX(M88*M40,0)) -> 0 | N35: =-MIN(+N33+N34,MAX(N88*N40,0)) -> -51311.616 | O35: =-MIN(+O33+O34,MAX(O88*O40,0)) -> -108775.26 | P35: =-MIN(+P33+P34,MAX(P88*P40,0)) -> -175601.63
C36: Ending Balance | E36: $T | G36: =SUM(G33:G35) -> 461681 | H36: =SUM(H33:H35) -> 595299 | I36: =SUM(I33:I35) -> 667823 | J36: =SUM(J33:J35) -> 701611 | K36: =SUM(K33:K35) -> 768561.19 | L36: =SUM(L33:L35) -> 809596.9 | M36: =SUM(M33:M35) -> 813193.71 | N36: =SUM(N33:N35) -> 761882.09 | ... P36: =SUM(P33:P35) -> 477505.2
C38: Taxable Income After NOL | E38: $T | G38: - | H38: - | I38: - | J38: -33788 | K38: =-SUM(K119,K35) -> -1262.5 | L38: =-SUM(L119,L35) -> -1319.375 | M38: =-SUM(M119,M35) -> -1376.9688 | N38: =-SUM(N119,N35) -> 49863.155 | O38: =-SUM(O119,O35) -> 107423.43 | P38: =-SUM(P119,P35) -> 174227.47
C39: Cash Taxes Payable | E39: $T | G39: - | H39: - | I39: - | J39: - | K39: =IF(K38<0,0,K38*Tax_Rate) -> 0 | L39: =IF(L38<0,0,L38*Tax_Rate) -> 0 | M39: =IF(M38<0,0,M38*Tax_Rate) -> 0 | N39: =IF(N38<0,0,N38*Tax_Rate) -> 10471.262 | O39: =IF(O38<0,0,O38*Tax_Rate) -> 22558.921 | P39: =IF(P38<0,0,P38*Tax_Rate) -> 36587.769
C40: NOL Utilization Limit (% of EBT) | E40: % | G40: 0.8 | H40: 0.8 | I40: 0.8 | J40: 0.8 | K40: 0.8 | L40: 0.8 | M40: 0.8 | N40: 0.8 | O40: 0.8 | P40: 0.8
C42: BALANCE SHEET
C44: Short-term investments | E44: % | I44: =I108/H106 -> 1.1319917 | J44: =J108/I106 -> 2.4804377 | K44: 2.5 | L44: 0.8 | M44: 0.8 | N44: 0.8 | O44: 0.8 | P44: 0.8
C45: Days receivables outstanding | E45: Days | G45: =G109*(G$104-EOMONTH(G$104,-12))/G$69 -> 116.56129 | H45: =H109*(H$104-EOMONTH(H$104,-12))/H$69 -> 99.930415 | I45: =I109*(I$104-EOMONTH(I$104,-12))/I$69 -> 63.888916 | J45: =J109*(J$104-EOMONTH(J$104,-12))/J$69 -> 59.103032 | K45: 52 | L45: =K45-4 -> 48 | M45: =L45-4 -> 44 | N45: =M45-4 -> 40 | O45: =N45-4 -> 36 | P45: =O45-4 -> 32
C46: Days inventory outstanding | E46: Days | G46: =G110*(G$104-EOMONTH(G$104,-12))/G$69 -> 80.961344 | H46: =H110*(H$104-EOMONTH(H$104,-12))/H$69 -> 173.76843 | I46: =I110*(I$104-EOMONTH(I$104,-12))/I$69 -> 101.82255 | J46: =J110*(J$104-EOMONTH(J$104,-12))/J$69 -> 54.08252 | K46: 52 | L46: =K46-4 -> 48 | M46: =L46-4 -> 44 | N46: =M46-4 -> 40 | O46: =N46-4 -> 36 | P46: =O46-4 -> 32
C47: Prepaid expenses and other current assets % Revenue | E47: % | G47: =G111/G69 -> 0.1657633 | H47: =H111/H69 -> 0.20821858 | I47: =I111/I69 -> 0.41603525 | J47: =J111/J69 -> 0.11476044 | K47: 0.08 | L47: 0.07 | M47: 0.07 | N47: 0.06 | O47: 0.06 | P47: 0.05
C49: Operating lease, right-of-use assets % Operating lease liability | E49: % | G49: =G115/SUM(G126,G129) -> 0.7863035 | H49: =H115/SUM(H126,H129) -> 0.78196258 | I49: =I115/SUM(I126,I129) -> 0.71600509 | J49: =J115/SUM(J126,J129) -> 0.7065679 | K49: =AVERAGE(G49:J49) -> 0.74770977 | L49: =AVERAGE(H49:K49) -> 0.73806133 | M49: =AVERAGE(I49:L49) -> 0.72708602 | N49: =AVERAGE(J49:M49) -> 0.72985626 | O49: =AVERAGE(K49:N49) -> 0.73567835 | P49: =AVERAGE(L49:O49) -> 0.73267049
C50: Unbilled receivable, non-current portion % Revenue | E50: % | G50: =G116/G69 -> 0 | H50: =H116/H69 -> 0 | I50: =I116/I69 -> 0.12688673 | J50: =J116/J69 -> 0.0912053 | K50: 0.07 | L50: 0.06 | M50: 0.05 | N50: 0.05 | O50: 0.04 | P50: 0.04
C52: Days Payables Outstanding | E52: Days | G52: =G123*(G104-EOMONTH(G104,-12))/G69 -> 52.861844 | H52: =H123*(H104-EOMONTH(H104,-12))/H69 -> 78.268298 | I52: =I123*(I104-EOMONTH(I104,-12))/I69 -> 15.53723 | J52: =J123*(J104-EOMONTH(J104,-12))/J69 -> 20.714557 | K52: 22 | L52: =K52-2 -> 20 | M52: =L52-2 -> 18 | N52: =M52-2 -> 16 | O52: =N52-2 -> 14 | P52: =O52-2 -> 12
C53: Accrued and other current liabilities % Opex | E53: % | G53: =G124/-G79 -> 0.13027133 | H53: =H124/-H79 -> 0.11175353 | I53: =I124/-I79 -> 0.15246418 | J53: =J124/-J79 -> 0.2115019 | K53: 0.13 | L53: =K53-1% -> 0.12 | M53: =L53-1% -> 0.11 | N53: =M53-1% -> 0.1 | O53: =N53-1% -> 0.09 | P53: =O53-1% -> 0.08
C54: Contract liabilities, current % Revenue | E54: % | G54: =G125/G69 -> 0 | H54: =H125/H69 -> 0 | I54: =I125/I69 -> 0.15472088 | J54: =J125/J69 -> 0.30918714 | K54: =AVERAGE(I54:J54) -> 0.23195401 | L54: 0.15 | M54: =L54-4% -> 0.11 | N54: =M54-1% -> 0.1 | O54: 0.1 | P54: 0.1
C55: Operating lease liability, current portion | E55: % | H55: =G126/G129 -> 0.18922754 | I55: =H126/H129 -> 0.24037313 | J55: =I126/I129 -> 0.37690551 | K55: =J126/J129 -> 0.55124866 | L55: =AVERAGE(H55:K55) -> 0.33943871 | M55: =AVERAGE(I55:L55) -> 0.3769915 | N55: =AVERAGE(J55:M55) -> 0.4111461 | O55: =AVERAGE(K55:N55) -> 0.41970624 | P55: =AVERAGE(L55:O55) -> 0.38682064
...

Sheet Drivers
H2: Historical | N2: Projected:
B3: =Company_Name&" - Revenue Drivers" -> Ouster, Inc. - Revenue Drivers | E3: Units: | F3: =EOMONTH(G3,-12) -> 44561 | G3: 44926 | H3: =EOMONTH(G3,12) -> 45291 | I3: =EOMONTH(H3,12) -> 45657 | J3: =EOMONTH(I3,12) -> 46022 | K3: =EOMONTH(J3,12) -> 46387 | L3: =EOMONTH(K3,12) -> 46752 | M3: =EOMONTH(L3,12) -> 47118 | N3: =EOMONTH(M3,12) -> 47483 | O3: =EOMONTH(N3,12) -> 47848
C6: Revenue | E6: $T | F6: {=Model!G69} -> 33578 | G6: {=Model!H69} -> 41029 | H6: {=Model!I69} -> 83279 | I6: {=Model!J69} -> 111101 | J6: 169000 | K6: =IF(Bundle="yes",(((K8-K22)*K14)+(K22*K24))/1000+K31,(K8*K14)/1000+K31) -> 254788 | L6: =IF(Bundle="yes",(((L8-L22)*L14)+(L22*L24))/1000+L31,(L8*L14)/1000+L31) -> 365254.16 | M6: =IF(Bundle="yes",(((M8-M22)*M14)+(M22*M24))/1000+M31,(M8*M14)/1000+M31) -> 535307.84 | N6: =IF(Bundle="yes",(((N8-N22)*N14)+(N22*N24))/1000+N31,(N8*N14)/1000+N31) -> 712266.9 | O6: =IF(Bundle="yes",(((O8-O22)*O14)+(O22*O24))/1000+O31,(O8*O14)/1000+O31) -> 912910.72
C8: Sensors shipped | E8: # | F8: 6475 | G8: 8650 | H8: 13400 | I8: 17300 | J8: 25000 | K8: =J8*(1+K9) -> 33750 | L8: =K8*(1+L9) -> 47250 | M8: =L8*(1+M9) -> 68512.5 | N8: =M8*(1+N9) -> 92491.875 | O8: =N8*(1+O9) -> 120239.44
C9: % Change | E9: % | G9: =G8/F8-1 -> 0.33590734 | H9: =H8/G8-1 -> 0.54913295 | I9: =I8/H8-1 -> 0.29104478 | J9: =J8/I8-1 -> 0.44508671 | K9: =INDEX($K$10:$O$12,MATCH(Scenario,$C$10:$C$12,0),1) -> 0.35 | L9: =INDEX($K$10:$O$12,MATCH(Scenario,$C$10:$C$12,0),2) -> 0.4 | M9: =INDEX($K$10:$O$12,MATCH(Scenario,$C$10:$C$12,0),3) -> 0.45 | N9: =INDEX($K$10:$O$12,MATCH(Scenario,$C$10:$C$12,0),4) -> 0.35 | O9: =INDEX($K$10:$O$12,MATCH(Scenario,$C$10:$C$12,0),5) -> 0.3
C10: Upside | E10: % | K10: =K11+5% -> 0.4 | L10: =L11+5% -> 0.45 | M10: =M11+5% -> 0.5 | N10: =N11+5% -> 0.4 | O10: =O11+5% -> 0.35
C11: Base | E11: % | K11: 0.35 | L11: 0.4 | M11: 0.45 | N11: 0.35 | O11: 0.3
C12: Downside | E12: % | K12: 0.2 | L12: 0.3 | M12: 0.4 | N12: 0.3 | O12: 0.25
C14: ASP | E14: $T | F14: =F6*1000/F8 -> 5185.7915 | G14: =G6*1000/G8 -> 4743.237 | H14: =H6*1000/H8 -> 6214.8507 | I14: =I6*1000/I8 -> 6422.0231 | J14: =J6/J8*Units -> 6760 | K14: =J14*(1+K15) -> 6895.2 | L14: =K14*(1+L15) -> 7033.104 | M14: =L14*(1+M15) -> 7103.435 | N14: =M14*(1+N15) -> 6961.3663 | O14: =N14*(1+O15) -> 6822.139
C15: % Change | G15: =G14/F14-1 -> -0.08533982 | H15: =H14/G14-1 -> 0.31025516 | I15: =I14/H14-1 -> 0.033335052 | J15: =J14/I14-1 -> 0.052627789 | K15: 0.02 | L15: 0.02 | M15: 0.01 | N15: -0.02 | O15: -0.02
C17: Attach Rate | E17: % | K17: =INDEX($K$18:$O$20,MATCH(Scenario,$C$18:$C$20,0),1) -> 0.15 | L17: =INDEX($K$18:$O$20,MATCH(Scenario,$C$18:$C$20,0),2) -> 0.2 | M17: =INDEX($K$18:$O$20,MATCH(Scenario,$C$18:$C$20,0),3) -> 0.25 | N17: =INDEX($K$18:$O$20,MATCH(Scenario,$C$18:$C$20,0),4) -> 0.3 | O17: =INDEX($K$18:$O$20,MATCH(Scenario,$C$18:$C$20,0),5) -> 0.35
C18: Upside | E18: % | K18: =K19+5% -> 0.2 | L18: =L19+5% -> 0.25 | M18: =M19+5% -> 0.3 | N18: =N19+5% -> 0.35 | O18: =O19+5% -> 0.4
C19: Base | E19: % | K19: 0.15 | L19: 0.2 | M19: 0.25 | N19: 0.3 | O19: 0.35
C20: Downside | E20: % | K20: 0.1 | L20: 0.15 | M20: 0.2 | N20: 0.2 | O20: 0.25
C22: Perception Systems shipped | E22: # | K22: =K8*K17 -> 5062.5 | L22: =L8*L17 -> 9450 | M22: =M8*M17 -> 17128.125 | N22: =N8*N17 -> 27747.562 | O22: =O8*O17 -> 42083.803
C24: Perception System ASP | E24: $T | K24: =K14+K26 -> 8095.2 | L24: =L14+L26 -> 8233.104 | M24: =M14+M26 -> 8303.435 | N24: =N14+N26 -> 8161.3663 | O24: =O14+O26 -> 8022.139
C26: Perception System uplift | E26: # | K26: =INDEX($K$27:$O$29,MATCH(Uplift,$C$27:$C$29,0),1) -> 1200 | L26: =INDEX($K$27:$O$29,MATCH(Uplift,$C$27:$C$29,0),2) -> 1200 | M26: =INDEX($K$27:$O$29,MATCH(Uplift,$C$27:$C$29,0),3) -> 1200 | N26: =INDEX($K$27:$O$29,MATCH(Uplift,$C$27:$C$29,0),4) -> 1200 | O26: =INDEX($K$27:$O$29,MATCH(Uplift,$C$27:$C$29,0),5) -> 1200
C27: Upside | E27: # | K27: 1500 | L27: 1500 | M27: 1500 | N27: 1500 | O27: 1500
C28: Base | E28: # | K28: 1200 | L28: 1200 | M28: 1200 | N28: 1200 | O28: 1200
C29: Downside | E29: # | K29: 900 | L29: 900 | M29: 900 | N29: 900 | O29: 900
C31: Stereolabs Revenue | E31: $T | K31: 16000 | L31: =K31*(1+L32) -> 21600 | M31: =L31*(1+M32) -> 28080 | N31: =M31*(1+N32) -> 35100 | O31: =N31*(1+O32) -> 42120
C32: % Change | E32: % | L32: =INDEX($L$33:$O$35,MATCH(Scenario,$C$33:$C$35,0),1) -> 0.35 | M32: =INDEX($L$33:$O$35,MATCH(Scenario,$C$33:$C$35,0),2) -> 0.3 | N32: =INDEX($L$33:$O$35,MATCH(Scenario,$C$33:$C$35,0),3) -> 0.25 | O32: =INDEX($L$33:$O$35,MATCH(Scenario,$C$33:$C$35,0),4) -> 0.2
C33: Upside | E33: % | L33: =L34+5% -> 0.4 | M33: =M34+5% -> 0.35 | N33: =N34+5% -> 0.3 | O33: =O34+5% -> 0.25
C34: Base | E34: % | L34: 0.35 | M34: 0.3 | N34: 0.25 | O34: 0.2
C35: Downside | E35: % | L35: =L34-5% -> 0.3 | M35: =M34-5% -> 0.25 | N35: =N34-5% -> 0.2 | O35: =O34-5% -> 0.15
C38: Software attached sensors | E38: # | I38: =I8*I39 -> 1297.5 | J38: =J8*J39 -> 3750
C39: % mix | E39: % | I39: =J39/2 -> 0.075 | J39: 0.15 | K39: 0.2
C41: Bloomberg estimate | E41: $T | J41: 148000 | K41: 202000 | L41: 278000 | M41: 392000 | N41: 514000
E42: % | J42: =J41/I6-1 -> 0.33212122 | K42: =K41/J41-1 -> 0.36486486 | L42: =L41/K41-1 -> 0.37623762 | M42: =M41/L41-1 -> 0.41007194 | N42: =N41/M41-1 -> 0.31122449
C44: Oppenheimer estimates | E44: $T | J44: 147900 | K44: 217500 | L44: 295300 | M44: 392400 | N44: 513900
E45: % | J45: =J44/I6-1 -> 0.33122114 | K45: =K44/J44-1 -> 0.47058824 | L45: =L44/K44-1 -> 0.35770115 | M45: =M44/L44-1 -> 0.32881815 | N45: =N44/M44-1 -> 0.30963303
H49: Historical | L49: Projected:
B50: ="CapEx & Depreciation - "&Company_Name -> CapEx & Depreciation - Ouster, Inc. | E50: Units: | F50: =F3 -> 44561 | G50: =G3 -> 44926 | H50: =H3 -> 45291 | I50: =I3 -> 45657 | J50: =J3 -> 46022 | K50: =K3 -> 46387 | L50: =L3 -> 46752 | M50: =M3 -> 47118 | ... O50: =O3 -> 47848
C52: CapEx: | E52: $T | F52: =-Model!G183 -> 4283 | G52: =-Model!H183 -> 5422 | H52: =-Model!I183 -> 3006 | I52: =-Model!J183 -> 3756 | J52: =-Model!K79*Drivers!J53 -> 4806.2293 | K52: =-Model!L79*Drivers!K53 -> 4650 | L52: =-Model!M79*Drivers!L53 -> 4650 | M52: =-Model!N79*Drivers!M53 -> 4650 | N52: =-Model!O79*Drivers!N53 -> 4650 | O52: =-Model!P79*Drivers!O53 -> 4650
C53: CapEx % OpEx (Cash only): | E53: % | F53: =-F52/Model!G79 -> 0.039367256 | G53: =-G52/Model!H79 -> 0.03467794 | H53: =-H52/Model!I79 -> 0.0078792994 | I53: =-I52/Model!J79 -> 0.025968459 | J53: 0.03 | K53: 0.03 | L53: 0.03 | M53: 0.03 | N53: 0.03 | O53: 0.03
C55: Property, Plant and Equipment, Net: | E55: $T | F55: =Model!G114 -> 10054 | G55: =Model!H114 -> 9695 | H55: =Model!I114 -> 10228 | I55: =Model!J114 -> 10164 | J55: =I55+J52-J67 -> 12724.695 | K55: =J55+K52-K67 -> 14174.803 | L55: =K55+L52-L67 -> 14866.144 | M55: =L55+M52-M67 -> 14918.773 | N55: =M55+N52-N67 -> 14416.773 | O55: =N55+O52-O67 -> 13416.662
C57: D&A of Existing Net PP&E and Intangibles: | E57: % | G57: =G60/G55 -> 0.97534812 | H57: =H60/H55 -> 1.6765741 | I57: =I60/I55 -> 0.96772924 | J57: 0.15 | K57: =J57-1% -> 0.14 | L57: =K57-1% -> 0.13 | M57: =L57-1% -> 0.12 | N57: =M57-1% -> 0.11 | O57: =N57-1% -> 0.1
C58: D&A of NEW CapEx & Intangible Purchases: | E58: % | J58: 0.15 | K58: 0.15 | L58: 0.15 | M58: 0.15 | N58: 0.15 | O58: 0.15
C60: D&A - Existing PP&E and Intangibles, Net: | E60: $T | F60: =Model!G151 -> 5477 | G60: =Model!H151 -> 9456 | H60: =Model!I151 -> 17148 | I60: =Model!J151 -> 9836 | J60: =I55*J57 -> 1524.6 | K60: =J55*K57 -> 1781.4573 | L60: =K55*L57 -> 1842.7244 | M60: =L55*M57 -> 1783.9373 | N60: =M55*N57 -> 1641.065 | O60: =N55*O57 -> 1441.6773
C61: D&A - Year 1 CapEx & Intangible Purchases: | E61: $T | J61: =$J$52*J58 -> 720.93439 | K61: =$J$52*K58 -> 720.93439 | L61: =$J$52*L58 -> 720.93439 | M61: =$J$52*M58 -> 720.93439 | N61: =$J$52*N58 -> 720.93439 | O61: =$J$52*O58 -> 720.93439
...

Sheet DCF
I2: Historical | M2: Projected:
B3: =Company_Name&" - Discounted Cash Flow Analysis" -> Ouster, Inc. - Discounted Cash Flow Analysis | E3: Units: | H3: 44926 | I3: 45291 | J3: 45657 | K3: 46022 | L3: 46387 | M3: 46752 | N3: 47118 | O3: 47483 | P3: 47848
E5: Scenario: | F5: Base | H5: Terminal Value - Multiples Method: | M5: Terminal Value - Perpetuity Growth Method:
E6: Bundle: | F6: yes
E7: Uplift: | F7: Base | H7: Median LTM TEV / EBITDA of Comps: | K7: =PubComps!Q36 -> 17.459867 | M7: Expected Long-Term GDP Growth: | P7: 0.015
H8: Median LTM TEV / EBITDA of Target: | K8: =[2]PubComps!S40 -> NM
C9: Company Name: | E9: Name | F9: =Company_Name -> Ouster, Inc.
C10: Ticker: | E10: Name | F10: =Ticker -> OUST | H10: Baseline Terminal EBITDA Multiple: | K10: =INDEX(K11:K13,MATCH(Scenario,H11:H13,0),1) -> 15.5 | M10: Baseline Terminal FCF Growth Rate: | P10: =INDEX(P11:P13,MATCH(Scenario,M11:M13,0),1) -> 0.02
C11: Current Share Price: | E11: $ / Share | F11: =Share_Price -> 21.06 | H11: Upside | K11: 16.5 | M11: Upside | P11: 0.03
C12: Diluted Shares Outstanding: | E12: M Shares | F12: =Diluted -> 52.56 | H12: Base | K12: 15.5 | M12: Base | P12: 0.02
H13: Downside | K13: 14.5 | M13: Downside | P13: 0.01
C14: Effective Tax Rate: | E14: % | F14: =Tax_Rate -> 0.21
C15: Discount Rate (WACC): | E15: % | F15: =WACC!L40 -> 0.10836181
H16: Baseline Terminal Value: | K16: =K10*(P63/Units) -> 3345.1232 | M16: Baseline Terminal Value: | P16: =(+P61*(1+Terminal_Growth_Rate)/(Discount_Rate-P10)*(1+Discount_Rate)^0.5)/Units -> 2939.0093
H17: Implied Terminal FCF Growth Rate: | K17: =(N63*(1+Discount_Rate)^0.5*Discount_Rate - O16) / (N63*(1+Discount_Rate)^0.5 + O16) -> 0.10836181 | M17: Implied Terminal EBITDA Multiple: | P17: =P16/(P63/Units) -> 13.618226
H19: (+) Present Value of Terminal Value: | K19: =K16/((1+Discount_Rate)^5) -> 1999.8819 | M19: (+) Present Value of Terminal Value: | P19: =P16/((1+Discount_Rate)^5) -> 1757.0867
H20: (+) Present Value of UFCF: | K20: =NPV(Discount_Rate,L61:P61)/Units -> 325.44824 | M20: (+) Present Value of UFCF: | P20: =NPV(Discount_Rate,L61:P61)/Units -> 325.44824
H21: Implied Enterprise Value: | K21: =SUM(K19:K20) -> 2325.3301 | M21: Implied Enterprise Value: | P21: =SUM(P19:P20) -> 2082.5349
C22: Current Equity Value: | F22: =$F$11*$F$12 -> 1106.9136
C23: (-) Cash & Investments: | F23: =-SUM(Model!K106:K108)/Units -> -210.56569 | H23: % of implied TEV from Terminal Value: | K23: =K19/K21 -> 0.86004214 | M23: % of implied TEV from Terminal Value: | P23: =P19/P21 -> 0.84372496
C24: (-) Net Operating Losses: | F24: 0
C25: (+) Debt & Finance Leases: | F25: 0 | H25: (+) Cash and Investments: | K25: =-F23 -> 210.56569 | M25: (+) Cash and Investments: | P25: =K25 -> 210.56569
C26: (+) Preferred Stock: | F26: 0 | H26: (+) Net Operating Losses: | K26: =-F24 -> 0 | M26: (+) Net Operating Losses: | P26: =K26 -> 0
C27: (+) Operating Leases: | F27: 0 | H27: (-)Debt and Finance Leases: | K27: =-F25 -> 0 | M27: (-)Debt and Finance Leases: | P27: =K27 -> 0
C28: (+) Noncontrolling Interests: | F28: 0 | H28: (-)Preferred Stock: | K28: =-F26 -> 0 | M28: (-)Preferred Stock: | P28: =K28 -> 0
C29: (+) Unfunded Pensions: | F29: 0 | H29: (-) Operating Leases: | K29: =-F27 -> 0 | M29: (-) Operating Leases: | P29: =K29 -> 0
C30: Current Enterprise Value: | F30: =SUM($F$22:$F$29) -> 896.34791 | H30: (-) Noncontrolling Interests: | K30: =-F28 -> 0 | M30: (-) Noncontrolling Interests: | P30: =K30 -> 0
H31: (-)Unfunded Pensions: | K31: =-F29 -> 0 | M31: (-)Unfunded Pensions: | P31: =K31 -> 0
H33: Implied Equity Value: | K33: =K21+SUM(K25:K31) -> 2535.8958 | M33: Implied Equity Value: | P33: =SUM(P21:P32) -> 2293.9443
H35: Diluted Shares Outstanding: | K35: =_xlfn.SINGLE(Diluted) -> 52.56 | M35: Diluted Shares Outstanding: | P35: =_xlfn.SINGLE(Diluted) -> 52.56
H37: Implied Share Price from DCF: | K37: =K33/K35 -> 48.247637 | M37: Implied Share Price from DCF: | P37: =P33/P35 -> 43.644299
H38: Premium / (Discount) to Current: | K38: =K37/F11-1 -> 1.2909609 | M38: Premium / (Discount) to Current: | P38: =P37/F11-1 -> 1.0723789
I40: Historical | M40: Projected:
B41: =Company_Name&" - Free Cash Flow Calculation" -> Ouster, Inc. - Free Cash Flow Calculation | E41: Units: | H41: 44926 | I41: 45291 | J41: 45657 | K41: 46022 | L41: 46387 | M41: 46752 | N41: 47118 | O41: 47483 | P41: 47848
C43: Revenue | E43: $T | G43: =Drivers!F6 -> 33578 | H43: =Drivers!G6 -> 41029 | I43: =Drivers!H6 -> 83279 | J43: =Drivers!I6 -> 111101 | K43: =Drivers!J6 -> 169000 | L43: =Drivers!K6 -> 254788 | M43: =Drivers!L6 -> 365254.16 | N43: =Drivers!M6 -> 535307.84 | ... P43: =Drivers!O6 -> 912910.72
C44: % Change | G44: 0 | H44: =H43/G43-1 -> 0.22190124 | I44: =I43/H43-1 -> 1.0297594 | J44: =J43/I43-1 -> 0.33408182 | K44: =K43/J43-1 -> 0.52113842 | L44: =L43/K43-1 -> 0.5076213 | M44: =M43/L43-1 -> 0.43356109 | N44: =N43/M43-1 -> 0.46557629 | O44: =O43/N43-1 -> 0.33057438 | P44: =P43/O43-1 -> 0.28169752
C46: Operating Expenses | E46: $T | G46: =Model!G79 -> -108796 | H46: =Model!H79 -> -156353 | I46: =Model!I79 -> -381506 | J46: =Model!J79 -> -144637 | K46: =Model!K79 -> -160207.64 | L46: =Model!L79 -> -155000 | M46: =Model!M79 -> -155000 | N46: =Model!N79 -> -155000 | ... P46: =Model!P79 -> -155000
C48: Operating Income (EBIT) | E48: $T | G48: =Model!G81 -> -99710 | H48: =Model!H81 -> -145423 | I48: =Model!I81 -> -373192 | J48: =Model!J81 -> -104177 | K48: =Model!K81 -> -77397.642 | L48: =Model!L81 -> -53084.8 | M48: =Model!M81 -> -8898.3344 | N48: =Model!N81 -> 59123.137 | ... P48: =Model!P81 -> 210164.29
C50: (-) Taxes, Excluding Effect of Interest | E50: $T | G50: 0 | H50: 0 | I50: 0 | J50: 0 | K50: =Model!K39 -> 0 | L50: =Model!L39 -> 0 | M50: =Model!M39 -> 0 | N50: =Model!N39 -> 10471.262 | O50: =Model!O39 -> 22558.921 | P50: =Model!P39 -> 36587.769
C52: Net Operating Profit After Taxes (NOPAT) | E52: $T | G52: =Model!G88 -> -96775 | H52: =Model!H88 -> -138255 | I52: =Model!I88 -> -373587 | J52: =Model!J88 -> -96508 | K52: =Model!K88 -> -66950.192 | L52: =Model!L88 -> -41035.703 | M52: =Model!M88 -> -3596.8137 | N52: =Model!N88 -> 64139.519 | ... P52: =Model!P88 -> 219502.04
...

Sheet WACC
B2: ="WACC Analysis - "&_xlfn.SINGLE(Company_Name) -> WACC Analysis - Ouster, Inc.
B3: ($ USD in Millions Except Per Share Amounts in USD as Stated)
B5: Discount Rate Calculations - Assumptions:
B6: Risk-Free Rate: | F6: 0.045
B7: Equity Risk Premium: | F7: 0.035
B8: Pre-Tax Cost of Debt: | F8: =[1]Drivers!K76 -> 0.03933665
B9: Cost of Preferred Stock: | F9: 0
B11: Company Name: | C11: Ticker: | D11: Levered Beta: | E11: (+) Debt & Capital Leases: | G11: (+) Preferred Stock: | I11: Equity Value: | K11: Effective Tax Rate:
B12: Comparable Companies - Unlevered Beta Calculation:
D13: Levered | G13: Preferred | I13: Equity | L13: Unlevered
B14: Name | C14: Ticker | D14: Beta | E14: Debt | F14: % Debt | G14: Stock | H14: % Preferred | I14: Value | J14: % Equity | K14: Tax Rate | L14: Beta
B15: =INDEX(Pub_Comps_Range,MATCH(B$11,Pub_Comps_Params,0),MATCH($C15,Pub_Comps_Tickers,0)) -> Hesai Group | C15: HSAI | D15: =INDEX(Pub_Comps_Range,MATCH(D$11,Pub_Comps_Params,0),MATCH($C15,Pub_Comps_Tickers,0)) -> 1.15 | E15: =INDEX(Pub_Comps_Range,MATCH(E$11,Pub_Comps_Params,0),MATCH($C15,Pub_Comps_Tickers,0)) -> 120.1 | F15: =E15/(E15+G15+I15) -> 0.029003357 | G15: =INDEX(Pub_Comps_Range,MATCH(G$11,Pub_Comps_Params,0),MATCH($C15,Pub_Comps_Tickers,0)) -> 0 | H15: =G15/(E15+G15+I15) -> 0 | I15: =INDEX(Pub_Comps_Range,MATCH(I$11,Pub_Comps_Params,0),MATCH($C15,Pub_Comps_Tickers,0)) -> 4020.8 | J15: =$I15/($E15+$G15+$I15) -> 0.97099664 | K15: =INDEX(Pub_Comps_Range,MATCH(K$11,Pub_Comps_Params,0),MATCH($C15,Pub_Comps_Tickers,0)) -> 0.061 | L15: =IFERROR(D15/(1+(E15/I15)*(1-K15)+G15/I15),"N/A") -> 1.1186252
B16: =INDEX(Pub_Comps_Range,MATCH(B$11,Pub_Comps_Params,0),MATCH($C16,Pub_Comps_Tickers,0)) -> Innoviz Technologies, Ltd. | C16: INVZ | D16: =INDEX(Pub_Comps_Range,MATCH(D$11,Pub_Comps_Params,0),MATCH($C16,Pub_Comps_Tickers,0)) -> 1.34 | E16: =INDEX(Pub_Comps_Range,MATCH(E$11,Pub_Comps_Params,0),MATCH($C16,Pub_Comps_Tickers,0)) -> 34.9 | F16: =E16/(E16+G16+I16) -> 0.13861105 | G16: =INDEX(Pub_Comps_Range,MATCH(G$11,Pub_Comps_Params,0),MATCH($C16,Pub_Comps_Tickers,0)) -> 0 | H16: =G16/(E16+G16+I16) -> 0 | I16: =INDEX(Pub_Comps_Range,MATCH(I$11,Pub_Comps_Params,0),MATCH($C16,Pub_Comps_Tickers,0)) -> 216.88368 | J16: =$I16/($E16+$G16+$I16) -> 0.86138895 | K16: =INDEX(Pub_Comps_Range,MATCH(K$11,Pub_Comps_Params,0),MATCH($C16,Pub_Comps_Tickers,0)) -> 0 | L16: =IFERROR(D16/(1+(E16/I16)*(1-K16)+G16/I16),"N/A") -> 1.1542612
B17: =INDEX(Pub_Comps_Range,MATCH(B$11,Pub_Comps_Params,0),MATCH($C17,Pub_Comps_Tickers,0)) -> Aeva Technologies, Inc. | C17: AEVA | D17: =INDEX(Pub_Comps_Range,MATCH(D$11,Pub_Comps_Params,0),MATCH($C17,Pub_Comps_Tickers,0)) -> 2.08 | E17: =INDEX(Pub_Comps_Range,MATCH(E$11,Pub_Comps_Params,0),MATCH($C17,Pub_Comps_Tickers,0)) -> 6.124 | F17: =E17/(E17+G17+I17) -> 0.0066345105 | G17: =INDEX(Pub_Comps_Range,MATCH(G$11,Pub_Comps_Params,0),MATCH($C17,Pub_Comps_Tickers,0)) -> 0 | H17: =G17/(E17+G17+I17) -> 0 | I17: =INDEX(Pub_Comps_Range,MATCH(I$11,Pub_Comps_Params,0),MATCH($C17,Pub_Comps_Tickers,0)) -> 916.92828 | J17: =$I17/($E17+$G17+$I17) -> 0.99336549 | K17: =INDEX(Pub_Comps_Range,MATCH(K$11,Pub_Comps_Params,0),MATCH($C17,Pub_Comps_Tickers,0)) -> 0.2 | L17: =IFERROR(D17/(1+(E17/I17)*(1-K17)+G17/I17),"N/A") -> 2.0689455
B18: =INDEX(Pub_Comps_Range,MATCH(B$11,Pub_Comps_Params,0),MATCH($C18,Pub_Comps_Tickers,0)) -> Luminar Technologies, Inc. | C18: LAZR | D18: =INDEX(Pub_Comps_Range,MATCH(D$11,Pub_Comps_Params,0),MATCH($C18,Pub_Comps_Tickers,0)) -> 1.36 | E18: =INDEX(Pub_Comps_Range,MATCH(E$11,Pub_Comps_Params,0),MATCH($C18,Pub_Comps_Tickers,0)) -> 449 | F18: =E18/(E18+G18+I18) -> 0.97567737 | G18: =INDEX(Pub_Comps_Range,MATCH(G$11,Pub_Comps_Params,0),MATCH($C18,Pub_Comps_Tickers,0)) -> 0 | H18: =G18/(E18+G18+I18) -> 0 | I18: =INDEX(Pub_Comps_Range,MATCH(I$11,Pub_Comps_Params,0),MATCH($C18,Pub_Comps_Tickers,0)) -> 11.193109 | J18: =$I18/($E18+$G18+$I18) -> 0.024322635 | K18: =INDEX(Pub_Comps_Range,MATCH(K$11,Pub_Comps_Params,0),MATCH($C18,Pub_Comps_Tickers,0)) -> 0 | L18: =IFERROR(D18/(1+(E18/I18)*(1-K18)+G18/I18),"N/A") -> 0.033078784
B19: =INDEX(Pub_Comps_Range,MATCH(B$11,Pub_Comps_Params,0),MATCH($C19,Pub_Comps_Tickers,0)) -> MicroVision, Inc. | C19: MVIS | D19: =INDEX(Pub_Comps_Range,MATCH(D$11,Pub_Comps_Params,0),MATCH($C19,Pub_Comps_Tickers,0)) -> 1.27 | E19: =INDEX(Pub_Comps_Range,MATCH(E$11,Pub_Comps_Params,0),MATCH($C19,Pub_Comps_Tickers,0)) -> 46 | F19: =E19/(E19+G19+I19) -> 0.142671 | G19: =INDEX(Pub_Comps_Range,MATCH(G$11,Pub_Comps_Params,0),MATCH($C19,Pub_Comps_Tickers,0)) -> 0 | H19: =G19/(E19+G19+I19) -> 0 | I19: =INDEX(Pub_Comps_Range,MATCH(I$11,Pub_Comps_Params,0),MATCH($C19,Pub_Comps_Tickers,0)) -> 276.4201 | J19: =$I19/($E19+$G19+$I19) -> 0.857329 | K19: =INDEX(Pub_Comps_Range,MATCH(K$11,Pub_Comps_Params,0),MATCH($C19,Pub_Comps_Tickers,0)) -> 0 | L19: =IFERROR(D19/(1+(E19/I19)*(1-K19)+G19/I19),"N/A") -> 1.0888078
B20: =INDEX(Pub_Comps_Range,MATCH(B$11,Pub_Comps_Params,0),MATCH($C20,Pub_Comps_Tickers,0)) -> Aeye, Inc. | C20: LIDR | D20: =INDEX(Pub_Comps_Range,MATCH(D$11,Pub_Comps_Params,0),MATCH($C20,Pub_Comps_Tickers,0)) -> 2.98 | E20: =INDEX(Pub_Comps_Range,MATCH(E$11,Pub_Comps_Params,0),MATCH($C20,Pub_Comps_Tickers,0)) -> 0.824 | F20: =E20/(E20+G20+I20) -> 0.0097890426 | G20: =INDEX(Pub_Comps_Range,MATCH(G$11,Pub_Comps_Params,0),MATCH($C20,Pub_Comps_Tickers,0)) -> 0 | H20: =G20/(E20+G20+I20) -> 0 | I20: =INDEX(Pub_Comps_Range,MATCH(I$11,Pub_Comps_Params,0),MATCH($C20,Pub_Comps_Tickers,0)) -> 83.35175 | J20: =$I20/($E20+$G20+$I20) -> 0.99021096 | K20: =INDEX(Pub_Comps_Range,MATCH(K$11,Pub_Comps_Params,0),MATCH($C20,Pub_Comps_Tickers,0)) -> 0 | L20: =IFERROR(D20/(1+(E20/I20)*(1-K20)+G20/I20),"N/A") -> 2.9508287
B22: Median: | D22: =MEDIAN(D15:D19) -> 1.34 | E22: =MEDIAN(E15:E19) -> 46 | F22: =MEDIAN(F15:F19) -> 0.13861105 | G22: =MEDIAN(G15:G19) -> 0 | H22: =MEDIAN(H15:H19) -> 0 | I22: =MEDIAN(I15:I19) -> 276.4201 | J22: =MEDIAN(J15:J19) -> 0.86138895 | K22: =MEDIAN(K15:K19) -> 0 | L22: =MEDIAN(L15:L19) -> 1.1186252
B24: =Company_Name -> Ouster, Inc. | C24: =Ticker -> OUST | D24: =INDEX(Pub_Comps_Range,MATCH(D$11,Pub_Comps_Params,0),MATCH($C24,Pub_Comps_Tickers,0)) -> 2.24 | E24: =INDEX(Pub_Comps_Range,MATCH(E$11,Pub_Comps_Params,0),MATCH($C24,Pub_Comps_Tickers,0)) -> 0 | F24: =E24/($E24+$G24+$I24) -> 0 | G24: =INDEX(Pub_Comps_Range,MATCH(G$11,Pub_Comps_Params,0),MATCH($C24,Pub_Comps_Tickers,0)) -> 0 | H24: =G24/($E24+$G24+$I24) -> 0 | I24: =INDEX(Pub_Comps_Range,MATCH(I$11,Pub_Comps_Params,0),MATCH($C24,Pub_Comps_Tickers,0)) -> 1119.2969 | J24: =I24/($E24+$G24+$I24) -> 1 | K24: 0.132 | L24: =IFERROR(D24/(1+(E24/I24)*(1-K24)+G24/I24),"N/A") -> 2.24
B26: =TEXT(Company_Name,"")& " - Levered Beta & WACC Calculation:" -> Ouster, Inc. - Levered Beta & WACC Calculation:
D27: Unlevered | G27: Preferred | I27: Equity | L27: Levered
C28: Ticker | D28: Beta | E28: Debt | F28: % Debt | G28: Stock | H28: % Preferred | I28: Value | J28: % Equity | K28: Tax Rate | L28: Beta
B29: Current Capital Structure: | C29: =C24 -> OUST | D29: =L24 -> 2.24 | E29: 5461 | F29: 0.033001557 | G29: 0 | H29: 0 | I29: 160016.04 | J29: 0.96699844 | K29: 0.132 | L29: =D29*(1+E29/I29*(1-K29)+G29/I29) -> 2.3063554
B30: "Optimal" Capital Structure: | D30: =L22 -> 1.1186252 | E30: =(E29+I29)*F30 -> 22936.946 | F30: =F22 -> 0.13861105 | G30: 0 | H30: 0 | I30: =(I29+E29)*J30 -> 142540.09 | J30: =J22 -> 0.86138895 | K30: 0.132 | L30: =D30*(1+E30/I30*(1-K30)+G30/I30) -> 1.274869
B32: Cost of Equity Based on Comparables, Current Capital Structure: | L32: =Risk_Free_Rate+Equity_Risk_Premium*L29 -> 0.12572244
B33: Cost of Equity Based on Comparables, "Optimal" Capital Structure: | L33: =Risk_Free_Rate+Equity_Risk_Premium*L30 -> 0.089620417
B34: Cost of Equity Based on Historical Beta: | L34: =Risk_Free_Rate+Equity_Risk_Premium*D24 -> 0.1234
B36: WACC, Current Capital Structure: | L36: =L32*J29+Cost_of_Debt*(1-K29)*F29+Cost_of_Preferred*H29 -> 0.12270022
B37: WACC, "Optimal" Capital Structure: | L37: =L33*J30+Cost_of_Debt*(1-K30)*F30+Cost_of_Preferred*H30 -> 0.081930802
B38: WACC, Current Capital Structure and Historical Cost of Equity: | L38: =L34*J29+Cost_of_Debt*(1-K29)*F29+Cost_of_Preferred*H29 -> 0.12045442
B40: Average WACC Produced by All Methods: | L40: =AVERAGE(L36:L38) -> 0.10836181

Sheet PubComps
B2: Comparable Companies - Semiconductor Manufacturing Equipment Provisions and Servicing
B3: ($ USD in Millions Except Per Share Amounts in USD as Stated)
B5: Company Name: | C5: Ticker: | D5: Share Price: | E5: Total Diluted Shares: | F5: Equity Value: | G5: Levered Beta: | H5: Effective Tax Rate: | I5: (-) Cash & Cash-Equivalents: | J5: (+) Debt & Capital Leases: | K5: (+) Preferred Stock: | L5: (+) Noncontrolling Interests: | M5: Enterprise Value: | N5: LTM Revenue: | O5: 2025-12-31 Revenue: | P5: 2026-12-31 Revenue: | Q5: 2025-12-31 Gross Profit: | R5: 2026-12-31 Gross Profit: | S5: 2027-12-31 Gross Profit: | T5: LTM Reported Net Income: | U5: 2025-12-31 Reported Net Income: | V5: 2026-12-31 Reported Net Income: | W5: Year 1 Projected Revenue Growth: | X5: Year 1 Projected EBITDA Growth: | Y5: LTM EBITDA Margin: | Z5: 2025-12-31 EBITDA Margin: | AA5: 2026-12-31 EBITDA Margin:
B6: Operating Statistics: | F6: Capitalization | W6: Projected | X6: Projected
D7: Share | E7: Diluted | F7: Equity | L7: Other & | M7: Enterprise | N7: Revenue | Q7: EBITDA | T7: Net Income | W7: Revenue | X7: EBITDA | Y7: EBITDA Margin | AF7: Ticker: | AK7: =Ticker -> OUST | AP7: ONTO | AU7: ACLS | AZ7: FORM | BE7: UCTT | BJ7: VECO | BO7: ENTG
B8: Company Name | C8: Ticker | D8: Price | E8: Shares | F8: Value | G8: Beta | H8: Tax Rate | I8: Cash | J8: Debt | K8: Preferred | L8: NCI | M8: Value | N8: LTM | O8: 46022 | P8: =EOMONTH(O8,12) -> 46387 | Q8: =$N$8 -> LTM | R8: =+$O$8 -> 46022 | S8: =+$P$8 -> 46387 | T8: =$N$8 -> LTM | U8: =+$O$8 -> 46022 | V8: =+$P$8 -> 46387 | W8: Growth | X8: Growth | Y8: =$N$8 -> LTM | Z8: =+$O$8 -> 46022 | AA8: =+$P$8 -> 46387
B9: =INDEX(Pub_Comps_Range,MATCH(B$5,Pub_Comps_Params,0),MATCH($C9,Pub_Comps_Tickers,0)) -> Hesai Group | C9: HSAI | D9: =INDEX(Pub_Comps_Range,MATCH(D$5,Pub_Comps_Params,0),MATCH($C9,Pub_Comps_Tickers,0)) -> 25.13 | E9: =INDEX(Pub_Comps_Range,MATCH(E$5,Pub_Comps_Params,0),MATCH($C9,Pub_Comps_Tickers,0)) -> 160 | F9: =INDEX(Pub_Comps_Range,MATCH(F$5,Pub_Comps_Params,0),MATCH($C9,Pub_Comps_Tickers,0)) -> 4020.8 | G9: =INDEX(Pub_Comps_Range,MATCH(G$5,Pub_Comps_Params,0),MATCH($C9,Pub_Comps_Tickers,0)) -> 1.15 | H9: =INDEX(Pub_Comps_Range,MATCH(H$5,Pub_Comps_Params,0),MATCH($C9,Pub_Comps_Tickers,0)) -> 0.061 | I9: =INDEX(Pub_Comps_Range,MATCH(I$5,Pub_Comps_Params,0),MATCH($C9,Pub_Comps_Tickers,0)) -> -1059 | J9: =INDEX(Pub_Comps_Range,MATCH(J$5,Pub_Comps_Params,0),MATCH($C9,Pub_Comps_Tickers,0)) -> 120.1 | K9: =INDEX(Pub_Comps_Range,MATCH(K$5,Pub_Comps_Params,0),MATCH($C9,Pub_Comps_Tickers,0)) -> 0 | ... AA9: =INDEX(Pub_Comps_Range,MATCH(AA$5,Pub_Comps_Params,0),MATCH($C9,Pub_Comps_Tickers,0)) -> 0.40880503
B10: =INDEX(Pub_Comps_Range,MATCH(B$5,Pub_Comps_Params,0),MATCH($C10,Pub_Comps_Tickers,0)) -> Innoviz Technologies, Ltd. | C10: INVZ | D10: =INDEX(Pub_Comps_Range,MATCH(D$5,Pub_Comps_Params,0),MATCH($C10,Pub_Comps_Tickers,0)) -> 1.04 | E10: =INDEX(Pub_Comps_Range,MATCH(E$5,Pub_Comps_Params,0),MATCH($C10,Pub_Comps_Tickers,0)) -> 208.542 | F10: =INDEX(Pub_Comps_Range,MATCH(F$5,Pub_Comps_Params,0),MATCH($C10,Pub_Comps_Tickers,0)) -> 216.88368 | G10: =INDEX(Pub_Comps_Range,MATCH(G$5,Pub_Comps_Params,0),MATCH($C10,Pub_Comps_Tickers,0)) -> 1.34 | H10: =INDEX(Pub_Comps_Range,MATCH(H$5,Pub_Comps_Params,0),MATCH($C10,Pub_Comps_Tickers,0)) -> 0 | I10: =INDEX(Pub_Comps_Range,MATCH(I$5,Pub_Comps_Params,0),MATCH($C10,Pub_Comps_Tickers,0)) -> -74.3 | J10: =INDEX(Pub_Comps_Range,MATCH(J$5,Pub_Comps_Params,0),MATCH($C10,Pub_Comps_Tickers,0)) -> 34.9 | K10: =INDEX(Pub_Comps_Range,MATCH(K$5,Pub_Comps_Params,0),MATCH($C10,Pub_Comps_Tickers,0)) -> 0 | ... AA10: =INDEX(Pub_Comps_Range,MATCH(AA$5,Pub_Comps_Params,0),MATCH($C10,Pub_Comps_Tickers,0)) -> 0.1686747
B11: =INDEX(Pub_Comps_Range,MATCH(B$5,Pub_Comps_Params,0),MATCH($C11,Pub_Comps_Tickers,0)) -> Aeva Technologies, Inc. | C11: AEVA | D11: =INDEX(Pub_Comps_Range,MATCH(D$5,Pub_Comps_Params,0),MATCH($C11,Pub_Comps_Tickers,0)) -> 14.34 | E11: =INDEX(Pub_Comps_Range,MATCH(E$5,Pub_Comps_Params,0),MATCH($C11,Pub_Comps_Tickers,0)) -> 63.942 | F11: =INDEX(Pub_Comps_Range,MATCH(F$5,Pub_Comps_Params,0),MATCH($C11,Pub_Comps_Tickers,0)) -> 916.92828 | G11: =INDEX(Pub_Comps_Range,MATCH(G$5,Pub_Comps_Params,0),MATCH($C11,Pub_Comps_Tickers,0)) -> 2.08 | H11: =INDEX(Pub_Comps_Range,MATCH(H$5,Pub_Comps_Params,0),MATCH($C11,Pub_Comps_Tickers,0)) -> 0.2 | I11: =INDEX(Pub_Comps_Range,MATCH(I$5,Pub_Comps_Params,0),MATCH($C11,Pub_Comps_Tickers,0)) -> -48.8 | J11: =INDEX(Pub_Comps_Range,MATCH(J$5,Pub_Comps_Params,0),MATCH($C11,Pub_Comps_Tickers,0)) -> 6.124 | K11: =INDEX(Pub_Comps_Range,MATCH(K$5,Pub_Comps_Params,0),MATCH($C11,Pub_Comps_Tickers,0)) -> 0 | ... AA11: =INDEX(Pub_Comps_Range,MATCH(AA$5,Pub_Comps_Params,0),MATCH($C11,Pub_Comps_Tickers,0)) -> 0
B12: =INDEX(Pub_Comps_Range,MATCH(B$5,Pub_Comps_Params,0),MATCH($C12,Pub_Comps_Tickers,0)) -> Luminar Technologies, Inc. | C12: LAZR | D12: =INDEX(Pub_Comps_Range,MATCH(D$5,Pub_Comps_Params,0),MATCH($C12,Pub_Comps_Tickers,0)) -> 0.08 | E12: =INDEX(Pub_Comps_Range,MATCH(E$5,Pub_Comps_Params,0),MATCH($C12,Pub_Comps_Tickers,0)) -> 139.91386 | F12: =INDEX(Pub_Comps_Range,MATCH(F$5,Pub_Comps_Params,0),MATCH($C12,Pub_Comps_Tickers,0)) -> 11.193109 | G12: =INDEX(Pub_Comps_Range,MATCH(G$5,Pub_Comps_Params,0),MATCH($C12,Pub_Comps_Tickers,0)) -> 1.36 | H12: =INDEX(Pub_Comps_Range,MATCH(H$5,Pub_Comps_Params,0),MATCH($C12,Pub_Comps_Tickers,0)) -> 0 | I12: =INDEX(Pub_Comps_Range,MATCH(I$5,Pub_Comps_Params,0),MATCH($C12,Pub_Comps_Tickers,0)) -> -6.3 | J12: =INDEX(Pub_Comps_Range,MATCH(J$5,Pub_Comps_Params,0),MATCH($C12,Pub_Comps_Tickers,0)) -> 449 | K12: =INDEX(Pub_Comps_Range,MATCH(K$5,Pub_Comps_Params,0),MATCH($C12,Pub_Comps_Tickers,0)) -> 0 | ... AA12: =INDEX(Pub_Comps_Range,MATCH(AA$5,Pub_Comps_Params,0),MATCH($C12,Pub_Comps_Tickers,0)) -> N/A
B13: =INDEX(Pub_Comps_Range,MATCH(B$5,Pub_Comps_Params,0),MATCH($C13,Pub_Comps_Tickers,0)) -> MicroVision, Inc. | C13: MVIS | D13: =INDEX(Pub_Comps_Range,MATCH(D$5,Pub_Comps_Params,0),MATCH($C13,Pub_Comps_Tickers,0)) -> 0.85 | E13: =INDEX(Pub_Comps_Range,MATCH(E$5,Pub_Comps_Params,0),MATCH($C13,Pub_Comps_Tickers,0)) -> 325.20012 | F13: =INDEX(Pub_Comps_Range,MATCH(F$5,Pub_Comps_Params,0),MATCH($C13,Pub_Comps_Tickers,0)) -> 276.4201 | G13: =INDEX(Pub_Comps_Range,MATCH(G$5,Pub_Comps_Params,0),MATCH($C13,Pub_Comps_Tickers,0)) -> 1.27 | H13: =INDEX(Pub_Comps_Range,MATCH(H$5,Pub_Comps_Params,0),MATCH($C13,Pub_Comps_Tickers,0)) -> 0 | I13: =INDEX(Pub_Comps_Range,MATCH(I$5,Pub_Comps_Params,0),MATCH($C13,Pub_Comps_Tickers,0)) -> -99 | J13: =INDEX(Pub_Comps_Range,MATCH(J$5,Pub_Comps_Params,0),MATCH($C13,Pub_Comps_Tickers,0)) -> 46 | K13: =INDEX(Pub_Comps_Range,MATCH(K$5,Pub_Comps_Params,0),MATCH($C13,Pub_Comps_Tickers,0)) -> 0 | ... AA13: =INDEX(Pub_Comps_Range,MATCH(AA$5,Pub_Comps_Params,0),MATCH($C13,Pub_Comps_Tickers,0)) -> 0.225 | AF13: ACMR
B14: =INDEX(Pub_Comps_Range,MATCH(B$5,Pub_Comps_Params,0),MATCH($C14,Pub_Comps_Tickers,0)) -> Aeye, Inc. | C14: LIDR | D14: =INDEX(Pub_Comps_Range,MATCH(D$5,Pub_Comps_Params,0),MATCH($C14,Pub_Comps_Tickers,0)) -> 1.85 | E14: =INDEX(Pub_Comps_Range,MATCH(E$5,Pub_Comps_Params,0),MATCH($C14,Pub_Comps_Tickers,0)) -> 45.055 | F14: =INDEX(Pub_Comps_Range,MATCH(F$5,Pub_Comps_Params,0),MATCH($C14,Pub_Comps_Tickers,0)) -> 83.35175 | G14: =INDEX(Pub_Comps_Range,MATCH(G$5,Pub_Comps_Params,0),MATCH($C14,Pub_Comps_Tickers,0)) -> 2.98 | H14: =INDEX(Pub_Comps_Range,MATCH(H$5,Pub_Comps_Params,0),MATCH($C14,Pub_Comps_Tickers,0)) -> 0 | I14: =INDEX(Pub_Comps_Range,MATCH(I$5,Pub_Comps_Params,0),MATCH($C14,Pub_Comps_Tickers,0)) -> -84.333 | J14: =INDEX(Pub_Comps_Range,MATCH(J$5,Pub_Comps_Params,0),MATCH($C14,Pub_Comps_Tickers,0)) -> 0.824 | K14: =INDEX(Pub_Comps_Range,MATCH(K$5,Pub_Comps_Params,0),MATCH($C14,Pub_Comps_Tickers,0)) -> 0 | ... AA14: =INDEX(Pub_Comps_Range,MATCH(AA$5,Pub_Comps_Params,0),MATCH($C14,Pub_Comps_Tickers,0)) -> 0.158
B15: Maximum | D15: =MAX(D9:D13) -> 25.13 | F15: =MAX(F9:F13) -> 4020.8 | M15: =MAX(M9:M13) -> 3081.9 | N15: =MAX(N9:N13) -> 385 | O15: =MAX(O9:O13) -> 445 | P15: =MAX(P9:P13) -> 636 | Q15: =MAX(Q9:Q13) -> 187 | R15: =MAX(R9:R13) -> 260 | S15: =MAX(S9:S13) -> 346 | T15: =MAX(T9:T13) -> 60.4 | ... AA15: =MAX(AA9:AA13) -> 0.40880503
B16: 75th Percentile | D16: =QUARTILE(D9:D13,3) -> 14.34 | F16: =QUARTILE(F9:F13,3) -> 916.92828 | M16: =QUARTILE(M9:M13,3) -> 874.25228 | N16: =QUARTILE(N9:N13,3) -> 75.77 | O16: =QUARTILE(O9:O13,3) -> 58 | P16: =QUARTILE(P9:P13,3) -> 83 | Q16: =QUARTILE(Q9:Q13,3) -> 13 | R16: =QUARTILE(R9:R13,3) -> 14 | S16: =QUARTILE(S9:S13,3) -> 28 | T16: =QUARTILE(T9:T13,3) -> -65.136 | ... AA16: =QUARTILE(AA9:AA13,3) -> 0.27095126
B17: Median | D17: =MEDIAN(D9:D13) -> 1.04 | F17: =MEDIAN(F9:F13) -> 276.4201 | M17: =MEDIAN(M9:M13) -> 453.89311 | N17: =MEDIAN(N9:N13) -> 48.442 | O17: =MEDIAN(O9:O13) -> 17 | P17: =MEDIAN(P9:P13) -> 28 | Q17: =MEDIAN(Q9:Q13) -> 0 | R17: =MEDIAN(R9:R13) -> 3.375 | S17: =MEDIAN(S9:S13) -> 13 | T17: =MEDIAN(T9:T13) -> -88 | ... AA17: =MEDIAN(AA9:AA13) -> 0.19683735
B18: 25th Percentile | D18: =QUARTILE(D9:D13,1) -> 0.85 | F18: =QUARTILE(F9:F13,1) -> 216.88368 | M18: =QUARTILE(M9:M13,1) -> 223.4201 | N18: =QUARTILE(N9:N13,1) -> 15.154 | O18: =QUARTILE(O9:O13,1) -> 3 | P18: =QUARTILE(P9:P13,1) -> 15 | Q18: =QUARTILE(Q9:Q13,1) -> -1 | R18: =QUARTILE(R9:R13,1) -> 0 | S18: =QUARTILE(S9:S13,1) -> 9.72 | T18: =QUARTILE(T9:T13,1) -> -156 | ... AA18: =QUARTILE(AA9:AA13,1) -> 0.12650602
B19: Minimum | D19: =MIN(D9:D13) -> 0.08 | F19: =MIN(F9:F13) -> 11.193109 | M19: =MIN(M9:M13) -> 177.48368 | N19: =MIN(N9:N13) -> 2.636 | O19: =MIN(O9:O13) -> 0 | P19: =MIN(P9:P13) -> 0 | Q19: =MIN(Q9:Q13) -> -1.89 | R19: =MIN(R9:R13) -> 0 | S19: =MIN(S9:S13) -> 0 | T19: =MIN(T9:T13) -> -234 | ... AA19: =MIN(AA9:AA13) -> 0
B21: =INDEX(Pub_Comps_Range,MATCH(B$5,Pub_Comps_Params,0),MATCH($C21,Pub_Comps_Tickers,0)) -> Ouster, Inc. | C21: =Ticker -> OUST | D21: =Share_Price -> 21.06 | E21: =INDEX(Pub_Comps_Range,MATCH(E$5,Pub_Comps_Params,0),MATCH($C21,Pub_Comps_Tickers,0)) -> 53.148 | F21: =INDEX(Pub_Comps_Range,MATCH(F$5,Pub_Comps_Params,0),MATCH($C21,Pub_Comps_Tickers,0)) -> 1119.2969 | G21: =INDEX(Pub_Comps_Range,MATCH(G$5,Pub_Comps_Params,0),MATCH($C21,Pub_Comps_Tickers,0)) -> 2.24 | H21: =INDEX(Pub_Comps_Range,MATCH(H$5,Pub_Comps_Params,0),MATCH($C21,Pub_Comps_Tickers,0)) -> 0.21 | I21: =INDEX(Pub_Comps_Range,MATCH(I$5,Pub_Comps_Params,0),MATCH($C21,Pub_Comps_Tickers,0)) -> -210.56569 | J21: =INDEX(Pub_Comps_Range,MATCH(J$5,Pub_Comps_Params,0),MATCH($C21,Pub_Comps_Tickers,0)) -> 0 | K21: =INDEX(Pub_Comps_Range,MATCH(K$5,Pub_Comps_Params,0),MATCH($C21,Pub_Comps_Tickers,0)) -> 0 | L21: =INDEX(Pub_Comps_Range,MATCH(L$5,Pub_Comps_Params,0),MATCH($C21,Pub_Comps_Tickers,0)) -> 773.0331 | ... V21: =INDEX(Pub_Comps_Range,MATCH(V$5,Pub_Comps_Params,0),MATCH($C21,Pub_Comps_Tickers,0)) -> -41.035703 | W21: =MIN(W10:W15) -> 0.43103448 | X21: =MIN(X10:X15) -> -2.7857143 | Y21: =MIN(Y10:Y15) -> -1.4036419 | Z21: =MIN(Z10:Z15) -> -0.63 | AA21: =MIN(AA10:AA15) -> 0
B23: Company Name: | C23: Ticker: | D23: Share Price: | F23: Equity Value: | M23: Enterprise Value: | N23: LTM EV / Revenue: | O23: 2025-12-31 EV / Revenue: | P23: 2026-12-31 EV / Revenue: | Q23: LTM EV / Gross Profit: | R23: 2025-12-31 EV / Gross Profit: | S23: 2026-12-31 EV / Gross Profit: | T23: LTM P / E: | U23: 2025-12-31 P / E: | V23: 2026-12-31 P / E:
B24: Valuation Statistics: | F24: Capitalization | N24: Enterprise Value / | Q24: Enterprise Value /
F25: Equity | M25: Enterprise | N25: Revenue | Q25: EBITDA | T25: P / E Multiple
B26: Company Name | C26: Ticker | D26: Share Price | F26: Value | M26: Value | N26: =$N$8 -> LTM | O26: =+$O$8 -> 46022 | P26: =+$P$8 -> 46387 | Q26: =$N$8 -> LTM | R26: =+$O$8 -> 46022 | S26: =+$P$8 -> 46387 | T26: =$N$8 -> LTM | U26: =+$O$8 -> 46022 | V26: =+$P$8 -> 46387
B27: =INDEX(Pub_Comps_Range,MATCH(B$23,Pub_Comps_Params,0),MATCH($C27,Pub_Comps_Tickers,0)) -> Hesai Group | C27: HSAI | D27: =INDEX(Pub_Comps_Range,MATCH(D$23,Pub_Comps_Params,0),MATCH($C27,Pub_Comps_Tickers,0)) -> 25.13 | F27: =INDEX(Pub_Comps_Range,MATCH(F$23,Pub_Comps_Params,0),MATCH($C27,Pub_Comps_Tickers,0)) -> 4020.8 | M27: =INDEX(Pub_Comps_Range,MATCH(M$23,Pub_Comps_Params,0),MATCH($C27,Pub_Comps_Tickers,0)) -> 3081.9 | N27: =INDEX(Pub_Comps_Range,MATCH(N$23,Pub_Comps_Params,0),MATCH($C27,Pub_Comps_Tickers,0)) -> 8.0049351 | O27: =INDEX(Pub_Comps_Range,MATCH(O$23,Pub_Comps_Params,0),MATCH($C27,Pub_Comps_Tickers,0)) -> 6.925618 | P27: =INDEX(Pub_Comps_Range,MATCH(P$23,Pub_Comps_Params,0),MATCH($C27,Pub_Comps_Tickers,0)) -> 4.8457547 | Q27: =INDEX(Pub_Comps_Range,MATCH(Q$23,Pub_Comps_Params,0),MATCH($C27,Pub_Comps_Tickers,0)) -> 19.322257 | R27: =INDEX(Pub_Comps_Range,MATCH(R$23,Pub_Comps_Params,0),MATCH($C27,Pub_Comps_Tickers,0)) -> 16.480749 | S27: =INDEX(Pub_Comps_Range,MATCH(S$23,Pub_Comps_Params,0),MATCH($C27,Pub_Comps_Tickers,0)) -> 11.853462 | T27: =INDEX(Pub_Comps_Range,MATCH(T$23,Pub_Comps_Params,0),MATCH($C27,Pub_Comps_Tickers,0)) -> 66.569536 | ... V27: =INDEX(Pub_Comps_Range,MATCH(V$23,Pub_Comps_Params,0),MATCH($C27,Pub_Comps_Tickers,0)) -> 44.675556
B28: =INDEX(Pub_Comps_Range,MATCH(B$23,Pub_Comps_Params,0),MATCH($C28,Pub_Comps_Tickers,0)) -> Innoviz Technologies, Ltd. | C28: INVZ | D28: =INDEX(Pub_Comps_Range,MATCH(D$23,Pub_Comps_Params,0),MATCH($C28,Pub_Comps_Tickers,0)) -> 1.04 | F28: =INDEX(Pub_Comps_Range,MATCH(F$23,Pub_Comps_Params,0),MATCH($C28,Pub_Comps_Tickers,0)) -> 216.88368 | M28: =INDEX(Pub_Comps_Range,MATCH(M$23,Pub_Comps_Params,0),MATCH($C28,Pub_Comps_Tickers,0)) -> 177.48368 | N28: =INDEX(Pub_Comps_Range,MATCH(N$23,Pub_Comps_Params,0),MATCH($C28,Pub_Comps_Tickers,0)) -> 3.6638388 | O28: =INDEX(Pub_Comps_Range,MATCH(O$23,Pub_Comps_Params,0),MATCH($C28,Pub_Comps_Tickers,0)) -> 3.0600634 | P28: =INDEX(Pub_Comps_Range,MATCH(P$23,Pub_Comps_Params,0),MATCH($C28,Pub_Comps_Tickers,0)) -> 2.1383576 | Q28: =INDEX(Pub_Comps_Range,MATCH(Q$23,Pub_Comps_Params,0),MATCH($C28,Pub_Comps_Tickers,0)) -> 15.597476 | R28: =INDEX(Pub_Comps_Range,MATCH(R$23,Pub_Comps_Params,0),MATCH($C28,Pub_Comps_Tickers,0)) -> 13.652591 | S28: =INDEX(Pub_Comps_Range,MATCH(S$23,Pub_Comps_Params,0),MATCH($C28,Pub_Comps_Tickers,0)) -> 12.677406 | T28: =INDEX(Pub_Comps_Range,MATCH(T$23,Pub_Comps_Params,0),MATCH($C28,Pub_Comps_Tickers,0)) -> NM | ... V28: =INDEX(Pub_Comps_Range,MATCH(V$23,Pub_Comps_Params,0),MATCH($C28,Pub_Comps_Tickers,0)) -> NM
B29: =INDEX(Pub_Comps_Range,MATCH(B$23,Pub_Comps_Params,0),MATCH($C29,Pub_Comps_Tickers,0)) -> Aeva Technologies, Inc. | C29: AEVA | D29: =INDEX(Pub_Comps_Range,MATCH(D$23,Pub_Comps_Params,0),MATCH($C29,Pub_Comps_Tickers,0)) -> 14.34 | F29: =INDEX(Pub_Comps_Range,MATCH(F$23,Pub_Comps_Params,0),MATCH($C29,Pub_Comps_Tickers,0)) -> 916.92828 | M29: =INDEX(Pub_Comps_Range,MATCH(M$23,Pub_Comps_Params,0),MATCH($C29,Pub_Comps_Tickers,0)) -> 874.25228 | N29: =INDEX(Pub_Comps_Range,MATCH(N$23,Pub_Comps_Params,0),MATCH($C29,Pub_Comps_Tickers,0)) -> 57.691189 | O29: =INDEX(Pub_Comps_Range,MATCH(O$23,Pub_Comps_Params,0),MATCH($C29,Pub_Comps_Tickers,0)) -> 51.426605 | P29: =INDEX(Pub_Comps_Range,MATCH(P$23,Pub_Comps_Params,0),MATCH($C29,Pub_Comps_Tickers,0)) -> 31.223296 | Q29: =INDEX(Pub_Comps_Range,MATCH(Q$23,Pub_Comps_Params,0),MATCH($C29,Pub_Comps_Tickers,0)) -> NM | R29: =INDEX(Pub_Comps_Range,MATCH(R$23,Pub_Comps_Params,0),MATCH($C29,Pub_Comps_Tickers,0)) -> NM | S29: =INDEX(Pub_Comps_Range,MATCH(S$23,Pub_Comps_Params,0),MATCH($C29,Pub_Comps_Tickers,0)) -> N/A | T29: =INDEX(Pub_Comps_Range,MATCH(T$23,Pub_Comps_Params,0),MATCH($C29,Pub_Comps_Tickers,0)) -> NM | ... V29: =INDEX(Pub_Comps_Range,MATCH(V$23,Pub_Comps_Params,0),MATCH($C29,Pub_Comps_Tickers,0)) -> NM
B30: =INDEX(Pub_Comps_Range,MATCH(B$23,Pub_Comps_Params,0),MATCH($C30,Pub_Comps_Tickers,0)) -> Luminar Technologies, Inc. | C30: LAZR | D30: =INDEX(Pub_Comps_Range,MATCH(D$23,Pub_Comps_Params,0),MATCH($C30,Pub_Comps_Tickers,0)) -> 0.08 | F30: =INDEX(Pub_Comps_Range,MATCH(F$23,Pub_Comps_Params,0),MATCH($C30,Pub_Comps_Tickers,0)) -> 11.193109 | M30: =INDEX(Pub_Comps_Range,MATCH(M$23,Pub_Comps_Params,0),MATCH($C30,Pub_Comps_Tickers,0)) -> 453.89311 | N30: =INDEX(Pub_Comps_Range,MATCH(N$23,Pub_Comps_Params,0),MATCH($C30,Pub_Comps_Tickers,0)) -> 5.9904066 | O30: =INDEX(Pub_Comps_Range,MATCH(O$23,Pub_Comps_Params,0),MATCH($C30,Pub_Comps_Tickers,0)) -> N/A | P30: =INDEX(Pub_Comps_Range,MATCH(P$23,Pub_Comps_Params,0),MATCH($C30,Pub_Comps_Tickers,0)) -> N/A | Q30: =INDEX(Pub_Comps_Range,MATCH(Q$23,Pub_Comps_Params,0),MATCH($C30,Pub_Comps_Tickers,0)) -> NM | R30: =INDEX(Pub_Comps_Range,MATCH(R$23,Pub_Comps_Params,0),MATCH($C30,Pub_Comps_Tickers,0)) -> N/A | S30: =INDEX(Pub_Comps_Range,MATCH(S$23,Pub_Comps_Params,0),MATCH($C30,Pub_Comps_Tickers,0)) -> N/A | T30: =INDEX(Pub_Comps_Range,MATCH(T$23,Pub_Comps_Params,0),MATCH($C30,Pub_Comps_Tickers,0)) -> NM | ... V30: =INDEX(Pub_Comps_Range,MATCH(V$23,Pub_Comps_Params,0),MATCH($C30,Pub_Comps_Tickers,0)) -> N/A
