Workbook
Name COGS: rNPV!$D$45
Name Company_Name: Model!$F$5
Name Cost_of_Debt: WACC!$F$8
Name Cost_of_Preferred: WACC!$F$9
Name Diluted: Model!$F$8
Name Discount_Rate: rNPV!$G$19
Name Equity_Risk_Premium: WACC!$F$7
Name Forward_Year_1: Model!$L$12
Name Forward_Year_2: Model!$L$13
Name Forward_Year_3: Model!$L$14
Name Hist_Year: Model!$L$5
Name Legal: rNPV!$D$9
Name LTM: Model!$L$11
Name OpEx: rNPV!$D$5
Name Pub_Comps_Params: Pubcomps_Data!$C$3:$C$102
Name Pub_Comps_Range: Pubcomps_Data!$C$3:$AL$102
Name Pub_Comps_Tickers: Pubcomps_Data!$C$3:$AL$3
Name Risk_Free_Rate: WACC!$F$6
Name RoyaltyJ: rNPV!#REF!
Name Royaltyxw: rNPV!#REF!
Name Scenario: rNPV!$D$6
Name Share_Price: Model!$F$7
Name Tax_Rate: Model!$F$10
Name Terminal_Growth_Rate: rNPV!$Q$14
Name Ticker: Model!$F$6
Name Units: Model!$F$13
Name Vali: rNPV!$D$8
Name Valuation_Date: Model!$L$8

Sheet Cover
B2: =Company_Name&" - Operating Model and Valuation - Cover Page and Navigation" -> Ultragenyx Pharmaceutical Inc. - Operating Model and Valuation - Cover Page and Navigation
C12: Company Name: | D12: =Company_Name -> Ultragenyx Pharmaceutical Inc.
C13: Model Name: | D13: Operating Model and Valuation (5-Year Forecast)
C14: Author: | D14: Glenn Rentrop
C16: File Name: | D16: =MID(CELL("filename"),SEARCH("[",CELL("filename"))+1, SEARCH("]",CELL("filename"))-SEARCH("[",CELL("filename"))-1) -> IOVAMODEL.xlsx
C17: Analysis Date: | D17: =Valuation_Date -> 45677
C19: Navigation, Summary, or Graph Worksheet:
C20: Financial Model Worksheet:
C21: Data and Back-End Calculation Worksheet:
B23: # | C23: Sheet Name | D23: Link to Sheet
B24: =_xlfn.SHEET(INDIRECT(D24&"!A1")) -> 2 | C24: Model and Valuation Summary | D24: Summary
B25: =_xlfn.SHEET(INDIRECT(D25&"!A1")) -> 3 | C25: Graphs and Dashboard | D25: Graphs
B26: =_xlfn.SHEET(INDIRECT(D26&"!A1")) -> 4 | C26: Operating Scenarios and 3-Statement Model | D26: Model
B27: =_xlfn.SHEET(INDIRECT(D27&"!A1")) -> 5 | C27: Revenue Drivers, Scenario Analysis, Capex, D&A | D27: Drivers
B28: =_xlfn.SHEET(INDIRECT(D28&"!A1")) -> 6 | C28: Stub Period Results from Q1 | D28: Q3
B29: =_xlfn.SHEET(INDIRECT(D29&"!A1")) -> 7 | C29: DCF valuation, rNPV's by asset | D29: rNPV
B30: =_xlfn.SHEET(INDIRECT(D30&"!A1")) -> 8 | C30: Weighted Average Cost of Capital (WACC) Calculations | D30: WACC
B31: =_xlfn.SHEET(INDIRECT(D31&"!A1")) -> 9 | C31: Valuation Summary - Back-End Calculations | D31: ValSum
B32: =_xlfn.SHEET(INDIRECT(D32&"!A1")) -> #REF! | C32: Valuation "Football Field" Chart | D32: ValGraph
B33: =_xlfn.SHEET(INDIRECT(D33&"!A1")) -> 10 | C33: Comparable Public Companies - Output | D33: PubComps
B34: =_xlfn.SHEET(INDIRECT(D34&"!A1")) -> 11 | C34: Comparable Public Companies - Data and Calculations | D34: PubComps_Data

Sheet Summary
C3: =Company_Name&" - Summary of Operating Model and Valuation - "&Scenario&" Case" -> Ultragenyx Pharmaceutical Inc. - Summary of Operating Model and Valuation - Base Case
C4: ($ in Thousands Except Per Share and Per Unit Data)
H6: Historical | N6: Projected
C7: Summary of Operational Performance: | E7: Units: | G7: 44561 | H7: =EOMONTH(G7,12) -> 44926 | I7: =EOMONTH(H7,12) -> 45291 | J7: =EOMONTH(I7,12) -> 45657 | K7: =EOMONTH(J7,12) -> 46022 | L7: =EOMONTH(K7,12) -> 46387 | M7: =EOMONTH(L7,12) -> 46752 | N7: =EOMONTH(M7,12) -> 47118 | O7: =EOMONTH(N7,12) -> 47483 | P7: =EOMONTH(O7,12) -> 47848 | R7: CAGR:
C8: Segment-Level Statistics:
C10: Product Revenue | E10: $T | G10: =Model!G59 -> 77017 | H10: =Model!H59 -> 118927 | I10: =Model!I59 -> 180413 | J10: =Model!J59 -> 285415 | K10: =Model!K59 -> 375393.05 | L10: =Model!L59 -> 585021.11 | M10: =Model!M59 -> 864635.16 | N10: =Model!N59 -> 1245100.3 | ... P10: =Model!P59 -> 2089814.3 | R10: =(P10/G10)^(1/YEARFRAC(G$7,P$7,))-1 -> 0.44304583
E11: % | H11: =H10/G10-1 -> 0.54416557 | I11: =I10/H10-1 -> 0.51700623 | J11: =J10/I10-1 -> 0.58200906 | K11: =K10/J10-1 -> 0.3152534 | L11: =L10/K10-1 -> 0.55842287 | M11: =M10/L10-1 -> 0.47795548 | N11: =N10/M10-1 -> 0.44002963 | O11: =O10/N10-1 -> 0.32716972 | P11: =P10/O10-1 -> 0.26466914
C13: Royalty revenue | E13: $T | G13: =Model!G60 -> 0 | H13: =Model!H60 -> 21692 | I13: =Model!I60 -> 182652 | J13: =Model!J60 -> 274815 | K13: =Model!K60 -> 296122.5 | L13: =Model!L60 -> 316851.07 | M13: =Model!M60 -> 335862.14 | N13: =Model!N60 -> 352655.24 | ... P13: =Model!P60 -> 388802.41 | R13: =(P13/H13)^(1/YEARFRAC(H$7,P$7,))-1 -> 0.43442772
E14: % | I14: =I13/H13-1 -> 7.4202471 | J14: =J13/I13-1 -> 0.50458248 | K14: =K13/J13-1 -> 0.077533967 | L14: =L13/K13-1 -> 0.07 | M14: =M13/L13-1 -> 0.06 | N14: =N13/M13-1 -> 0.05 | O14: =O13/N13-1 -> 0.05 | P14: =P13/O13-1 -> 0.05
C16: Non-cash collaboration royalty revenue | E16: $T | G16: =Model!G61 -> 189149 | H16: =Model!H61 -> 236716 | I16: =Model!I61 -> 69705 | J16: =Model!J61 -> 0 | K16: =Model!K61 -> 0 | L16: =Model!L61 -> 0 | M16: =Model!M61 -> 0 | N16: =Model!N61 -> 0 | ... P16: =Model!P61 -> 0
C18: Company-Wide:
C20: Revenue: | E20: $T | G20: =Model!G62 -> 266166 | H20: =Model!H62 -> 377335 | I20: =Model!I62 -> 432770 | J20: =Model!J62 -> 560230 | K20: =Model!K62 -> 673000 | L20: =Model!L62 -> 745000 | M20: =Model!M62 -> 1200497.3 | N20: =Model!N62 -> 1597755.5 | ... P20: =Model!P62 -> 2478616.7 | R20: =(P20/G20)^(1/YEARFRAC(G$7,P$7,))-1 -> 0.28136536
C21: Revenue Growth: | E21: % | H21: =H20/G20-1 -> 0.41766792 | I21: =I20/H20-1 -> 0.1469119 | J21: =J20/I20-1 -> 0.29452134 | K21: =K20/J20-1 -> 0.20129233 | L21: =L20/K20-1 -> 0.10698366 | M21: =M20/L20-1 -> 0.61140577 | N21: =N20/M20-1 -> 0.33091136 | O21: =O20/N20-1 -> 0.26599305 | P21: =P20/O20-1 -> 0.22537139
C23: Gross Profit: | E23: $T | G23: =Model!G62-Model!G64 -> 250158 | H23: =Model!H62-Model!H64 -> 349015 | I23: =Model!I62-Model!I64 -> 387561 | J23: =Model!J62-Model!J64 -> 483502 | K23: =Model!K62-Model!K64 -> 564000 | L23: =Model!L62-Model!L64 -> 655824.55 | M23: =Model!M62-Model!M64 -> 1056799.5 | N23: =Model!N62-Model!N64 -> 1453957.5 | ... P23: =Model!P62-Model!P64 -> 2255541.2 | R23: =(P23/G23)^(1/YEARFRAC(G$7,P$7,))-1 -> 0.2767773
C24: Profit Margin: | E24: % | H24: =G23/H20 -> 0.66295997 | I24: =H23/I20 -> 0.80646764 | J24: =I23/J20 -> 0.69178909 | K24: =J23/K20 -> 0.71842793 | L24: =K23/L20 -> 0.75704698 | M24: =L23/M20 -> 0.54629406 | N24: =M23/N20 -> 0.66142752 | O24: =N23/O20 -> 0.71880331 | P24: =O23/P20 -> 0.74263199
C26: =[1]Model!C84 -> Total operating expenses | E26: $T | G26: =-Model!G67 -> 733143 | H26: =-Model!H67 -> 1012248 | I26: =-Model!I67 -> 1003457 | J26: =-Model!J67 -> 1096203 | K26: =-Model!K67 -> 1208000 | L26: =-Model!L67 -> 1133225.5 | M26: =-Model!M67 -> 900447.84 | N26: =-Model!N67 -> 707682.99 | ... P26: =-Model!P67 -> 831075.51 | R26: =(P26/G26)^(1/YEARFRAC(G$7,P$7,))-1 -> 0.014028588
C28: EBIT | G28: =Model!G69 -> -466977 | H28: =Model!H69 -> -634913 | I28: =Model!I69 -> -570687 | J28: =Model!J69 -> -535973 | K28: =Model!K69 -> -535000 | L28: =Model!L69 -> -388225.45 | M28: =Model!M69 -> 300049.46 | N28: =Model!N69 -> 890072.5 | ... P28: =Model!P69 -> 1647541.2 | R28: =(P28/G28)^(1/YEARFRAC(G$7,P$7,))-1 -> -2.1503708
C29: Ebit Margin: | H29: =H28/H20 -> -1.6826242 | I29: =I28/I20 -> -1.3186843 | J29: =J28/J20 -> -0.95670171 | K29: =K28/K20 -> -0.79494799 | L29: =L28/L20 -> -0.52110799 | M29: =M28/M20 -> 0.24993764 | N29: =N28/N20 -> 0.55707679 | O29: =O28/O20 -> 0.55404848
C31: Comprehensive Income: | E31: $T | G31: =Model!G78 -> -538221 | H31: =Model!H78 -> -687719 | I31: =Model!I78 -> -609943 | J31: =Model!J78 -> -567586 | K31: =Model!K78 -> -586936.59 | L31: =Model!L78 -> -451266.6 | M31: =Model!M78 -> 221576.01 | N31: =Model!N78 -> 822459.44 | ... P31: =Model!P78 -> 1651310.3 | R31: =(P31/G31)^(1/YEARFRAC(G$7,P$7,))-1 -> -2.1326519
C32: Basic Earnings per Share (EPS): | E32: $ as Stated | G32: =Model!G85 -> -6.7 | H32: =Model!H85 -> -10.12 | I32: =Model!I85 -> -8.25 | J32: =Model!J85 -> -6.29 | K32: =Model!K85 -> -5.2093264 | L32: =Model!L85 -> -3.7395413 | M32: =Model!M85 -> 3.2817712 | N32: =Model!N85 -> 9.2989039 | ... P32: =Model!P85 -> 17.016768
C34: Capital expenditures: | E34: $T | G34: =Model!G172 -> -73093 | H34: =Model!H172 -> -116123 | I34: =Model!I172 -> -44267 | J34: =Model!J172 -> -7491 | K34: =Model!K172 -> -6980 | L34: =Model!L172 -> -6631 | M34: =Model!M172 -> -3150 | N34: =Model!N172 -> -2900 | ... P34: =Model!P172 -> -3040 | R34: =(P34/G34)^(1/YEARFRAC(G$7,P$7,))-1 -> -0.29764721
C35: % Revenue: | E35: %
C37: Cash Flow From Operations: | E37: $T | G37: =Model!G168 -> -423935 | H37: =Model!H168 -> -366459 | I37: =Model!I168 -> -476285 | J37: =Model!J168 -> -414188 | K37: =Model!K168 -> -18419.914 | L37: =Model!L168 -> -352456.35 | M37: =Model!M168 -> 140716.03 | N37: =Model!N168 -> 737315.01 | ... P37: =Model!P168 -> 1501170.5
C38: Cash Flow From Investing: | E38: $T | G38: =Model!G179 -> -195372 | H38: =Model!H179 -> -291652 | I38: =Model!I179 -> 168000 | J38: =Model!J179 -> -17768 | K38: =Model!K179 -> -93799.998 | L38: =Model!L179 -> 6414.5169 | M38: =Model!M179 -> 68561.755 | N38: =Model!N179 -> -3289.6174 | ... P38: =Model!P179 -> 22101.977
C39: Cash Flows From Financing Activities: | E39: $T | G39: =Model!G192 -> 118552 | H39: =Model!H192 -> 501208 | I39: =Model!I192 -> 388142 | J39: =Model!J192 -> 399241 | K39: =Model!K192 -> 0 | L39: =Model!L192 -> 0 | M39: =Model!M192 -> 0 | N39: =Model!N192 -> 0 | ... P39: =Model!P192 -> 0
C41: Total Assets: | E41: $T | G41: =Model!G106 -> 1522397 | H41: =Model!H106 -> 1545444 | I41: =Model!I106 -> 1491013 | J41: =Model!J106 -> 1503456 | K41: =Model!K106 -> 1504434.2 | L41: =Model!L106 -> 1162273.4 | M41: =Model!M106 -> 1422569.4 | N41: =Model!N106 -> 2235992.1 | ... P41: =Model!P106 -> 4940679.9
C42: Cash and Cash Equivalents: | E42: $T | G42: =Model!G92 -> 307584 | H42: =Model!H92 -> 132944 | I42: =Model!I92 -> 213584 | J42: =Model!J92 -> 173729 | K42: =Model!K92 -> 60426.088 | L42: =Model!L92 -> -286670.99 | M42: =Model!M92 -> -78443.516 | N42: =Model!N92 -> 654153.48 | ... P42: =Model!P92 -> 3246576.5
C44: EBITDA: | E44: $T | G44: =Model!G83 -> -453738 | H44: =Model!H83 -> -616693 | I44: =Model!I83 -> -544681 | J44: =Model!J83 -> -500430 | K44: =Model!K83 -> -508221.88 | L44: =Model!L83 -> -364829.64 | M44: =Model!M83 -> 320169.6 | N44: =Model!N83 -> 907201.07 | ... P44: =Model!P83 -> 1660155.9 | R44: =(P44/G44)^(1/YEARFRAC(G$7,P$7,))-1 -> -2.1550313
C45: EBITDA Margin: | E45: % | H45: =H44/H20 -> -1.6343382 | I45: =I44/I20 -> -1.2585923 | J45: =J44/J20 -> -0.89325813 | K45: =K44/K20 -> -0.75515881 | L45: =L44/L20 -> -0.48970422 | M45: =M44/M20 -> 0.26669748 | N45: =N44/N20 -> 0.56779718 | O45: =O44/O20 -> 0.56130445 | P45: =P44/P20 -> 0.66979129
H47: LTM | J47: Projected:
C48: Summary of Valuation Multiples: | E48: Units: | I48: =K7 -> 46022 | J48: =L7 -> 46387
C49: EV / Revenue - Comparables: | E49: x | H49: {=PubComps!N36:P36} -> 3.4784195 | I49: 5.4271576 | J49: 3.268504
C50: ="EV / Revenue - "&Company_Name&":" -> EV / Revenue - Ultragenyx Pharmaceutical Inc.: | E50: x | H50: {=PubComps!N40:P40} -> 3.9865889 | I50: 3.3185835 | J50: 2.9978613
C51: Projected Revenue Growth - Comparables: | E51: % | J51: =PubComps!W17 -> 0.15154256
C52: ="Projected Revenue Growth - "&Company_Name&":" -> Projected Revenue Growth - Ultragenyx Pharmaceutical Inc.: | E52: % | J52: =PubComps!W21 -> 0.064013841
C54: EV / EBITDA - Comparables: | E54: x | H54: {=PubComps!Q36:S36} -> 10.759602 | I54: 15.526997 | J54: 13.125439
C55: ="EV / EBITDA - "&Company_Name&":" -> EV / EBITDA - Ultragenyx Pharmaceutical Inc.: | E55: x | H55: {=PubComps!Q40:S40} -> NM | I55: NM | J55: NM
C56: Projected EBITDA Growth - Comparables: | E56: % | J56: =PubComps!X17 -> 0.835457
C57: ="Projected EBITDA Growth - "&Company_Name&":" -> Projected EBITDA Growth - Ultragenyx Pharmaceutical Inc.: | E57: % | J57: =PubComps!X21 -> 0.2139738
C59: P / E - Comparables: | E59: x | H59: {=PubComps!T36:V36} -> 13.07005 | I59: 18.145034 | J59: 14.770238
...

Sheet Graphs
K3: ="Revenue by Segment" -> Revenue by Segment
K17: ="Revenue vs. OpEx" -> Revenue vs. OpEx
J33: ="OpEx breakout" -> OpEx breakout
J42: =Company_Name&" - Price Volume Graph" -> Ultragenyx Pharmaceutical Inc. - Price Volume Graph
K46: Date | L46: Close | M46: Volume
K47: 46042 | L47: 22.63 | M47: 2275800
K48: 46038 | L48: 22.49 | M48: 1900600
K49: 46037 | L49: 23.5 | M49: 1760800
K50: 46036 | L50: 24.07 | M50: 2264700
K51: 46035 | L51: 24.11 | M51: 3545100
K52: 46034 | L52: 24.37 | M52: 4596500
K53: 46031 | L53: 22.51 | M53: 2764700
K54: 46030 | L54: 23.21 | M54: 2681800
K55: 46029 | L55: 24.2 | M55: 4460400
K56: 46028 | L56: 22.54 | M56: 3744400
K57: 46027 | L57: 23.11 | M57: 3956400
K58: 46024 | L58: 23.6 | M58: 3639700
... K297: 45678 | L297: 41.28 | M297: 1164800

Sheet Model
I2: Historical | O2: Projected:
B3: =Company_Name -> Ultragenyx Pharmaceutical Inc. | E3: Units: | G3: 44561 | H3: =EOMONTH(G3,12) -> 44926 | I3: =EOMONTH(H3,12) -> 45291 | J3: =EOMONTH(I3,12) -> 45657 | K3: =EOMONTH(J3,12) -> 46022 | L3: =EOMONTH(K3,12) -> 46387 | M3: =EOMONTH(L3,12) -> 46752 | N3: =EOMONTH(M3,12) -> 47118 | O3: =EOMONTH(N3,12) -> 47483 | P3: =EOMONTH(O3,12) -> 47848
C5: Company Name: | E5: Name | F5: Ultragenyx Pharmaceutical Inc. | H5: Last Fiscal Year: | L5: 45657
C6: Ticker: | E6: Name | F6: RARE | H6: Next Fiscal Year: | L6: =EOMONTH(L5,12) -> 46022
C7: Current Share Price: | E7: $ / Share | F7: 23.66 | H7: Most Recent Quarter End Date: | L7: 45608
C8: Diluted Shares Outstanding: | E8: M Shares | F8: 97.56 | H8: Valuation Date: | L8: 45677
C10: Effective Tax Rate: | E10: % | F10: 0.21
C11: Discount Rate (WACC): | E11: % | F11: =Discount_Rate -> 0.1 | H11: LTM Period: | L11: 45565
H12: Forward Year 1: | L12: =EOMONTH(L5,12) -> 46022
C13: Conversion Units: | E13: # | F13: 1000 | H13: Forward Year 2: | L13: =EOMONTH(L12,12) -> 46387
H14: Forward Year 3: | L14: =EOMONTH(L13,12) -> 46752
I16: Historical | O16: Projected:
B17: =Company_Name&" - Model Drivers and Assumptions" -> Ultragenyx Pharmaceutical Inc. - Model Drivers and Assumptions | E17: Units: | G17: =G3 -> 44561 | H17: =EOMONTH(G17,12) -> 44926 | I17: =EOMONTH(H17,12) -> 45291 | J17: =EOMONTH(I17,12) -> 45657 | K17: =EOMONTH(J17,12) -> 46022 | L17: =EOMONTH(K17,12) -> 46387 | M17: =EOMONTH(L17,12) -> 46752 | N17: =EOMONTH(M17,12) -> 47118 | O17: =EOMONTH(N17,12) -> 47483 | P17: =EOMONTH(O17,12) -> 47848
C18: Income Statement
C20: Cost of sales % Revenue | E20: % | G20: =G64/G62 -> 0.060142918 | H20: =H64/H62 -> 0.075052672 | I20: =I64/I62 -> 0.10446427 | J20: =J64/J62 -> 0.13695804 | K20: =AVERAGE(G20:J20) -> 0.094154473
C21: Selling, general and administrative % Revenue | E21: % | G21: =G65/G62 -> 0.82648422 | H21: =H65/H62 -> 0.73711424 | I21: =I65/I62 -> 0.71585138 | J21: =J65/J62 -> 0.57406779 | K21: =AVERAGE(G21:J21) -> 0.71337941
C23: Interest income % cash | E23: % | H23: =H71/G92 -> 0.036003173 | I23: =I71/H92 -> 0.20074618 | J23: =J71/I92 -> 0.17092104 | K23: 0.04 | L23: 0.04 | M23: 0.04 | N23: 0.04 | O23: 0.04 | P23: 0.04
C25: Beginning Balance | E25: $T | G25: 0 | H25: =G29 -> 1862400 | I25: =H29 -> 1466600 | J25: =I29 -> 1664700 | K25: =J29 -> 1934900 | L25: =K29 -> 2521836.6 | M25: =L29 -> 2973103.2 | N25: =M29 -> 2795842.4 | O25: =N29 -> 2137874.8 | P25: =O29 -> 1271592.3
C26: (+) NOLs Created | E26: $T | G26: 0 | H26: 0 | I26: 198100 | J26: 270200 | K26: =IF(K78<0,-K78,0) -> 586936.59 | L26: =IF(L78<0,-L78,0) -> 451266.6 | M26: =IF(M78<0,-M78,0) -> 0 | N26: =IF(N78<0,-N78,0) -> 0 | O26: =IF(O78<0,-O78,0) -> 0 | P26: =IF(P78<0,-P78,0) -> 0
C27: (-) NOLs Used | E27: $T | G27: 0 | H27: -395800 | I27: 0 | J27: 0 | K27: =-MIN(+K25+K26,MAX(K78*K33,0)) -> 0 | L27: =-MIN(+L25+L26,MAX(L78*L33,0)) -> 0 | M27: =-MIN(+M25+M26,MAX(M78*M33,0)) -> -177260.81 | N27: =-MIN(+N25+N26,MAX(N78*N33,0)) -> -657967.55 | O27: =-MIN(+O25+O26,MAX(O78*O33,0)) -> -866282.49 | P27: =-MIN(+P25+P26,MAX(P78*P33,0)) -> -1271592.3
C28: Other NOL Adjustments | E28: $T | G28: 0 | H28: 0 | I28: 0 | J28: 0 | K28: 0 | L28: 0 | M28: 0 | N28: 0 | O28: 0 | P28: 0
C29: Ending Balance | E29: $T | G29: 1862400 | H29: =SUM(H25:H28) -> 1466600 | I29: =SUM(I25:I28) -> 1664700 | J29: =SUM(J25:J28) -> 1934900 | K29: =SUM(K25:K28) -> 2521836.6 | L29: =SUM(L25:L28) -> 2973103.2 | M29: =SUM(M25:M28) -> 2795842.4 | N29: =SUM(N25:N28) -> 2137874.8 | O29: =SUM(O25:O28) -> 1271592.3 | P29: =SUM(P25:P28) -> 0
C31: Taxable Income After NOL | E31: $T | G31: 0 | H31: 0 | I31: 0 | J31: 0 | K31: =IF(K27<0,SUM(K27,K78),0) -> 0 | L31: =IF(L27<0,SUM(L27,L78),0) -> 0 | M31: =IF(M27<0,SUM(M27,M78),0) -> 44315.202 | N31: =IF(N27<0,SUM(N27,N78),0) -> 164491.89 | O31: =IF(O27<0,SUM(O27,O78),0) -> 216570.62 | P31: =IF(P27<0,SUM(P27,P78),0) -> 379717.96
C32: Cash Taxes Payable | E32: $T | G32: 0 | H32: 0 | I32: 0 | J32: 0 | K32: =K31*Tax_Rate -> 0 | L32: =L31*Tax_Rate -> 0 | M32: =M31*Tax_Rate -> 9306.1925 | N32: =N31*Tax_Rate -> 34543.296 | O32: =O31*Tax_Rate -> 45479.831 | P32: =P31*Tax_Rate -> 79740.771
C33: NOL Utilization Limit (% of EBT) | E33: $T | G33: 0.8 | H33: 0.8 | I33: 0.8 | J33: 0.8 | K33: 0.8 | L33: 0.8 | M33: 0.8 | N33: 0.8 | O33: 0.8 | P33: 0.8
C35: Balance Sheet
C37: Days Recievables Outstanding | E37: Days | G37: =G94*(G57-EOMONTH(G57,-12))/G62 -> 38.989503 | H37: =H94*(H57-EOMONTH(H57,-12))/H62 -> 39.122862 | I37: =I94*(I57-EOMONTH(I57,-12))/I62 -> 61.897428 | J37: =J94*(J57-EOMONTH(J57,-12))/J62 -> 79.572972 | K37: 90 | L37: 100 | M37: 90 | N37: 80 | O37: 70 | P37: 65
C38: Days Inventory Outstanding | E38: Days | G38: =G95*(G57-EOMONTH(G57,-12))/G62 -> 22.257971 | H38: =H95*(H57-EOMONTH(H57,-12))/H62 -> 25.891025 | I38: =I95*(I57-EOMONTH(I57,-12))/I62 -> 28.649594 | J38: =J95*(J57-EOMONTH(J57,-12))/J62 -> 29.403213 | K38: =AVERAGE(G38:J38) -> 26.550451 | L38: =K38+2 -> 28.550451 | M38: =L38+2 -> 30.550451 | N38: =M38+2 -> 32.550451 | O38: =N38+2 -> 34.550451 | P38: =O38+2 -> 36.550451
C39: Prepaid expenses and other current assets % Revenue | E39: % | G39: =G96/G62 -> 0.26954983 | H39: =H96/H62 -> 0.18266527 | I39: =I96/I62 -> 0.11002611 | J39: =J96/J62 -> 0.071916891 | K39: 0.06 | L39: 0.05 | M39: 0.03 | N39: 0.02 | O39: 0.01 | P39: 0.01
C41: Marketable debt securities (non-current) % current | E41: % | G41: =G101/G93 -> 0.59853402 | H41: =H101/H93 -> 0.24229935 | I41: =I101/I93 -> 0.54974493 | J41: =J101/J93 -> 0.30943213 | K41: =AVERAGE(G41:J41) -> 0.42500261 | L41: =K41-5% -> 0.37500261 | M41: =L41-5% -> 0.32500261 | N41: =M41-5% -> 0.27500261 | O41: =N41-5% -> 0.22500261 | P41: =O41-5% -> 0.17500261
C42: Other assets % Revenue | E42: % | G42: =G105/G62 -> 0.077237513 | H42: =H105/H62 -> 0.044644679 | I42: =I105/I62 -> 0.13329251 | J42: =J105/J62 -> 0.11188262 | K42: =AVERAGE(G42:J42) -> 0.091764331 | L42: 0.07 | M42: 0.05 | N42: 0.04 | O42: 0.03 | P42: 0.02
C44: Days Payables Outstanding | E44: Days | G44: =G110*(G57-EOMONTH(G57,-12))/G62 -> 23.501762 | H44: =H110*(H57-EOMONTH(H57,-12))/H62 -> 41.859382 | I44: =I110*(I57-EOMONTH(I57,-12))/I62 -> 35.519121 | J44: =J110*(J57-EOMONTH(J57,-12))/J62 -> 25.319415 | K44: =AVERAGE(G44:J44) -> 31.54992 | L44: 28 | M44: 26 | N44: 24 | O44: 22 | P44: 20
C45: Accrued liabilities % Opex | E45: % | G45: =-G111/G67 -> 0.19853562 | H45: =-H111/H67 -> 0.20220144 | I45: =-I111/I67 -> 0.19580909 | J45: =-J111/J67 -> 0.21982516 | K45: =AVERAGE(G45:J45) -> 0.20409283 | L45: =K45-3% -> 0.17409283 | M45: =L45-3% -> 0.14409283 | N45: =M45-2% -> 0.12409283 | O45: =N45-2% -> 0.10409283 | P45: =O45-2% -> 0.084092826
C47: Other liabilities (current) | E47: % | G47: =G115/G122 -> 0 | H47: =H115/H122 -> 0 | I47: =I115/I122 -> 0 | J47: =J115/J122 -> 0.25055614 | K47: 0.25055614 | L47: 0.25055614 | M47: 0.25055614 | N47: 0.25055614 | O47: 0.25055614 | P47: 0.25055614
C49: Lease liabilities (non-current) % PPE | E49: % | G49: =G119/G99 -> 0.21879403 | H49: =H119/H99 -> 0.076288088 | I49: =I119/I99 -> 0.10522222 | J49: =J119/J99 -> 0.11297 | K49: =AVERAGE(H49:J49) -> 0.098160104 | L49: =AVERAGE(I49:K49) -> 0.10545078 | M49: =AVERAGE(J49:L49) -> 0.10552696 | N49: =AVERAGE(K49:M49) -> 0.10304595 | O49: =AVERAGE(L49:N49) -> 0.10467456 | P49: =AVERAGE(M49:O49) -> 0.10441582
C50: Other liabilities (non-current) | E50: % | G50: =G122/G65 -> 0.0045685556 | H50: =H122/H65 -> 0.017329465 | I50: =I122/I65 -> 0.039396512 | J50: =J122/J65 -> 0.05311402 | K50: =AVERAGE(G50:J50) -> 0.028602138 | L50: 0.03 | M50: 0.02 | N50: 0.02 | O50: 0.01 | P50: 0.01
C52: Cash Flow Statement
C54: Stock-based compensation % R&D | E54: % | G54: =G149/G66 -> 0.21110604 | H54: =H149/H66 -> 0.18472518 | I54: =I149/I66 -> 0.20853914 | J54: =J149/J66 -> 0.22644781 | K54: =AVERAGE(G54:J54) -> 0.20770454 | L54: =K54-2% -> 0.18770454 | M54: =L54-2% -> 0.16770454 | N54: =M54-2% -> 0.14770454 | O54: =N54-2% -> 0.12770454 | P54: =O54-2% -> 0.10770454
I56: Historical | O56: Projected:
B57: ="Income Statement - "&Company_Name -> Income Statement - Ultragenyx Pharmaceutical Inc. | E57: Units: | G57: =G3 -> 44561 | H57: =EOMONTH(G57,12) -> 44926 | I57: =EOMONTH(H57,12) -> 45291 | J57: =EOMONTH(I57,12) -> 45657 | K57: =EOMONTH(J57,12) -> 46022 | L57: =EOMONTH(K57,12) -> 46387 | M57: =EOMONTH(L57,12) -> 46752 | N57: =EOMONTH(M57,12) -> 47118 | O57: =EOMONTH(N57,12) -> 47483 | P57: =EOMONTH(O57,12) -> 47848
...

Sheet Drivers
B2: =Company_Name&" - Revenue Drivers" -> Ultragenyx Pharmaceutical Inc. - Revenue Drivers | I2: Historical | O2: Projected:
B3: Commercial Products | E3: Units: | G3: =Model!G3 -> 44561 | H3: =EOMONTH(G3,12) -> 44926 | I3: =EOMONTH(H3,12) -> 45291 | J3: =EOMONTH(I3,12) -> 45657 | K3: =EOMONTH(J3,12) -> 46022 | L3: =EOMONTH(K3,12) -> 46387 | M3: =EOMONTH(L3,12) -> 46752 | N3: =EOMONTH(M3,12) -> 47118 | O3: =EOMONTH(N3,12) -> 47483 | ... AE3: =EOMONTH(AD3,12) -> 53327
B4: COMMERCIAL PRODUCTS
C6: Product sales | E6: $T | G6: =Model!G59 -> 77017 | H6: =Model!H59 -> 118927 | I6: =Model!I59 -> 180413 | J6: =Model!J59 -> 285415 | K6: =SUM(K27,K81,K112,K161) -> 375393.05 | L6: =SUM(L27,L81,L112,L161,L216,L264,L312,L361) -> 585021.11 | M6: =SUM(M27,M81,M112,M161,M216,M264,M312,M361) -> 864635.16 | N6: =SUM(N27,N81,N112,N161,N216,N264,N312,N361) -> 1245100.3 | O6: =SUM(O27,O81,O112,O161,O216,O264,O312,O361) -> 1652459.4 | P6: =SUM(P27,P81,P112,P161,P216,P264,P312,P361) -> 2089814.3 | Q6: =SUM(Q27,Q81,Q112,Q161,Q216,Q264,Q312,Q361) -> 2473172 | R6: =SUM(R27,R81,R112,R161,R216,R264,R312,R361) -> 2636940.8 | S6: =SUM(S27,S81,S112,S161,S216,S264,S312,S361) -> 2659930 | ... AE6: =SUM(AE27,AE81,AE112,AE161,AE216,AE264,AE312,AE361) -> 1081252.4
C7: Royalty revenue | E7: $T | G7: =Model!G60 -> 0 | H7: =Model!H60 -> 21692 | I7: =Model!I60 -> 182652 | J7: =Model!J60 -> 274815 | K7: =K29 -> 296122.5 | L7: =L29 -> 316851.07 | M7: =M29 -> 335862.14 | N7: =N29 -> 352655.24 | O7: =O29 -> 370288.01 | P7: =P29 -> 388802.41 | Q7: =Q29 -> 408242.53 | R7: =R29 -> 428654.65 | ... AE7: =AE29 -> 0
C8: Non-cash collaboration royalty revenue | E8: $T | G8: =Model!G61 -> 189149 | H8: =Model!H61 -> 236716 | I8: =Model!I61 -> 69705 | J8: =Model!J61 -> 0 | K8: 0 | L8: 0 | M8: 0 | N8: 0 | O8: 0 | P8: 0 | Q8: 0 | R8: 0 | S8: 0 | T8: 0 | U8: 0 | V8: 0 | W8: 0 | X8: 0 | Y8: 0 | Z8: 0 | AA8: 0 | AB8: 0 | AC8: 0 | AD8: 0 | AE8: 0
C9: Total revenues | E9: $T | G9: =Model!G62 -> 266166 | H9: =Model!H62 -> 377335 | I9: =Model!I62 -> 432770 | J9: =Model!J62 -> 560230 | K9: =SUM(K6:K8) -> 671515.55 | L9: =Model!L62 -> 745000 | M9: =SUM(M6:M8) -> 1200497.3 | N9: =SUM(N6:N8) -> 1597755.5 | O9: =SUM(O6:O8) -> 2022747.4 | P9: =SUM(P6:P8) -> 2478616.7 | Q9: =SUM(Q6:Q8) -> 2881414.6 | R9: =SUM(R6:R8) -> 3065595.5 | S9: =SUM(S6:S8) -> 2981421 | T9: =SUM(T6:T8) -> 2623781.7 | ... AE9: =SUM(AE6:AE8) -> 1081252.4
C10: % Growth | H10: =H9/G9-1 -> 0.41766792 | I10: =I9/H9-1 -> 0.1469119 | J10: =J9/I9-1 -> 0.29452134 | K10: =K9/J9-1 -> 0.19864261 | L10: =L9/K9-1 -> 0.10943075 | M10: =M9/L9-1 -> 0.61140577 | N10: =N9/M9-1 -> 0.33091136 | O10: =O9/N9-1 -> 0.26599305 | ... W10: =W9/V9-1 -> -0.33991469
C12: Cost of sales | E12: $T | G12: 16008 | H12: 28320 | I12: 45209 | J12: 76728 | K12: =Model!K64 -> 109000 | L12: =Model!L64 -> 89175.452 | M12: =Model!M64 -> 143697.84 | N12: =Model!N64 -> 143797.99 | O12: =Model!O64 -> 182047.26 | P12: =SUM(P47,P84,P115,P164) -> 139024.68 | Q12: =Q9*0.09 -> 259327.31 | R12: =R9*0.09 -> 275903.59 | S12: =S9*0.09 -> 268327.89 | T12: =T9*0.09 -> 236140.35 | U12: =U9*0.09 -> 212616.59 | V12: =V9*0.09 -> 161692.6 | W12: =W9*0.09 -> 106730.91 | X12: =X9*0.09 -> 97441.802 | ... AE12: =AE9*0.09 -> 97312.718
C13: Research and development | E13: $T | G13: 497153 | H13: 705789 | I13: 648449 | J13: 697865 | K13: =Model!K65 -> 349000 | L13: =Model!L65 -> 331550 | M13: =Model!M65 -> 315000 | N13: =Model!N65 -> 290000 | O13: =Model!O65 -> 320000 | P13: =O13*0.95 -> 304000 | Q13: =P13*0.95 -> 288800 | R13: =Q13*0.95 -> 274360 | S13: =R13*0.95 -> 260642 | T13: =S13*0.95 -> 247609.9 | U13: =T13*0.95 -> 235229.4 | V13: =U13*0.95 -> 223467.93 | W13: =V13*0.95 -> 212294.54 | ... AE13: =AD13*0.95 -> 140840.53
C14: Selling, general and administrative | E14: $T | G14: 219982 | H14: 278139 | I14: 309799 | J14: 321610 | K14: =Model!K66 -> 750000 | L14: =Model!L66 -> 712500 | M14: =Model!M66 -> 441750 | N14: =Model!N66 -> 273885 | O14: =Model!O66 -> 400000 | P14: =P17 -> 304000 | Q14: =Q17 -> 288800 | R14: =R17 -> 274360 | S14: =S17 -> 260642 | T14: =T17 -> 247609.9 | U14: =U17 -> 235229.4 | V14: =V17 -> 223467.93 | W14: =W17 -> 212294.54 | ... AE14: =AE17 -> 200000
C15: Total operating expenses | E15: $T | G15: =-SUM(G12:G14) -> -733143 | H15: =-SUM(H12:H14) -> -1012248 | I15: =-SUM(I12:I14) -> -1003457 | J15: =-SUM(J12:J14) -> -1096203 | K15: =-SUM(K12:K14) -> -1208000 | L15: =-SUM(L12:L14) -> -1133225.5 | M15: =-SUM(M12:M14) -> -900447.84 | N15: =-SUM(N12:N14) -> -707682.99 | ... AE15: =-SUM(AE12:AE14) -> -438153.25
C17: SG&A | K17: =INDEX($K$18:$AE$20,MATCH(OpEx,$C$18:$C$20,0),1) -> 300000 | L17: =INDEX($K$18:$AE$20,MATCH(OpEx,$C$18:$C$20,0),2) -> 280000 | M17: =INDEX($K$18:$AE$20,MATCH(OpEx,$C$18:$C$20,0),3) -> 260000 | N17: =INDEX($K$18:$AE$20,MATCH(OpEx,$C$18:$C$20,0),4) -> 290000 | O17: =INDEX($K$18:$AE$20,MATCH(OpEx,$C$18:$C$20,0),5) -> 320000 | P17: =INDEX($K$18:$AE$20,MATCH(OpEx,$C$18:$C$20,0),6) -> 304000 | Q17: =INDEX($K$18:$AE$20,MATCH(OpEx,$C$18:$C$20,0),7) -> 288800 | R17: =INDEX($K$18:$AE$20,MATCH(OpEx,$C$18:$C$20,0),8) -> 274360 | S17: =INDEX($K$18:$AE$20,MATCH(OpEx,$C$18:$C$20,0),9) -> 260642 | T17: =INDEX($K$18:$AE$20,MATCH(OpEx,$C$18:$C$20,0),10) -> 247609.9 | U17: =INDEX($K$18:$AE$20,MATCH(OpEx,$C$18:$C$20,0),11) -> 235229.4 | V17: =INDEX($K$18:$AE$20,MATCH(OpEx,$C$18:$C$20,0),12) -> 223467.93 | W17: =INDEX($K$18:$AE$20,MATCH(OpEx,$C$18:$C$20,0),13) -> 212294.54 | X17: =INDEX($K$18:$AE$20,MATCH(OpEx,$C$18:$C$20,0),14) -> 201679.81 | Y17: =INDEX($K$18:$AE$20,MATCH(OpEx,$C$18:$C$20,0),15) -> 200000 | Z17: =INDEX($K$18:$AE$20,MATCH(OpEx,$C$18:$C$20,0),16) -> 200000 | AA17: =INDEX($K$18:$AE$20,MATCH(OpEx,$C$18:$C$20,0),17) -> 200000 | AB17: =INDEX($K$18:$AE$20,MATCH(OpEx,$C$18:$C$20,0),18) -> 200000 | AC17: =INDEX($K$18:$AE$20,MATCH(OpEx,$C$18:$C$20,0),19) -> 200000 | AD17: =INDEX($K$18:$AE$20,MATCH(OpEx,$C$18:$C$20,0),20) -> 200000 | AE17: =INDEX($K$18:$AE$20,MATCH(OpEx,$C$18:$C$20,0),21) -> 200000
C18: Upside | K18: 200000 | L18: 210000 | M18: 230000 | N18: 270000 | O18: 250000 | P18: =O18-10000 -> 240000 | Q18: =P18-10000 -> 230000 | R18: =Q18-10000 -> 220000 | S18: =R18-10000 -> 210000 | T18: =S18-10000 -> 200000 | U18: 200000 | V18: 200000 | W18: 200000 | X18: 200000 | Y18: 200000 | Z18: 200000 | AA18: 200000 | AB18: 200000 | AC18: 200000 | AD18: 200000 | AE18: 200000
C19: Base | G19: 219982 | H19: 278139 | I19: 309799 | J19: 321610 | K19: 300000 | L19: 280000 | M19: 260000 | N19: 290000 | O19: 320000 | P19: =O19*0.95 -> 304000 | Q19: =P19*0.95 -> 288800 | R19: =Q19*0.95 -> 274360 | S19: =R19*0.95 -> 260642 | T19: =S19*0.95 -> 247609.9 | U19: =T19*0.95 -> 235229.4 | V19: =U19*0.95 -> 223467.93 | W19: =V19*0.95 -> 212294.54 | X19: =W19*0.95 -> 201679.81 | Y19: 200000 | Z19: 200000 | AA19: 200000 | AB19: 200000 | AC19: 200000 | AD19: 200000 | AE19: 200000
C20: Downside | K20: 350000 | L20: 330000 | M20: 300000 | N20: 320000 | O20: 350000 | P20: =O20*0.95 -> 332500 | Q20: =P20*0.95 -> 315875 | R20: =Q20*0.95 -> 300081.25 | S20: =R20*0.95 -> 285077.19 | T20: =S20*0.95 -> 270823.33 | U20: =T20*0.95 -> 257282.16 | V20: =U20*0.95 -> 244418.05 | W20: =V20*0.95 -> 232197.15 | ... Y20: =X20*0.95 -> 209557.93 | Z20: 200000 | AA20: 200000 | AB20: 200000 | AC20: 200000 | AD20: 200000 | AE20: 200000
B22: CRYSVITA | P22: LOE
C24: Crysvita total revenue | E24: $T | G24: 210815 | H24: 279394 | I24: 328054 | J24: 409524 | K24: 481000 | L24: =SUM(L27,L29) -> 659851.07 | M24: =SUM(M27,M29) -> 747462.14 | N24: =SUM(N27,N29) -> 805415.24 | O24: =SUM(O27,O29) -> 854741.21 | P24: =SUM(P27,P29) -> 902322.8 | Q24: =SUM(Q27,Q29) -> 947438.94 | R24: =SUM(R27,R29) -> 994810.88 | S24: =SUM(S27,S29) -> 746108.16 | ... V24: =SUM(V27,V29) -> 431250.52
C25: % Growth | H25: =H24/G24-1 -> 0.32530418 | I25: =I24/H24-1 -> 0.17416265 | J25: =J24/I24-1 -> 0.24834326 | K25: =K24/J24-1 -> 0.17453434 | L25: =L24/K24-1 -> 0.37183175 | M25: =M24/L24-1 -> 0.132774 | N25: =N24/M24-1 -> 0.077533167 | O25: =O24/N24-1 -> 0.061242896 | ... V25: =V24/U24-1 -> -0.15
C27: Crysvita product sales | E27: $T | G27: 21422 | H27: 42678 | I27: 75697 | J27: 134709 | K27: 245000 | L27: =K27*(1+L28) -> 343000 | M27: =L27*(1+M28) -> 411600 | N27: =M27*(1+N28) -> 452760 | O27: =N27*(1+O28) -> 484453.2 | P27: =O27*(1+P28) -> 513520.39 | Q27: =P27*(1+Q28) -> 539196.41 | R27: =Q27*(1+R28) -> 566156.23 | S27: =R27*(1+S28) -> 424617.17 | ... V27: =U27*(1+V28) -> 245428.73
C28: % Growth | E28: % | H28: =H27/G27-1 -> 0.99225096 | I28: =I27/H27-1 -> 0.7736773 | J28: =J27/I27-1 -> 0.77958175 | K28: 0.6 | L28: 0.4 | M28: 0.2 | N28: 0.1 | O28: 0.07 | P28: 0.06 | Q28: 0.05 | R28: 0.05 | S28: -0.25 | T28: -0.2 | U28: -0.15 | V28: -0.15
C29: Crysvita royalty/rev-share stream | E29: $T | G29: 189393 | H29: 236716 | I29: 252357 | J29: 274815 | K29: =J29*(1+K30) -> 296122.5 | L29: =K29*(1+L30) -> 316851.07 | M29: =L29*(1+M30) -> 335862.14 | N29: =M29*(1+N30) -> 352655.24 | O29: =N29*(1+O30) -> 370288.01 | P29: =O29*(1+P30) -> 388802.41 | Q29: =P29*(1+Q30) -> 408242.53 | R29: =Q29*(1+R30) -> 428654.65 | ... V29: =U29*(1+V30) -> 185821.79
C30: % Growth | H30: =H29/G29-1 -> 0.24986668 | I30: =I29/H29-1 -> 0.066074959 | J30: =J29/I29-1 -> 0.088992974 | K30: =AVERAGE(I30:J30) -> 0.077533967 | L30: 0.07 | M30: 0.06 | N30: 0.05 | O30: 0.05 | P30: =AVERAGE(N30:O30) -> 0.05 | Q30: =AVERAGE(O30:P30) -> 0.05 | R30: =AVERAGE(P30:Q30) -> 0.05 | S30: -0.25 | T30: -0.2 | U30: -0.15 | V30: -0.15
C32: Royalty revenue applied to reduce liability (repayment) % Royalty stream | E32: % | G32: =-G40/G29 -> 0.09478175 | H32: =-H40/H29 -> 0.091637236 | I32: =-I40/I29 -> 0.2350123 | J32: =-J40/J29 -> 0.30906974 | K32: =IF(K39>0,31%,0) -> 0.31 | L32: =IF(L39>0,31%,0) -> 0.31 | M32: =IF(M39>0,31%,0) -> 0.31 | N32: =IF(N39>0,31%,0) -> 0.31 | O32: =IF(O39>0,31%,0) -> 0.31 | P32: =IF(P39>0,31%,0) -> 0.31 | Q32: =IF(Q39>0,31%,0) -> 0.31 | R32: =IF(R39>0,31%,0) -> 0.31 | ... V32: =IF(V39>0,31%,0) -> 0.31
C35: Liabilities for sales of future royalties (current) | E35: $T | G35: =Model!G114 -> 0 | H35: =Model!H114 -> 0 | I35: =Model!I114 -> 29242 | J35: =Model!J114 -> 49847 | K35: =-L40 -> 98223.832 | L35: =-M40 -> 104117.26 | M35: =-N40 -> 109323.13 | N35: =-O40 -> 114789.28 | O35: =-P40 -> 120528.75 | P35: =-Q40 -> 126555.18 | Q35: =-R40 -> 132882.94 | R35: =-S40 -> 99662.207 | ... V35: =-W40 -> 0
C36: Liabilities for sales of future royalties (non-current) | E36: $T | G36: =Model!G121 -> 351786 | H36: =Model!H121 -> 875439 | I36: =Model!I121 -> 862325 | J36: =Model!J121 -> 819824 | K36: =K37-K35 -> 1136384.9 | L36: =L37-L35 -> 1094669.4 | M36: =M37-M35 -> 1049749.6 | N36: =N37-N35 -> 996605.77 | O36: =O37-O35 -> 937373.59 | P36: =P37-P35 -> 873255.17 | Q36: =Q37-Q35 -> 802817.76 | R36: =R37-R35 -> 765111.63 | ... V36: =V37-V35 -> 808514.71
C37: Liabilities for sales of future royalties (total) | E37: $T | G37: =SUM(G35:G36) -> 351786 | H37: =SUM(H35:H36) -> 875439 | I37: =SUM(I35:I36) -> 891567 | J37: =SUM(J35:J36) -> 869671 | K37: =K43 -> 1234608.8 | L37: =L43 -> 1198786.6 | M37: =M43 -> 1159072.7 | N37: =N43 -> 1111395.1 | O37: =O43 -> 1057902.3 | P37: =P43 -> 999810.35 | Q37: =Q43 -> 935700.7 | R37: =R43 -> 864773.84 | ... V37: =V43 -> 808514.71
C39: Liabilities for sales of future royalties — Beginning of year | E39: $T | G39: 335665 | H39: =G43 -> 351786 | I39: =H43 -> 875439 | J39: =I43 -> 891567 | K39: =J43 -> 869671 | L39: =K43 -> 1234608.8 | M39: =L43 -> 1198786.6 | N39: =M43 -> 1159072.7 | O39: =N43 -> 1111395.1 | ... V39: =U43 -> 804026.67
C40: Less: Royalty revenue applied to reduce liability (repayment) | E40: $T | G40: -17951 | H40: -21692 | I40: -59307 | J40: -84937 | K40: =IF(K29*K32<K39,-K29*K32,-K39) -> -91797.974 | L40: =IF(L29*L32<L39,-L29*L32,-L39) -> -98223.832 | M40: =IF(M29*M32<M39,-M29*M32,-M39) -> -104117.26 | N40: =IF(N29*N32<N39,-N29*N32,-N39) -> -109323.13 | O40: =IF(O29*O32<O39,-O29*O32,-O39) -> -114789.28 | P40: =IF(P29*P32<P39,-P29*P32,-P39) -> -120528.75 | Q40: =IF(Q29*Q32<Q39,-Q29*Q32,-Q39) -> -126555.18 | R40: =IF(R29*R32<R39,-R29*R32,-R39) -> -132882.94 | ... V40: =IF(V29*V32<V39,-V29*V32,-V39) -> -57604.755
C41: Proceeds from sale of future royalties | E41: $T | G41: =Model!G183 -> 0 | H41: =Model!H183 -> 490950 | I41: =Model!I183 -> 0 | J41: =Model!J183 -> 0 | K41: 400000 | L41: 0 | M41: 0 | N41: 0 | O41: 0 | P41: 0 | Q41: 0 | R41: 0 | S41: 0 | T41: 0 | U41: 0 | V41: 0
C42: Add: Non-cash interest expense (accretion) | E42: $T | G42: 34072 | H42: 54395 | I42: 75435 | J42: =Model!J155 -> 63041 | K42: =AVERAGE(G42:J42) -> 56735.75 | L42: =AVERAGE(H42:K42) -> 62401.688 | M42: =AVERAGE(I42:L42) -> 64403.359 | N42: =AVERAGE(J42:M42) -> 61645.449 | O42: =AVERAGE(K42:N42) -> 61296.562 | P42: =AVERAGE(L42:O42) -> 62436.764 | Q42: =AVERAGE(M42:P42) -> 62445.534 | R42: =AVERAGE(N42:Q42) -> 61956.077 | ... V42: =AVERAGE(R42:U42) -> 62092.795
C43: Liabilities for sales of future royalties — End of year | E43: $T | G43: =SUM(G39:G42) -> 351786 | H43: =SUM(H39:H42) -> 875439 | I43: =SUM(I39:I42) -> 891567 | J43: =SUM(J39:J42) -> 869671 | K43: =SUM(K39:K42) -> 1234608.8 | L43: =SUM(L39:L42) -> 1198786.6 | M43: =SUM(M39:M42) -> 1159072.7 | N43: =SUM(N39:N42) -> 1111395.1 | ... V43: =SUM(V39:V42) -> 808514.71
C45: Non-cash interest expense on liabilities for sales of future royalties (P&L) | E45: $T | G45: 29422 | H45: 43015 | I45: 66004 | J45: 63041
C47: COGS (Revenue Weighted) | E47: $ | G47: =(G24/G9)*G12 -> 12679.029 | H47: =(H24/H9)*H12 -> 20969.266 | I47: =(I24/I9)*I12 -> 34269.92 | J47: =(J24/J9)*J12 -> 56087.602 | K47: =K24*K48 -> 45288.301 | L47: =L24*L48 -> 67738.57 | M47: =M24*M48 -> 81890.855 | N47: =N24*N48 -> 89265.863 | O47: =O24*O48 -> 89150.035 | P47: =P24*P48 -> 96401.599 | Q47: =Q24*Q48 -> 102211.7 | R47: =R24*R48 -> 106905.36 | ... V47: =V24*V48 -> 46205.915
C48: Incremental COGS % Revenue | E48: % | G48: =G47/G24 -> 0.060142918 | H48: =H47/H24 -> 0.075052672 | I48: =I47/I24 -> 0.10446427 | J48: =J47/J24 -> 0.13695804 | K48: =AVERAGE(G48:J48) -> 0.094154473 | L48: =AVERAGE(H48:K48) -> 0.10265736 | M48: =AVERAGE(I48:L48) -> 0.10955853 | N48: =AVERAGE(J48:M48) -> 0.1108321 | O48: =AVERAGE(K48:N48) -> 0.10430062 | P48: =AVERAGE(L48:O48) -> 0.10683715 | Q48: =AVERAGE(M48:P48) -> 0.1078821 | R48: =AVERAGE(N48:Q48) -> 0.10746299 | ... V48: =AVERAGE(R48:U48) -> 0.10714402
B52: DOJOLVI | T52: LOE
C54: GLOBAL
C55: LC-FAOD Ex- U.S. | E55: # | G55: 10781.645 | H55: 10835.824 | I55: 10890.275 | J55: 10945 | K55: 11000 | L55: 11055 | M55: 11110 | N55: 11165.5 | O55: 11221.5 | P55: 11278 | Q55: 11334 | R55: 11390.5 | S55: 11448 | T55: 11505.5 | U55: 11563 | V55: 11620.5 | W55: 11678
C56: % Growth | E56: % | H56: 0.005 | I56: 0.005 | J56: 0.005 | K56: 0.005 | L56: 0.005 | M56: 0.005 | N56: 0.005 | O56: 0.005 | P56: 0.005 | Q56: 0.005 | R56: 0.005 | S56: 0.005 | T56: 0.005 | U56: 0.005 | V56: 0.005 | W56: 0.005
C58: UNITED STATES
...

Sheet Q3
B2: =Company_Name&" - Q3 Financial Results" -> Ultragenyx Pharmaceutical Inc. - Q3 Financial Results
B3: ($ in Thousands Except Per Share and Per Unit Data)
B6: Reported Income Statement and Cash Flow Statement Figures from Q3: | H6: FY25- Q1 | I6: FY25- Q2 | J6: FY25- Q3
C8: Revenue: | H8: 139292 | I8: 166496 | J8: 159933
C9: Annual Revenue Growth Rate: | I9: =I8/H8-1 -> 0.19530196 | J9: =J8/I8-1 -> -0.039418364
C10: Operating Income (EBIT): | H10: -142939 | I10: -107888 | J10: -170890
C11: Annual Operating Margin: | H11: =+H10/H8 -> -1.0261824 | I11: =+I10/I8 -> -0.64799154 | J11: =+J10/J8 -> -1.0685099
C13: Taxes, Excluding Effect of Interest: | H13: -1310 | I13: -947 | J13: -873
C15: Net Operating Profit After Tax (NOPAT): | H15: =SUM(H10,H13) -> -144249 | I15: =SUM(I10,I13) -> -108835 | J15: =SUM(J10,J13) -> -171763
C17: Adjustments for Non-Cash Charges:
C18: Depreciation & Amortization: | H18: 8990 | I18: 8619 | J18: 8606
C19: Deferred Income Taxes: | H19: 0 | I19: 0 | J19: 0
C20: Other Operating Activities: | H20: 32091 | I20: 20030 | J20: 25525
C21: Total Adjustments for Non-Cash Charges: | H21: =SUM(H18:H20) -> 41081 | I21: =SUM(I18:I20) -> 28649 | J21: =SUM(J18:J20) -> 34131
C23: Net Change in Working Capital:
C24: Accounts Receivable: | H24: 10062 | I24: -12653 | J24: 5425
C25: Inventories: | H25: -763 | I25: 208 | J25: -5595
C26: Accounts Payable: | H26: -48454 | I26: -9682 | J26: 45124
C27: Other Liabilities: | H27: -1324 | I27: -2460 | J27: -1278
C28: Total Net Change in Working Capital: | H28: =SUM(H24:H27) -> -40479 | I28: =SUM(I24:I27) -> -24587 | J28: =SUM(J24:J27) -> 43676
C30: Capital Expenditures and Acquisitions: | H30: -1324 | I30: -2460 | J30: -1278
C32: Q3 Unlevered Free Cash Flow: | H32: =SUM(H15,H21,H28,H30) -> -144971 | I32: =SUM(I15,I21,I28,I30) -> -107233 | J32: =SUM(J15,J21,J28,J30) -> -95234

Sheet rNPV
H2: Historical | P2: Projected:
B3: =Ticker&"- Risk-Adjusted Net Present Value Calculation" -> RARE- Risk-Adjusted Net Present Value Calculation | E3: Units: | H3: 44377 | I3: 44742 | J3: 45107 | K3: 45473 | L3: 45838 | M3: 46203 | N3: 46568 | O3: 46934 | P3: 47299 | Q3: =EOMONTH(P3,12) -> 47664 | R3: =EOMONTH(Q3,12) -> 48029 | S3: =EOMONTH(R3,12) -> 48395 | T3: =EOMONTH(S3,12) -> 48760 | U3: =EOMONTH(T3,12) -> 49125 | V3: =EOMONTH(U3,12) -> 49490 | W3: =EOMONTH(V3,12) -> 49856 | X3: =EOMONTH(W3,12) -> 50221 | ... AF3: =EOMONTH(AE3,12) -> 53143
C5: OpEx: | D5: Base
C6: Scenario: | D6: Base | I6: Terminal Value - Multiples Method: | N6: Terminal Value - Perpetuity Growth Method: | S6: UX - 111 | W6: Company Wide
S7: Risk-Adjusted Net Present Value - Output | W7: Sum of DCF and rNPV Outputs
I8: Median CY 26 TEV / EBITDA of Comps: | L8: =[2]PubComps!S37 -> 14.299154 | N8: Expected Long-Term GDP Growth: | Q8: 0.015
I9: Median CY 26 TEV / EBITDA of Target: | L9: =[2]PubComps!S41 -> 0 | S9: NPV of rFCFs | U9: =NPV(Discount_Rate,J109:V109) -> 735051.07 | W9: UX - 111 | Y9: =U12 -> 7.5343488
W10: DTX - 401 | Y10: =U21 -> 7.9530104
I11: Baseline Terminal EBITDA Multiple: | L11: =INDEX(L12:L14,MATCH(Scenario,I12:I14,0),1) -> 9 | N11: Baseline Terminal FCF Growth Rate: | Q11: =INDEX(Q12:Q14,MATCH(Scenario,N12:N14,0),1) -> -0.015 | S11: Shares Outstanding | U11: =Diluted*Units -> 97560 | W11: DTX - 301 | Y11: =U30 -> 0.46160697
I12: Upside | L12: 10 | N12: Upside | Q12: -0.01 | S12: Implied Price per Share | U12: =U9/U11 -> 7.5343488 | W12: GTX - 102 | Y12: =U39 -> 11.027859
C13: Company Name: | E13: Name | G13: =Company_Name -> Ultragenyx Pharmaceutical Inc. | I13: Base | L13: 9 | N13: Base | Q13: -0.015 | W13: DCF | Y13: =L38 -> 26.602275
C14: Ticker: | E14: Name | G14: =Ticker -> RARE | I14: Downside | L14: 8 | N14: Downside | Q14: -0.02 | W14: Total Implied Share Price | Y14: =SUM(Y9:Y13) -> 53.5791
C15: Current Share Price: | E15: $ / Share | G15: 23.5 | S15: DTX - 401 | W15: Premium / (Discount) to Current: | Y15: =Y14/G15-1 -> 1.2799617
C16: Diluted Shares Outstanding: | E16: M Shares | G16: =Diluted -> 97.56 | S16: Risk-Adjusted Net Present Value - Output
I17: Baseline Terminal Value: | L17: =L11*(W86/Units) -> 1494.3886 | N17: Baseline Terminal Value: | Q17: =(W86*(1+Terminal_Growth_Rate)/(Discount_Rate-Q11)*(1+Discount_Rate)^0.5)/Units -> 1484.0401
C18: Effective Tax Rate: | E18: % | G18: 0.12 | I18: Implied Terminal FCF Growth Rate: | L18: =(W83*(1+Discount_Rate)^0.5*Discount_Rate - L17) / (W83*(1+Discount_Rate)^0.5 + L17) -> 0.085621653 | N18: Implied Terminal EBITDA Multiple: | Q18: =Q17/(W86/Units) -> 8.9376754 | S18: NPV of rFCFs | U18: =NPV(Discount_Rate,J132:W132) -> 775895.69
C19: Discount Rate (WACC): | E19: % | G19: 0.1
I20: (+) Present Value of Terminal Value: | L20: =L17/((1+Discount_Rate)^12) -> 476.15828 | N20: (+) Present Value of Terminal Value: | Q20: =Q17/((1+Discount_Rate)^12) -> 472.8609 | S20: Shares Outstanding | U20: =Diluted*Units -> 97560
C21: Current Equity Value: | G21: =G15*G16 -> 2292.66 | I21: (+) Present Value of UFCF: | L21: =NPV(Discount_Rate,L83:W83)/Units -> 1952.4306 | N21: (+) Present Value of UFCF: | Q21: =NPV(Discount_Rate,L83:W83)/Units -> 1952.4306 | S21: Implied Price per Share | U21: =U18/U20 -> 7.9530104
C22: (-) Cash & Investments: | G22: =-Model!J92/Units -> -173.729 | I22: Implied Enterprise Value: | L22: =SUM(L20:L21) -> 2428.5889 | N22: Implied Enterprise Value: | Q22: =SUM(Q20:Q21) -> 2425.2915
C23: (-) Net Operating Losses: | G23: 0
C24: (+) Debt & Finance Leases: | G24: 0 | I24: % of implied TEV from Terminal Value: | L24: =L20/L22 -> 0.19606376 | N24: % of implied TEV from Terminal Value: | Q24: =Q20/Q22 -> 0.19497075 | S24: DTX - 301
C25: (+) Preferred Stock: | G25: 0 | S25: Risk-Adjusted Net Present Value - Output
C26: (+) Operating Leases: | G26: 0 | I26: (+) Cash and Investments: | L26: =-G22 -> 173.729 | N26: (+) Cash and Investments: | Q26: =L26 -> 173.729
C27: (+) Noncontrolling Interests: | G27: 7 | I27: (+) Net Operating Losses: | L27: =-G23 -> 0 | N27: (+) Net Operating Losses: | Q27: =L27 -> 0 | S27: NPV of rFCFs | U27: =NPV(Discount_Rate,J154:X154) -> 45034.376
C28: (+) Unfunded Pensions: | G28: 0 | I28: (-)Debt and Finance Leases: | L28: =-G24 -> 0 | N28: (-)Debt and Finance Leases: | Q28: =L28 -> 0
C29: Current Enterprise Value: | G29: =SUM(G21:G28) -> 2125.931 | I29: (-)Preferred Stock: | L29: =-G25 -> 0 | N29: (-)Preferred Stock: | Q29: =L29 -> 0 | S29: Shares Outstanding | U29: =Diluted*Units -> 97560
I30: (-) Operating Leases: | L30: =-G26 -> 0 | N30: (-) Operating Leases: | Q30: =L30 -> 0 | S30: Implied Price per Share | U30: =U27/U29 -> 0.46160697
I31: (-) Noncontrolling Interests: | L31: =-G27 -> -7 | N31: (-) Noncontrolling Interests: | Q31: =L31 -> -7
I32: (-)Unfunded Pensions: | L32: =-G28 -> 0 | N32: (-)Unfunded Pensions: | Q32: =L32 -> 0
S33: GTX - 102
I34: Implied Equity Value: | L34: =L22+SUM(L26:L32) -> 2595.3179 | N34: Implied Equity Value: | Q34: =SUM(Q22:Q33) -> 2592.2155 | S34: Risk-Adjusted Net Present Value - Output
I36: Diluted Shares Outstanding: | L36: =_xlfn.SINGLE(Diluted) -> 97.56 | N36: Diluted Shares Outstanding: | Q36: =_xlfn.SINGLE(Diluted) -> 97.56 | S36: NPV of rFCFs | U36: =NPV(Discount_Rate,J177:AF177) -> 1075877.9
I38: Implied Share Price from DCF: | L38: =L34/L36 -> 26.602275 | N38: Implied Share Price from DCF: | Q38: =Q34/Q36 -> 26.570475 | S38: Shares Outstanding | U38: =Diluted*Units -> 97560
I39: Premium / (Discount) to Current: | L39: =L38/G15-1 -> 0.13201169 | N39: Premium / (Discount) to Current: | Q39: =Q38/G15-1 -> 0.1306585 | S39: Implied Price per Share | U39: =U36/U38 -> 11.027859
H41: Historical | P41: Projected:
B42: ="Free Cash Flow - "&Company_Name -> Free Cash Flow - Ultragenyx Pharmaceutical Inc. | E42: Units: | H42: =H3 -> 44377 | I42: =I3 -> 44742 | J42: =J3 -> 45107 | K42: =K3 -> 45473 | L42: =L3 -> 45838 | M42: =M3 -> 46203 | N42: =N3 -> 46568 | O42: =O3 -> 46934 | ... X42: =X3 -> 50221 | Y42: =EOMONTH(X42,12) -> 50586 | Z42: =EOMONTH(Y42,12) -> 50951 | AA42: =EOMONTH(Z42,12) -> 51317 | AB42: =EOMONTH(AA42,12) -> 51682 | AC42: =EOMONTH(AB42,12) -> 52047 | AD42: =EOMONTH(AC42,12) -> 52412 | AE42: =EOMONTH(AD42,12) -> 52778 | AF42: =EOMONTH(AE42,12) -> 53143
B43: ASSUMPTIONS
C45: COGS % Revenue | D45: 0.12
C47: Company - Wide
...

Sheet WACC
B2: ="WACC Analysis - "&_xlfn.SINGLE(Company_Name) -> WACC Analysis - Ultragenyx Pharmaceutical Inc.
B3: ($ USD in Millions Except Per Share Amounts in USD as Stated)
B5: Discount Rate Calculations - Assumptions:
B6: Risk-Free Rate: | F6: 0.045
B7: Equity Risk Premium: | F7: 0.035
B8: Pre-Tax Cost of Debt: | F8: 0.02532108
B9: Cost of Preferred Stock: | F9: 0
B11: Company Name: | C11: Ticker: | D11: Levered Beta: | E11: (+) Debt & Capital Leases: | G11: (+) Preferred Stock: | I11: Equity Value: | K11: Effective Tax Rate:
B12: Comparable Companies - Unlevered Beta Calculation:
D13: Levered | G13: Preferred | I13: Equity | L13: Unlevered
B14: Name | C14: Ticker | D14: Beta | E14: Debt | F14: % Debt | G14: Stock | H14: % Preferred | I14: Value | J14: % Equity | K14: Tax Rate | L14: Beta
B15: =INDEX(Pub_Comps_Range,MATCH(B$11,Pub_Comps_Params,0),MATCH($C15,Pub_Comps_Tickers,0)) -> Amicus Therapeutics, Inc. | C15: FOLD | D15: =INDEX(Pub_Comps_Range,MATCH(D$11,Pub_Comps_Params,0),MATCH($C15,Pub_Comps_Tickers,0)) -> 1.78 | E15: =INDEX(Pub_Comps_Range,MATCH(E$11,Pub_Comps_Params,0),MATCH($C15,Pub_Comps_Tickers,0)) -> 442 | F15: =E15/(E15+G15+I15) -> 0.12021708 | G15: =INDEX(Pub_Comps_Range,MATCH(G$11,Pub_Comps_Params,0),MATCH($C15,Pub_Comps_Tickers,0)) -> 0 | H15: =G15/(E15+G15+I15) -> 0 | I15: =INDEX(Pub_Comps_Range,MATCH(I$11,Pub_Comps_Params,0),MATCH($C15,Pub_Comps_Tickers,0)) -> 3234.6821 | J15: =$I15/($E15+$G15+$I15) -> 0.87978292 | K15: =INDEX(Pub_Comps_Range,MATCH(K$11,Pub_Comps_Params,0),MATCH($C15,Pub_Comps_Tickers,0)) -> 0.2 | L15: =IFERROR(D15/(1+(E15/I15)*(1-K15)+G15/I15),"N/A") -> 1.6045935
B16: =INDEX(Pub_Comps_Range,MATCH(B$11,Pub_Comps_Params,0),MATCH($C16,Pub_Comps_Tickers,0)) -> GE Healthcare Technologies Inc. | C16: BMRN | D16: =INDEX(Pub_Comps_Range,MATCH(D$11,Pub_Comps_Params,0),MATCH($C16,Pub_Comps_Tickers,0)) -> 1.27 | E16: =INDEX(Pub_Comps_Range,MATCH(E$11,Pub_Comps_Params,0),MATCH($C16,Pub_Comps_Tickers,0)) -> 604 | F16: =E16/(E16+G16+I16) -> 0.053205687 | G16: =INDEX(Pub_Comps_Range,MATCH(G$11,Pub_Comps_Params,0),MATCH($C16,Pub_Comps_Tickers,0)) -> 0 | H16: =G16/(E16+G16+I16) -> 0 | I16: =INDEX(Pub_Comps_Range,MATCH(I$11,Pub_Comps_Params,0),MATCH($C16,Pub_Comps_Tickers,0)) -> 10748.17 | J16: =$I16/($E16+$G16+$I16) -> 0.94679431 | K16: =INDEX(Pub_Comps_Range,MATCH(K$11,Pub_Comps_Params,0),MATCH($C16,Pub_Comps_Tickers,0)) -> 0.234 | L16: =IFERROR(D16/(1+(E16/I16)*(1-K16)+G16/I16),"N/A") -> 1.2175879
B17: =INDEX(Pub_Comps_Range,MATCH(B$11,Pub_Comps_Params,0),MATCH($C17,Pub_Comps_Tickers,0)) -> Sarepta Therapeutics, Inc. | C17: SRPT | D17: =INDEX(Pub_Comps_Range,MATCH(D$11,Pub_Comps_Params,0),MATCH($C17,Pub_Comps_Tickers,0)) -> 1.26 | E17: =INDEX(Pub_Comps_Range,MATCH(E$11,Pub_Comps_Params,0),MATCH($C17,Pub_Comps_Tickers,0)) -> 1260 | F17: =E17/(E17+G17+I17) -> 0.36696692 | G17: =INDEX(Pub_Comps_Range,MATCH(G$11,Pub_Comps_Params,0),MATCH($C17,Pub_Comps_Tickers,0)) -> 0 | H17: =G17/(E17+G17+I17) -> 0 | I17: =INDEX(Pub_Comps_Range,MATCH(I$11,Pub_Comps_Params,0),MATCH($C17,Pub_Comps_Tickers,0)) -> 2173.552 | J17: =$I17/($E17+$G17+$I17) -> 0.63303308 | K17: =INDEX(Pub_Comps_Range,MATCH(K$11,Pub_Comps_Params,0),MATCH($C17,Pub_Comps_Tickers,0)) -> 0.2 | L17: =IFERROR(D17/(1+(E17/I17)*(1-K17)+G17/I17),"N/A") -> 0.8607986
B18: =INDEX(Pub_Comps_Range,MATCH(B$11,Pub_Comps_Params,0),MATCH($C18,Pub_Comps_Tickers,0)) -> PTC Therapeutics, Inc. | C18: PTCT | D18: =INDEX(Pub_Comps_Range,MATCH(D$11,Pub_Comps_Params,0),MATCH($C18,Pub_Comps_Tickers,0)) -> 2.15 | E18: =INDEX(Pub_Comps_Range,MATCH(E$11,Pub_Comps_Params,0),MATCH($C18,Pub_Comps_Tickers,0)) -> 2492 | F18: =E18/(E18+G18+I18) -> 0.67740106 | G18: =INDEX(Pub_Comps_Range,MATCH(G$11,Pub_Comps_Params,0),MATCH($C18,Pub_Comps_Tickers,0)) -> 0 | H18: =G18/(E18+G18+I18) -> 0 | I18: =INDEX(Pub_Comps_Range,MATCH(I$11,Pub_Comps_Params,0),MATCH($C18,Pub_Comps_Tickers,0)) -> 1186.766 | J18: =$I18/($E18+$G18+$I18) -> 0.32259894 | K18: =INDEX(Pub_Comps_Range,MATCH(K$11,Pub_Comps_Params,0),MATCH($C18,Pub_Comps_Tickers,0)) -> 0.2 | L18: =IFERROR(D18/(1+(E18/I18)*(1-K18)+G18/I18),"N/A") -> 0.8022809
B19: =INDEX(Pub_Comps_Range,MATCH(B$11,Pub_Comps_Params,0),MATCH($C19,Pub_Comps_Tickers,0)) -> Travere Therapeutics, Inc. | C19: TVTX | D19: =INDEX(Pub_Comps_Range,MATCH(D$11,Pub_Comps_Params,0),MATCH($C19,Pub_Comps_Tickers,0)) -> 1.08 | E19: =INDEX(Pub_Comps_Range,MATCH(E$11,Pub_Comps_Params,0),MATCH($C19,Pub_Comps_Tickers,0)) -> 329 | F19: =E19/(E19+G19+I19) -> 0.11647064 | G19: =INDEX(Pub_Comps_Range,MATCH(G$11,Pub_Comps_Params,0),MATCH($C19,Pub_Comps_Tickers,0)) -> 0 | H19: =G19/(E19+G19+I19) -> 0 | I19: =INDEX(Pub_Comps_Range,MATCH(I$11,Pub_Comps_Params,0),MATCH($C19,Pub_Comps_Tickers,0)) -> 2495.7461 | J19: =$I19/($E19+$G19+$I19) -> 0.88352936 | K19: =INDEX(Pub_Comps_Range,MATCH(K$11,Pub_Comps_Params,0),MATCH($C19,Pub_Comps_Tickers,0)) -> 0.2 | L19: =IFERROR(D19/(1+(E19/I19)*(1-K19)+G19/I19),"N/A") -> 0.97696935
B20: =INDEX(Pub_Comps_Range,MATCH(B$11,Pub_Comps_Params,0),MATCH($C20,Pub_Comps_Tickers,0)) -> CareDx, Inc | C20: CPRX | D20: =INDEX(Pub_Comps_Range,MATCH(D$11,Pub_Comps_Params,0),MATCH($C20,Pub_Comps_Tickers,0)) -> 2.56 | E20: =INDEX(Pub_Comps_Range,MATCH(E$11,Pub_Comps_Params,0),MATCH($C20,Pub_Comps_Tickers,0)) -> 2.9 | F20: =E20/(E20+G20+I20) -> 0.0010121313 | G20: =INDEX(Pub_Comps_Range,MATCH(G$11,Pub_Comps_Params,0),MATCH($C20,Pub_Comps_Tickers,0)) -> 0 | H20: =G20/(E20+G20+I20) -> 0 | I20: =INDEX(Pub_Comps_Range,MATCH(I$11,Pub_Comps_Params,0),MATCH($C20,Pub_Comps_Tickers,0)) -> 2862.341 | J20: =$I20/($E20+$G20+$I20) -> 0.99898787 | K20: =INDEX(Pub_Comps_Range,MATCH(K$11,Pub_Comps_Params,0),MATCH($C20,Pub_Comps_Tickers,0)) -> 0.239 | L20: =IFERROR(D20/(1+(E20/I20)*(1-K20)+G20/I20),"N/A") -> 2.5580277
B22: Median: | D22: =MEDIAN(D15:D19) -> 1.27 | E22: =MEDIAN(E15:E19) -> 604 | F22: =MEDIAN(F15:F19) -> 0.12021708 | G22: =MEDIAN(G15:G19) -> 0 | H22: =MEDIAN(H15:H19) -> 0 | I22: =MEDIAN(I15:I19) -> 2495.7461 | J22: =MEDIAN(J15:J19) -> 0.87978292 | K22: =MEDIAN(K15:K19) -> 0.2 | L22: =MEDIAN(L15:L19) -> 0.97696935
B24: =Company_Name -> Ultragenyx Pharmaceutical Inc. | C24: =Ticker -> RARE | D24: =INDEX(Pub_Comps_Range,MATCH(D$11,Pub_Comps_Params,0),MATCH($C24,Pub_Comps_Tickers,0)) -> 2.24 | E24: =INDEX(Pub_Comps_Range,MATCH(E$11,Pub_Comps_Params,0),MATCH($C24,Pub_Comps_Tickers,0)) -> 0 | F24: =E24/($E24+$G24+$I24) -> 0 | G24: =INDEX(Pub_Comps_Range,MATCH(G$11,Pub_Comps_Params,0),MATCH($C24,Pub_Comps_Tickers,0)) -> 0 | H24: =G24/($E24+$G24+$I24) -> 0 | I24: =INDEX(Pub_Comps_Range,MATCH(I$11,Pub_Comps_Params,0),MATCH($C24,Pub_Comps_Tickers,0)) -> 2322.1817 | J24: =I24/($E24+$G24+$I24) -> 1 | K24: 0.132 | L24: =IFERROR(D24/(1+(E24/I24)*(1-K24)+G24/I24),"N/A") -> 2.24
B26: =TEXT(Company_Name,"")& " - Levered Beta & WACC Calculation:" -> Ultragenyx Pharmaceutical Inc. - Levered Beta & WACC Calculation:
D27: Unlevered | G27: Preferred | I27: Equity | L27: Levered
C28: Ticker | D28: Beta | E28: Debt | F28: % Debt | G28: Stock | H28: % Preferred | I28: Value | J28: % Equity | K28: Tax Rate | L28: Beta
B29: Current Capital Structure: | C29: =C24 -> RARE | D29: =L24 -> 2.24 | E29: 5461 | F29: 0.033001557 | G29: 0 | H29: 0 | I29: 160016.04 | J29: 0.96699844 | K29: 0.132 | L29: =D29*(1+E29/I29*(1-K29)+G29/I29) -> 2.3063554
B30: "Optimal" Capital Structure: | D30: =L22 -> 0.97696935 | E30: =(E29+I29)*F30 -> 19893.167 | F30: =F22 -> 0.12021708 | G30: 0 | H30: 0 | I30: =(I29+E29)*J30 -> 145583.87 | J30: =J22 -> 0.87978292 | K30: 0.132 | L30: =D30*(1+E30/I30*(1-K30)+G30/I30) -> 1.0928448
B32: Cost of Equity Based on Comparables, Current Capital Structure: | L32: =Risk_Free_Rate+Equity_Risk_Premium*L29 -> 0.12572244
B33: Cost of Equity Based on Comparables, "Optimal" Capital Structure: | L33: =Risk_Free_Rate+Equity_Risk_Premium*L30 -> 0.083249567
B34: Cost of Equity Based on Historical Beta: | L34: =Risk_Free_Rate+Equity_Risk_Premium*D24 -> 0.1234
B36: WACC, Current Capital Structure: | L36: =L32*J29+Cost_of_Debt*(1-K29)*F29+Cost_of_Preferred*H29 -> 0.12229873
B37: WACC, "Optimal" Capital Structure: | L37: =L33*J30+Cost_of_Debt*(1-K30)*F30+Cost_of_Preferred*H30 -> 0.075883762
B38: WACC, Current Capital Structure and Historical Cost of Equity: | L38: =L34*J29+Cost_of_Debt*(1-K29)*F29+Cost_of_Preferred*H29 -> 0.12005294
B40: Average WACC Produced by All Methods: | L40: =AVERAGE(L36:L38) -> 0.10607848

Sheet Valsum
B2: ="Valuation Summary - "&Company_Name -> Valuation Summary - Ultragenyx Pharmaceutical Inc.
B3: ($ USD in Millions Except Per Share Amounts in USD as Stated)
B5: ="Valuation Statistics - "&TEXT(Company_Name,"") -> Valuation Statistics - Ultragenyx Pharmaceutical Inc. | C5: Range of Valuation Multiples / Premiums | I5: Implied Per-Share Value Range
D7: 75th | F7: 25th | H7: Applicable | J7: 25th | L7: 75th
C8: Maximum | D8: Percentile | E8: Median | F8: Percentile | G8: Minimum | H8: Company | I8: Minimum | J8: Percentile | K8: Median | L8: Percentile | M8: Maximum
B9: Methodology Name | C9: Multiple | D9: Multiple | E9: Multiple | F9: Multiple | G9: Multiple | H9: Figure | I9: Multiple | J9: Multiple | K9: Multiple | L9: Multiple | M9: Multiple
B11: Public Company Comparables:
B12: LTM TEV / Revenue: | C12: {=TRANSPOSE(PubComps!N34:V38)} -> 5.8962067 | D12: 5.2155071 | E12: 3.4784195 | F12: 1.6291963 | G12: 1.0702661 | H12: {=TRANSPOSE(PubComps!N21:V21)} -> 560.23 | I12: =(I34+SUM($E$33:$E$39))/$E$42 -> 7.0558646 | J12: =(J34+SUM($E$33:$E$39))/$E$42 -> 10.265474 | K12: =(K34+SUM($E$33:$E$39))/$E$42 -> 20.884481 | L12: =(L34+SUM($E$33:$E$39))/$E$42 -> 30.859558 | M12: =(M34+SUM($E$33:$E$39))/$E$42 -> 34.768418
B13: ="CY "&TEXT(EOMONTH(Hist_Year,12),"YY")&" TEV / Revenue:" -> CY 25 TEV / Revenue: | C13: 5.9060244 | D13: 5.666591 | E13: 5.4271576 | F13: 4.2677447 | G13: 3.1083318 | H13: 673 | I13: =(I35+SUM($E$33:$E$39))/$E$42 -> 22.352217 | J13: =(J35+SUM($E$33:$E$39))/$E$42 -> 30.350217 | K13: =(K35+SUM($E$33:$E$39))/$E$42 -> 38.348217 | L13: =(L35+SUM($E$33:$E$39))/$E$42 -> 39.999905 | M13: =(M35+SUM($E$33:$E$39))/$E$42 -> 41.651593
B14: ="CY "&TEXT(EOMONTH(Hist_Year,24),"YY")&" TEV / Revenue:" -> CY 26 TEV / Revenue: | C14: 5.5507026 | D14: 4.3761929 | E14: 3.268504 | F14: 2.2367003 | G14: 1.6480868 | H14: 745 | I14: =(I36+SUM($E$33:$E$39))/$E$42 -> 13.495281 | J14: =(J36+SUM($E$33:$E$39))/$E$42 -> 17.990126 | K14: =(K36+SUM($E$33:$E$39))/$E$42 -> 25.869316 | L14: =(L36+SUM($E$33:$E$39))/$E$42 -> 34.32799 | M14: =(M36+SUM($E$33:$E$39))/$E$42 -> 43.29693
B15: LTM TEV / EBITDA: | C15: 74.534544 | D15: 29.046088 | E15: 10.759602 | F15: 6.3951731 | G15: 2.6728924 | H15: -535.973 | I15: =(I37+SUM($E$33:$E$39))/$E$42 -> -13.774325 | J15: =(J37+SUM($E$33:$E$39))/$E$42 -> -34.22371 | K15: =(K37+SUM($E$33:$E$39))/$E$42 -> -58.200912 | L15: =(L37+SUM($E$33:$E$39))/$E$42 -> -158.66281 | M15: =(M37+SUM($E$33:$E$39))/$E$42 -> -408.5663
B16: ="CY "&TEXT(EOMONTH(Hist_Year,12),"YY")&" TEV / EBITDA:" -> CY 25 TEV / EBITDA: | C16: 44.333534 | D16: 29.930265 | E16: 15.526997 | F16: 15.216953 | G16: 14.906909 | H16: -508.22188 | I16: =(I38+SUM($E$33:$E$39))/$E$42 -> -76.745 | J16: =(J38+SUM($E$33:$E$39))/$E$42 -> -78.360121 | K16: =(K38+SUM($E$33:$E$39))/$E$42 -> -79.975241 | L16: =(L38+SUM($E$33:$E$39))/$E$42 -> -155.00657 | M16: =(M38+SUM($E$33:$E$39))/$E$42 -> -230.03789
B17: ="CY "&TEXT(EOMONTH(Hist_Year,24),"YY")&" TEV / EBITDA:" -> CY 26 TEV / EBITDA: | C17: 48.091854 | D17: 20.675825 | E17: 13.125439 | F17: 9.7785333 | G17: 7.5513216 | H17: -364.82964 | I17: =(I39+SUM($E$33:$E$39))/$E$42 -> -27.328526 | J17: =(J39+SUM($E$33:$E$39))/$E$42 -> -35.657276 | K17: =(K39+SUM($E$33:$E$39))/$E$42 -> -48.173168 | L17: =(L39+SUM($E$33:$E$39))/$E$42 -> -76.408148 | M17: =(M39+SUM($E$33:$E$39))/$E$42 -> -178.93152
B18: LTM P / E: | C18: 20.669558 | D18: 16.869804 | E18: 13.07005 | F18: 7.3251489 | G18: 1.5802477 | H18: -569.183 | I18: =(I40+SUM($E$33:$E$39))/$E$42 -> -8.309503 | J18: =(J40+SUM($E$33:$E$39))/$E$42 -> -41.826315 | K18: =(K40+SUM($E$33:$E$39))/$E$42 -> -75.343126 | L18: =(L40+SUM($E$33:$E$39))/$E$42 -> -97.511589 | M18: =(M40+SUM($E$33:$E$39))/$E$42 -> -119.68005
B19: ="CY "&TEXT(EOMONTH(Hist_Year,12),"YY")&" P / E:" -> CY 25 P / E: | C19: 20.433783 | D19: 19.289409 | E19: 18.145034 | F19: 17.000659 | G19: 15.856285 | H19: -586.93659 | I19: =(I41+SUM($E$33:$E$39))/$E$42 -> -94.483997 | J19: =(J41+SUM($E$33:$E$39))/$E$42 -> -101.36874 | K19: =(K41+SUM($E$33:$E$39))/$E$42 -> -108.25348 | L19: =(L41+SUM($E$33:$E$39))/$E$42 -> -115.13822 | M19: =(M41+SUM($E$33:$E$39))/$E$42 -> -122.02296
B20: ="CY "&TEXT(EOMONTH(Hist_Year,24),"YY")&" P / E:" -> CY 26 P / E: | C20: 40.433526 | D20: 34.188303 | E20: 14.770238 | F20: 12.527005 | G20: 11.500275 | H20: -451.2666 | I20: =(I42+SUM($E$33:$E$39))/$E$42 -> -52.284902 | J20: =(J42+SUM($E$33:$E$39))/$E$42 -> -57.034069 | K20: =(K42+SUM($E$33:$E$39))/$E$42 -> -67.410209 | L20: =(L42+SUM($E$33:$E$39))/$E$42 -> -157.22903 | M20: =(M42+SUM($E$33:$E$39))/$E$42 -> -186.11649
B29: Discounted Cash Flow Analysis:
B30: (9.9% - 11.9% WACC, 5.5% - 8.5% Free Cash Flow Growth Rate
B32: Implied Enterprise Value: | E32: =rNPV!G21 -> 2292.66
B33: (+) Cash and Investments: | E33: =[1]DCF!L29 -> 88.775
B34: (+) Net Operating Losses: | E34: =[1]DCF!L30 -> 0 | G34: Enterprise Value --> | I34: =G12*$H12 -> 599.59515 | J34: =F12*$H12 -> 912.72467 | K34: =E12*$H12 -> 1948.715 | L34: =D12*$H12 -> 2921.8835 | M34: =C12*$H12 -> 3303.2319
B35: (-)Debt and Finance Leases: | E35: =[1]DCF!L31 -> 0 | G35: Enterprise Value --> | I35: =G13*$H13 -> 2091.9073 | J35: =F13*$H13 -> 2872.1922 | K35: =E13*$H13 -> 3652.477 | L35: =D13*$H13 -> 3813.6157 | M35: =C13*$H13 -> 3974.7544
B36: (-)Preferred Stock: | E36: =[1]DCF!L32 -> 0 | G36: Enterprise Value --> | I36: =G14*$H14 -> 1227.8247 | J36: =F14*$H14 -> 1666.3417 | K36: =E14*$H14 -> 2435.0355 | L36: =D14*$H14 -> 3260.2637 | M36: =C14*$H14 -> 4135.2734
B37: (-) Operating Leases: | E37: =[1]DCF!L33 -> 0 | G37: Enterprise Value --> | I37: =G15*$H15 -> -1432.5982 | J37: =F15*$H15 -> -3427.6401 | K37: =E15*$H15 -> -5766.856 | L37: =D15*$H15 -> -15567.919 | M37: =C15*$H15 -> -39948.503
B38: (-) Noncontrolling Interests: | E38: =[1]DCF!L34 -> 0 | G38: Enterprise Value --> | I38: =G16*$H16 -> -7576.0172 | J38: =F16*$H16 -> -7733.5884 | K38: =E16*$H16 -> -7891.1595 | L38: =D16*$H16 -> -15211.216 | M38: =C16*$H16 -> -22531.272
B39: (-)Unfunded Pensions: | E39: =[1]DCF!L35 -> 0 | G39: Enterprise Value --> | I39: =G17*$H17 -> -2754.946 | J39: =F17*$H17 -> -3567.4988 | K39: =E17*$H17 -> -4788.5493 | L39: =D17*$H17 -> -7543.1539 | M39: =C17*$H17 -> -17545.334
B40: Implied Equity Value: | E40: =SUM(E32:E39) -> 2381.435 | G40: Equity Value --> | I40: =G18*$H18 -> -899.45011 | J40: =F18*$H18 -> -4169.3503 | K40: =E18*$H18 -> -7439.2504 | L40: =D18*$H18 -> -9602.0056 | M40: =C18*$H18 -> -11764.761
G41: Equity Value --> | I41: =G19*$H19 -> -9306.6337 | J41: =F19*$H19 -> -9978.3091 | K41: =E19*$H19 -> -10649.984 | L41: =D19*$H19 -> -11321.66 | M41: =C19*$H19 -> -11993.335
B42: Diluted Shares Outstanding: | E42: =Diluted -> 97.56 | G42: Equity Value --> | I42: =G20*$H20 -> -5189.69 | J42: =F20*$H20 -> -5653.0187 | K42: =E20*$H20 -> -6665.315 | L42: =D20*$H20 -> -15428.039 | M42: =C20*$H20 -> -18246.3
B44: Implied Share Price from DCF: | E44: =E40/E42 -> 24.409953 | G44: Enterprise Value --> | I44: =+G23*$H23 -> 0 | J44: =H23*F23 -> 0 | K44: =H23*E23 -> 0 | L44: =H23*D23 -> 0 | M44: =H23*C23 -> 0
